Workbook
Name adsf: #REF!
Name BID_FORM: #REF!
Name Build: #REF!
Name DBSUM: #REF!
Name FIRST_: #REF!
Name LOOPSUM: #REF!
Name Print_Area_MI: #REF!
Name qweqwe: #REF!
Name RECOMPARE: #REF!
Name RESTART: #REF!
Name SBINS: #REF!
Name SBRID: #REF!
Name SCONT: #REF!
Name SECOND_: #REF!
Name SELEC: #REF!
Name SEQUP: #REF!
Name SEXCV: #REF!
Name SEXCVA: #REF!
Name SEXCVB: #REF!
Name SEXTW: #REF!
Name sf: #REF!
Name SFARM: #REF!
Name SFEE_: #REF!
Name SFINS: #REF!
Name SFLOO: #REF!
Name SFPRT: #REF!
Name SGENC: #REF!
Name SHVAC: #REF!
Name SPERM: #REF!
Name SPLBG: #REF!
Name SRFWP: #REF!
Name SRFWPA: #REF!
Name SRFWPB: #REF!
Name SSCON: #REF!
Name SSERV: #REF!
Name SSITE: #REF!
Name SSPEC: #REF!
Name SSTRU: #REF!
Name SSTRUA: #REF!
Name SSTRUB: #REF!
Name SubcontractorTable: 'Item Breakdown'!$B$2886:$C$2939
Name SubcontractorTable: #REF!
Name SUMMARY: #REF!
Name SVERT: #REF!
Name SYSBORDER: #REF!
Name SYSTEMSPRINT: #REF!
Name TOTALSUM: #REF!
Name TRADEBORDER: #REF!
Name TRADEPRINT: #REF!
Name Unit: #REF!
Name UnitTypes: #REF!

Sheet NOTES
B1: NOTES
B3: Project Name : Starbucks #6212, University Park Village
B4: Location : 1620 S University Dr, Fort Worth, TX 76107
B5: Date of Drawings : Permit Set 8/28/2025
B7: DEMOLITION
B8: "Items to be preserved" list for items that shall be salvaged for relocation
B9: At locations where existing walls are to be removed existing walls to remain. Perform demolition without disturbing exisitng elements to remain
B10: Field verify type of construction and height of walls, Fields verify that walls to be removed do not provide support for existing building elements and existing construction to remain
B11: MEPs demolition are not included.
B12: Height of cubbies and menu board are assumed base on starbucks standard (https://www.navymwr.org/modules/media/?do=download&id=e4a72850-fe08-4e91-a9ce-0a7fa6f77cbe)
B13: Removal shall include any residual material after demolition i.e pieces of wall covering or backing. Removal of all coverings is to be done w/o damaging the existing wall surface to remain
B14: The manhours computed in the sheet include hauling, as well as the disassembly of any connections, fasteners, and accessories related to the item.
... B19: Exterior Siding
B20: ='Exterior Siding'!B7 -> Only Patching and repair area were considered in takeoffs.
B21: ='Exterior Siding'!B8 -> Brick Veneer considered in the takeoffs as per plan.
B22: Exterior Painting
B23: ='Exterior Painting'!B22 -> Two coats of stain paint are considered for the Exterior Patio Railings.
B24: ='Exterior Painting'!B23 -> One coat of primer and two coats of paint are considered for the Exterior Patio Posts.
B25: As per Key Note 6 , Patio Railing will be restained wood SW3524.
B26: As per Key Note 6 , Patio Post will be repainted SW7048.
B27: Metal Framing
B28: Wall Type per print A101, Interior New Wall Schedule.
B29: Jamb, Header, Soffit and Bracing details per print I509.
B30: Drywall
B31: Wall Type per print A101, Wall Sheating Key for wall type.
B32: See print I201-I204 for height reference.
B33: See print I103 for ceiling sched/type reference.
B34: Consider 5/8" GWB Type X for all wall and GWB Clg, U.N.O.
B35: Flooring & Tile
B36: Finish Material Schedule per print I603.
... B79: Considere 2x10 FRT blocking per detail 2 | I504

Sheet SUMMARY
C3: MATERIAL BREAKDOWN
C4: =NOTES!B3 -> Project Name : Starbucks #6212, University Park Village | E4: Proposal for plans dated: | F4: 45897
C5: =NOTES!B4 -> Location : 1620 S University Dr, Fort Worth, TX 76107 | E5: Floor Level: | F5: 1
E6: Total Square Footage (Building): | F6: 2758
E7: Total Square Footage (Site): | F7: --
D9: WORK DESCRIPTION | E9: TOTAL MANHOURS | F9: TOTAL MATERIAL COST
D11: ='Item Breakdown'!C14 -> DEMOLITION | E11: =ROUNDUP(SUM('Item Breakdown'!G16:G62),0) -> 166 | F11: ='Item Breakdown'!J65 -> 0
D12: ='Item Breakdown'!C67 -> LANDSCAPING | E12: =ROUNDUP(SUM('Item Breakdown'!G68:G88),0) -> 6 | F12: ='Item Breakdown'!J91 -> 0
D13: ='Item Breakdown'!C93 -> EXTERIOR SIDING | E13: =ROUNDUP(SUM('Item Breakdown'!G94:G96),0) -> 8 | F13: ='Item Breakdown'!J99 -> 0
D14: ='Item Breakdown'!C101 -> EXTERIOR PAINTING | E14: =ROUNDUP(SUM('Item Breakdown'!G102:G106),0) -> 16 | F14: ='Item Breakdown'!J109 -> 0
D15: ='Item Breakdown'!C111 -> METAL STUD FRAMING | E15: =ROUNDUP(SUM('Item Breakdown'!G112:G179),0) -> 59 | F15: ='Item Breakdown'!J182 -> 0
D16: ='Item Breakdown'!C184 -> DRYWALL | E16: =ROUNDUP(SUM('Item Breakdown'!G185:G200),0) -> 124 | F16: ='Item Breakdown'!J203 -> 0
D17: ='Item Breakdown'!C205 -> FLOORING & TILE | E17: =ROUNDUP(SUM('Item Breakdown'!G206:G219),0) -> 149 | F17: ='Item Breakdown'!J222 -> 0
D18: ='Item Breakdown'!C224 -> INTERIOR FINISHES | E18: =ROUNDUP(SUM('Item Breakdown'!G225:G239),0) -> 461 | F18: ='Item Breakdown'!J242 -> 0
D19: ='Item Breakdown'!C244 -> INTERIOR PAINTING | E19: =SUM('Item Breakdown'!G245:G273) -> 116 | F19: ='Item Breakdown'!J276 -> 0
D20: ='Item Breakdown'!C278 -> INTERIOR TRIM | E20: =ROUNDUP(SUM('Item Breakdown'!G279:G286),0) -> 3 | F20: ='Item Breakdown'!J289 -> 0
D21: ='Item Breakdown'!C291 -> OPENING | E21: =ROUNDUP(SUM('Item Breakdown'!G292:G318),0) -> 15 | F21: ='Item Breakdown'!J321 -> 0
D22: ='Item Breakdown'!C323 -> MILLWORK | E22: =ROUNDUP(SUM('Item Breakdown'!G324:G373),0) -> 58 | F22: ='Item Breakdown'!J376 -> 0
D23: ='Item Breakdown'!C378 -> SPECIALTIES | E23: =ROUNDUP(SUM('Item Breakdown'!G379:G452),0) -> 115 | F23: ='Item Breakdown'!J455 -> 0
D24: ='Item Breakdown'!C457 -> ROUGH CARPENTRY | E24: =ROUNDUP(SUM('Item Breakdown'!G458:G463),0) -> 18 | F24: ='Item Breakdown'!J466 -> 0
D26: TOTAL | E26: =SUM(E10:E24) -> 1314 | F26: =SUM(F10:F24) -> 0
C30: ALTERNATES
E31: TOTAL MANHOURS | F31: TOTAL MATERIAL COST
C32: 1
C33: 2

Sheet Item Breakdown
C3: =NOTES!B3 -> Project Name : Starbucks #6212, University Park Village
C4: =NOTES!B4 -> Location : 1620 S University Dr, Fort Worth, TX 76107
C5: =NOTES!B5 -> Date of Drawings : Permit Set 8/28/2025
G7: www.gclegacyconstruction.com
G8: 10455 Markison Rd., Dallas, TX 75238
C9: MATERIAL BREAKDOWN
C11: ITEM | D11: DESCRIPTION | E11: QTY | F11: UNIT | G11: MANHOURS | H11: CREW | I11: MATERIAL COST (Excluding Tax) | J11: Total | M11: Wastage | N11: Unit Material Cost
C14: DEMOLITION
C15: EXTERIOR
C16: DEMOLISH EXTERIOR FURNITURE | D16: This includes all tables and chairs | E16: 10 | F16: EA | G16: 3 | H16: MH, 2 WORKERS | I16: =E16*N16*(1+M16) -> 0 | J16: =SUM(I16) -> 0 | M16: 0 | N16: 0
C17: DEMOLISH EXISTING METAL AWNING | D17: GC to patch/repair wall as needed | E17: 260 | F17: SF | G17: 6.5 | H17: MH, 3 WORKERS | I17: =E17*N17*(1+M17) -> 0 | J17: =SUM(I17) -> 0 | M17: 0 | N17: 0
C18: DEMOLISH EXISTING METAL DECORATION OVER CLERESTORY WINDOWS | D18: 3'-4" Height as per sheet D103 | E18: 236.9 | F18: SF | G18: 6 | H18: MH, 3 WORKERS | I18: =E18*N18*(1+M18) -> 0 | J18: =SUM(I18) -> 0 | M18: 0 | N18: 0
C19: DEMOLISH EXISTING FABRIC COVERING ON PATIO STRUCTURE | D19: GC to prepare for new | E19: 184.5 | F19: SF | G19: 1.9 | H19: MH, 2 WORKERS | I19: =E19*N19*(1+M19) -> 0 | J19: =SUM(I19) -> 0 | M19: 0 | N19: 0
C21: INTERIOR
C22: DEMOLISH EXISTING WALL TO EXTENT SHOWN | D22: Average Height 10' (Ref D102 Sheet) | E22: 2082.8 | F22: SF | G22: 42 | H22: MH, 3 WORKERS | I22: =E22*N22*(1+M22) -> 0 | J22: =SUM(I22) -> 0 | M22: 0 | N22: 0
C23: DEMOLISH EXISTING FLOOR AND BASE FINISH | D23: Patch & Repair for New Finish | E23: 2721.69 | F23: SF | G23: 14 | H23: MH, 3 WORKERS | I23: =E23*N23*(1+M23) -> 0 | J23: =SUM(I23) -> 0 | M23: 0 | N23: 0
C24: DEMOLISH EXISTING FIXTURES | D24: This Includes all tables, and chairs | E24: 15 | F24: EA | G24: 4 | H24: MH, 2 WORKERS | I24: =E24*N24*(1+M24) -> 0 | J24: =SUM(I24) -> 0 | M24: 0 | N24: 0
C25: DEMOLISH EXISTING FIXTURES | D25: This includes all interior fixtures | E25: 371.03 | F25: SF | G25: 6 | H25: MH, 3 WORKERS | I25: =E25*N25*(1+M25) -> 0 | J25: =SUM(I25) -> 0 | M25: 0 | N25: 0
C26: DEMOLISH EXISTING CONDIMENT CART | E26: 1 | F26: EA | G26: 0.5 | H26: MH, 2 WORKERS | I26: =E26*N26*(1+M26) -> 0 | J26: =SUM(I26) -> 0 | M26: 0 | N26: 0
C27: DEMOLISH EXISTING IN-WALL FOOD/BEVERAGE COOLER | E27: 2 | F27: EA | G27: 3 | H27: MH, 3 WORKERS | I27: =E27*N27*(1+M27) -> 0 | J27: =SUM(I27) -> 0 | M27: 0 | N27: 0
C28: DEMOLISH EXISTING INTERIOR FURNITURE & FIXTURES | D28: This includes all tables, chairs, and kitchen fixtures | E28: 11 | F28: EA | G28: 3.2 | H28: MH, 2 WORKERS | I28: =E28*N28*(1+M28) -> 0 | J28: =SUM(I28) -> 0 | M28: 0 | N28: 0
C29: DEMOLISH EXISTING MERCH BASKET | E29: 2 | F29: EA | G29: 1 | H29: MH, 2 WORKERS | I29: =E29*N29*(1+M29) -> 0 | J29: =SUM(I29) -> 0 | M29: 0 | N29: 0
C30: DEMOLISH EXISTING MERCH BAYS | E30: 2 | F30: EA | G30: 2 | H30: MH, 2 WORKERS | I30: =E30*N30*(1+M30) -> 0 | J30: =SUM(I30) -> 0 | M30: 0 | N30: 0
C31: DEMOLISH EXISTING WALL FINISHES | D31: Elevation refer to sheet D102-D103 | E31: 2652.9 | F31: SF | G31: 18 | H31: MH, 3 WORKERS | I31: =E31*N31*(1+M31) -> 0 | J31: =SUM(I31) -> 0 | M31: 0 | N31: 0
C32: REMOVE EXISTING CASEWORK, HANGING DEVICES, AND FASTENERS | D32: All counters in the serving area | E32: 129.18 | F32: SF | G32: 4 | H32: MH, 2 WORKERS | I32: =E32*N32*(1+M32) -> 0 | J32: =SUM(I32) -> 0 | M32: 0 | N32: 0
C33: REMOVE EXISTING DOOR FRAME, AND ASSOCIATED FASTENERS | E33: 9 | F33: EA | G33: 4.5 | H33: MH, 2 WORKERS | I33: =E33*N33*(1+M33) -> 0 | J33: =SUM(I33) -> 0 | M33: 0 | N33: 0
C35: CEILING
C36: DEMOLISH EXISTING MENU BOARD | D36: No details on height (Assumed as per standard of starbucks 35") See Notes for references | E36: 78.75 | F36: SF | G36: 2 | H36: MH, 2 WORKERS | I36: =E36*N36*(1+M36) -> 0 | J36: =SUM(I36) -> 0 | M36: 0 | N36: 0
C37: DEMOLISH EXISTING UPPER CUBBIES | D37: No details on height (Assumed as per standard of starbucks 35") See Notes for references | E37: 78.75 | F37: SF | G37: 2 | H37: MH, 2 WORKERS | I37: =E37*N37*(1+M37) -> 0 | J37: =SUM(I37) -> 0 | M37: 0 | N37: 0
C38: DEMOLISH EXISTING ACT CEILING TILES AND GRID | E38: 1210.9 | F38: SF | G38: 12 | H38: MH, 3 WORKERS | I38: =E38*N38*(1+M38) -> 0 | J38: =SUM(I38) -> 0 | M38: 0 | N38: 0
C39: DEMOLISH HARD LID CEILING, FRAMING AND ASSOCIATED FASTENERS TO BOTTOM OF STRUCTURE ABOVE | E39: 270.7 | F39: SF | G39: 4 | H39: MH, 3 WORKERS | I39: =E39*N39*(1+M39) -> 0 | J39: =SUM(I39) -> 0 | M39: 0 | N39: 0
C41: ITEMS TO RELOCATE
C42: 1 DR U/C FRIDGE | D42: Relocation only, Excluding Installation | E42: 2 | F42: EA | G42: 1.5 | H42: MH, 2 MOVERS | I42: =E42*N42*(1+M42) -> 0 | J42: =SUM(I42) -> 0 | M42: 0 | N42: 0
C43: 2-DR FREEZER | D43: Relocation only, Excluding Installation | E43: 1 | F43: EA | G43: 1.5 | H43: MH, 2 MOVERS | I43: =E43*N43*(1+M43) -> 0 | J43: =SUM(I43) -> 0 | M43: 0 | N43: 0
C44: 2-DR FRIDGE | D44: Relocation only, Excluding Installation | E44: 1 | F44: EA | G44: 1.5 | H44: MH, 2 MOVERS | I44: =E44*N44*(1+M44) -> 0 | J44: =SUM(I44) -> 0 | M44: 0 | N44: 0
C45: 3-COMP SINK & ASSOCIATED ITEMS | D45: Relocation only, Excluding Installation | E45: 1 | F45: EA | G45: 2 | H45: MH, 3 (INCL LEAD) | I45: =E45*N45*(1+M45) -> 0 | J45: =SUM(I45) -> 0 | M45: 0 | N45: 0
C46: BLENDERS | D46: Relocation only, Excluding Installation | E46: 2 | F46: EA | G46: 0.5 | H46: MH, 1 MOVER | I46: =E46*N46*(1+M46) -> 0 | J46: =SUM(I46) -> 0 | M46: 0 | N46: 0
C47: CUP CADDY & DISPENSERS | D47: Relocation only, Excluding Installation | E47: 1 | F47: EA | G47: 0.25 | H47: MH, 1 MOVER | I47: =E47*N47*(1+M47) -> 0 | J47: =SUM(I47) -> 0 | M47: 0 | N47: 0
C48: CUP LABELER | D48: Relocation only, Excluding Installation | E48: 4 | F48: EA | G48: 2 | H48: MH, 1 MOVER | I48: =E48*N48*(1+M48) -> 0 | J48: =SUM(I48) -> 0 | M48: 0 | N48: 0
C49: ESPRESSO MACHINES | D49: Relocation only, Excluding Installation | E49: 2 | F49: EA | G49: 2 | H49: MH, 2 MOVERS | I49: =E49*N49*(1+M49) -> 0 | J49: =SUM(I49) -> 0 | M49: 0 | N49: 0
...

Sheet Flooring & Tile
B1: Flooring & Tile Finishes
B3: BASE TAKE-OFF
B5: Unit Name | C5: Product | D5: Qty by Unit | E5: Waste Add-on | G5: Total | J5: MANHOURS/SF | K5: TOTAL MANHOURS
D6: NET
B7: 19795 | C7: Polyvinyl Floor Tile - Eco-Grip - Pewter - 60" x 96" x 1/4" thk | D7: 98.7 | E7: =D7*$F$6 -> 0 | G7: =E7 -> 0 | H7: SY | J7: 1.08 | K7: =ROUNDUP(J7*D7,0) -> 107
B8: 20230 | C8: Floor Tile - I COCCI - Graphite - 24" x 24" (Installation only) | D8: 1697.4 | E8: =D8*$F$6 -> 0 | G8: =E8 -> 0 | H8: SF | J8: 0.14 | K8: =ROUNDUP(J8*D8,0) -> 238
B9: 20267 | C9: Wall Tile - French Clay - Bronzage - 12" x 24" - Vertical Stacked (Installation only) | D9: 335.1 | E9: =D9*$F$6 -> 0 | G9: =E9 -> 0 | H9: SF | J9: 0.14 | K9: =ROUNDUP(J9*D9,0) -> 47
B10: 24559 | C10: Wall Tile - Flatiron - Olivia - Gloss - 2.5" x 9" Vertical Stacked (Installation only) | D10: 156.9 | E10: =D10*$F$6 -> 0 | G10: =E10 -> 0 | H10: SF | J10: 0.14 | K10: =ROUNDUP(J10*D10,0) -> 22
B11: x0409 | C11: Tile Base - Daltile Color Wheel - A3361MOD, Matte Black k711 (Installation only) | D11: 42.9 | E11: =D11*$F$6 -> 0 | G11: =E11 -> 0 | H11: LF | J11: 0.3 | K11: =ROUNDUP(J11*D11,0) -> 13
B12: 11403 | C12: Tile Base - Nero - 6"x12" (Installation only) | D12: 189.3 | E12: =D12*$F$6 -> 0 | G12: =E12 -> 0 | H12: LF | J12: 0.12 | K12: =ROUNDUP(J12*D12,0) -> 23
B13: 19795 | C13: Tile Base - Polyvinyl Floor Tile - Eco-Grip - Pewter - 6" | D13: 243.6 | E13: =D13*$F$6 -> 0 | G13: =E13 -> 0 | H13: LF | J13: 0.3 | K13: =ROUNDUP(J13*D13,0) -> 74
B14: x0404 | C14: Schluter Base - Dilex AHK-AGRB - Brushed Graphite | D14: 58.4 | E14: =D14*$F$6 -> 0 | G14: =E14 -> 0 | H14: LF | J14: 0.1 | K14: =ROUNDUP(J14*D14,0) -> 6
B15: x0801 | C15: Trim - Schluter Jolly Edge Trim - Aluminum Matte Black - Code: J100MGS | D15: 4.09 | E15: =D15*$F$6 -> 0 | G15: =E15 -> 0 | H15: LF | J15: 0.05 | K15: =ROUNDUP(J15*D15,0) -> 1
C16: Schluter Transition Strip for Tile to Eco-Grip | D16: 16.3 | E16: =D16*$F$6 -> 0 | G16: =E16 -> 0 | H16: LF | J16: 0.06 | K16: =ROUNDUP(J16*D16,0) -> 1
C17: Transition for Walk Off Mat to Tile - Schluter Systems - Edge Metal - Schiene - 3/8" | D17: 16.1 | E17: =D17*$F$6 -> 0 | G17: =E17 -> 0 | H17: LF | J17: 0.05 | K17: =ROUNDUP(J17*D17,0) -> 1
B21: NOTES:
B22: Flooring & Tile
B23: Finish Material Schedule per print I603.
B24: Items that are provided by SB and to be installed only by GC ; Tile 20230, tile base x0409, tile base 11403, tile 24599 and tile 20267.
B25: Polyvinyl floor tile is considered as SY unit in the takeoff ; size sheets: 60" x 96" x 1/4" thk.
B26: Polyvinyl floor tile base is considered as LF unit in the takeoff.
B27: Walk Off Mat is existing to remain per plan notes.

Sheet FDI
B3: Description | C3: Location | D3: QTY (LF) | E3: Drywall Height (LF) - Side 1 | F3: Drywall Height (LF) - Side 2 | G3: Side 1 (Interior Side) | K3: Side 2 (Exterior Side) | O3: Multiplier | P3: Wall Area (SF) | T3: STUDS
G4: Sheathing Type | H4: THK | I4: Finish Level | J4: No. of Layers | K4: Sheathing Type | L4: THK | M4: Finish Level | N4: No. of Layers | P4: Side 1 | Q4: Side 2 | R4: 1 1/2" 20ga x 12' @ 16"OC | S4: 1 1/2" 20ga Bracing x 8' @ 48"OC | T4: 3 5/8" 20ga x 20' @ 16"OC | U4: 3 5/8" 16ga x 14' @ 16"OC | V4: 3 5/8" 20ga x 12' @ 16"OC | W4: 3 5/8" 20ga Bracing x 8' @ 48"OC | X4: 3 5/8" 16ga x 2' @ 16"OC | Y4: 6" 20ga x 20' @ 16"OC | Z4: 6" 20ga x 14' @ 16"OC | AA4: 6" 20ga x 12' @ 16"OC | AB4: 6" 20ga Bracing x 8' @ 48"OC
B5: WALLS
B6: PHASE 1
B7: 1-T-N | C7: Interior Wall | D7: 4 | E7: 12 | G7: 5/8" Gypsum Board Type X | H7: 45785 | I7: 4 | J7: 1 | O7: 1 | P7: =D7*E7*J7*O7 -> 48 | Q7: =D7*F7*N7*O7 -> 0 | R7: =D7 -> 4 | S7: =D7 -> 4
B8: 2-F-N | C8: Interior Wall | D8: 27 | E8: 19 | G8: 5/8" Gypsum Board Type X | H8: 45785 | I8: 4 | J8: 1 | O8: 1 | P8: =D8*E8*J8*O8 -> 513 | Q8: =D8*F8*N8*O8 -> 0 | T8: =D8 -> 27
B9: 2-P-N | C9: Interior Wall | D9: 32 | E9: 12 | G9: 5/8" Gypsum Board Type X | H9: 45785 | I9: 4 | J9: 1 | O9: 1 | P9: =D9*E9*J9*O9 -> 384 | Q9: =D9*F9*N9*O9 -> 0 | V9: =D9 -> 32
B10: 2-T-N | C10: Interior Wall | D10: 18 | E10: 12 | G10: 5/8" Gypsum Board Type X | H10: 45785 | I10: 4 | J10: 1 | O10: 1 | P10: =D10*E10*J10*O10 -> 216 | Q10: =D10*F10*N10*O10 -> 0 | V10: =D10 -> 18 | W10: =D10 -> 18
B11: 3-F-N | C11: Interior Wall | D11: 17 | E11: 19 | F11: 12 | G11: 5/8" Gypsum Board Type X | H11: 45785 | I11: 4 | J11: 1 | K11: 5/8" Gypsum Board Type X | L11: 45785 | M11: 4 | N11: 1 | O11: 1 | P11: =D11*E11*J11*O11 -> 323 | Q11: =D11*F11*N11*O11 -> 204 | T11: =D11 -> 17
B12: 3-P-N | C12: Interior Wall | D12: 3 | E12: 2 | F12: 2 | G12: 5/8" Gypsum Board Type X | H12: 45785 | I12: 4 | J12: 1 | K12: 5/8" Gypsum Board Type X | L12: 45785 | M12: 4 | N12: 1 | O12: 1 | P12: =D12*E12*J12*O12 -> 6 | Q12: =D12*F12*N12*O12 -> 6 | X12: =D12 -> 3
B13: 3-T-N | C13: Interior Wall | D13: 44 | E13: 12 | F13: 12 | G13: 5/8" Gypsum Board Type X | H13: 45785 | I13: 4 | J13: 1 | K13: 5/8" Gypsum Board Type X | L13: 45785 | M13: 4 | N13: 1 | O13: 1 | P13: =D13*E13*J13*O13 -> 528 | Q13: =D13*F13*N13*O13 -> 528 | V13: =D13 -> 44 | W13: =D13 -> 44
B14: 3-T-N-H | C14: Interior Wall | D14: 7 | E14: 14 | F14: 14 | G14: 5/8" Gypsum Board Type X | H14: 45785 | I14: 4 | J14: 1 | K14: 5/8" Gypsum Board Type X | L14: 45785 | M14: 4 | N14: 1 | O14: 1 | P14: =D14*E14*J14*O14 -> 98 | Q14: =D14*F14*N14*O14 -> 98 | U14: =D14 -> 7 | W14: =D14 -> 7
B15: 4-F-N | C15: Interior Wall | D15: 3 | E15: 19 | F15: 12 | G15: 5/8" Gypsum Board Type X | H15: 45785 | I15: 4 | J15: 1 | K15: 5/8" Gypsum Board Type X | L15: 45785 | M15: 4 | N15: 1 | O15: 1 | P15: =D15*E15*J15*O15 -> 57 | Q15: =D15*F15*N15*O15 -> 36 | Y15: =D15 -> 3
B16: 4-T-N | C16: Interior Wall | D16: 9 | E16: 14 | F16: 14 | G16: 5/8" Gypsum Board Type X | H16: 45785 | I16: 4 | J16: 1 | K16: 5/8" Gypsum Board Type X | L16: 45785 | M16: 4 | N16: 1 | O16: 1 | P16: =D16*E16*J16*O16 -> 126 | Q16: =D16*F16*N16*O16 -> 126 | Z16: =D16 -> 9 | AB16: =D16 -> 9
B17: 4-T-N | C17: Interior Wall | D17: 33 | E17: 12 | F17: 12 | G17: 5/8" Gypsum Board Type X | H17: 45785 | I17: 4 | J17: 1 | K17: 5/8" Gypsum Board Type X | L17: 45785 | M17: 4 | N17: 1 | O17: 1 | P17: =D17*E17*J17*O17 -> 396 | Q17: =D17*F17*N17*O17 -> 396 | AA17: =D17 -> 33 | AB17: =D17 -> 33
B18: 5-T-N | C18: Interior Wall | D18: 10 | E18: 12 | G18: 5/8" Gypsum Board Type X | H18: 45785 | I18: 4 | J18: 1 | O18: 1 | P18: =D18*E18*J18*O18 -> 120 | Q18: =D18*F18*N18*O18 -> 0 | AA18: =D18 -> 10 | AB18: =D18 -> 10
B19: GWB TYPE X MR | C19: Work Room, Partner Area | D19: 16 | E19: 14 | G19: 5/8" Gypsum Board Type X MR | H19: 45785 | I19: 4 | J19: 1 | O19: 1 | P19: =D19*E19*J19*O19 -> 224 | Q19: =D19*F19*N19*O19 -> 0
B20: GWB TYPE X MR | C20: Work Room, Partner Area | D20: 105 | E20: 12 | G20: 5/8" Gypsum Board Type X MR | H20: 45785 | I20: 4 | J20: 1 | O20: 1 | P20: =D20*E20*J20*O20 -> 1260 | Q20: =D20*F20*N20*O20 -> 0
B21: 14 CBB | C21: Backbar | D21: 65 | E21: 12 | G21: 1/4" Cement Backer Board | H21: 45661 | J21: 1 | O21: 1 | P21: =D21*E21*J21*O21 -> 780 | Q21: =D21*F21*N21*O21 -> 0
O22: =G7 -> 5/8" Gypsum Board Type X | P22: =SUMIF($G$7:$G$21,O22,$P$7:$P$21) -> 2815 | Q22: =SUMIF($K$7:$K$21,O22,$Q$7:$Q$21) -> 1394 | R22: =SUM(R7:R20) -> 4 | S22: =SUM(S7:S20) -> 4 | T22: =SUM(T7:T20) -> 44 | U22: =SUM(U7:U20) -> 7 | V22: =SUM(V7:V20) -> 94 | W22: =SUM(W7:W20) -> 69 | X22: =SUM(X7:X20) -> 3 | Y22: =SUM(Y7:Y20) -> 3 | ... AB22: =SUM(AB7:AB20) -> 52
O23: =G19 -> 5/8" Gypsum Board Type X MR | P23: =SUMIF($G$7:$G$21,O23,$P$7:$P$21) -> 1484 | Q23: =SUMIF($K$7:$K$21,O23,$Q$7:$Q$21) -> 0
O24: =G21 -> 1/4" Cement Backer Board | P24: =SUMIF($G$7:$G$21,O24,$P$7:$P$21) -> 780 | Q24: =SUMIF($K$7:$K$21,O24,$Q$7:$Q$21) -> 0
B25: Description | C25: Location | D25: Perimeter/ Length (LF) | E25: Area (SF) | F25: Height (LF) | G25: Side 1 | J25: Ceiling Area (SF)
G27: Sheathing Type | H27: Finish Level | I27: No. of Layers | J27: Side 1 | K27: STUD
B28: Ceiling | K28: 3 5/8" 20ga x 12' @ 16"OC | L28: 3 5/8" 20ga Bracing x 12' @ 48"OC | M28: 3 5/8" 20ga x 1' @ 16"OC | N28: 3 5/8" 20ga x 10' @ 16"OC | O28: (2) 6" 16ga CSJ x 8' @ 8"OC | P28: (2) 6" 16ga x 6' @ 8"OC
B29: PHASE 1
B30: Gypsum Board Ceiling | E30: 779 | G30: 5/8" Gypsum Board Type X | H30: 4 | I30: 1 | J30: =E30*I30 -> 779
B31: Soffit, H=4' | D31: 88 | E31: =D31*F31 -> 352 | F31: 4 | G31: 5/8" Gypsum Board Type X | H31: 4 | I31: 1 | J31: =E31*I31 -> 352 | K31: =D31 -> 88 | L31: =D31 -> 88
B32: Soffit, H=1' | D32: 117 | E32: =D32*F32 -> 117 | F32: 1 | G32: 5/8" Gypsum Board Type X | H32: 4 | I32: 1 | J32: =E32*I32 -> 117 | M32: =D32 -> 117
B33: Header, H=1' | D33: 34 | E33: =D33*F33 -> 34 | F33: 1 | G33: 5/8" Gypsum Board Type X | H33: 4 | I33: 1 | J33: =E33*I33 -> 34 | M33: =D33 -> 34
B34: Box Header, 2s, H=9' | D34: 9 | E34: =D34*F34*2 -> 162 | F34: 9 | G34: 5/8" Gypsum Board Type X | H34: 4 | I34: 1 | J34: =E34*I34 -> 162 | N34: =D34 -> 9
B35: 12 CBB & 58 GWB Type X MR | C35: Water Heater Shelf | D35: =3+2/12 -> 3.1666667 | E35: 20 | F35: =6+3/12 -> 6.25 | G35: 5/8" Gypsum Board Type X MR | H35: 4 | I35: 1 | J35: =E35*I35 -> 20 | O35: =D35 -> 3.1666667
D36: =3+2/12 -> 3.1666667 | E36: 20 | F36: =6+3/12 -> 6.25 | G36: 1/2" Cement Backer Board | I36: 1 | J36: =E36*I36 -> 20
B37: 58 GWB Type X | C37: Water Heater Shelf | D37: 5 | E37: =D37*F37*2 -> 60 | F37: 6 | G37: 5/8" Gypsum Board Type X | H37: 4 | I37: 1 | J37: =E37*I37 -> 60 | P37: =D37 -> 5
I38: =G30 -> 5/8" Gypsum Board Type X | J38: =SUMIF($G$30:$G$36,I38,$J$30:$J$36) -> 1444 | K38: =SUM(K30:K37) -> 88 | L38: =SUM(L30:L37) -> 88 | M38: =SUM(M30:M37) -> 151 | N38: =SUM(N30:N37) -> 9 | O38: =SUM(O30:O37) -> 3.1666667 | P38: =SUM(P30:P37) -> 5
I39: =G35 -> 5/8" Gypsum Board Type X MR | J39: =SUMIF($G$30:$G$36,I39,$J$30:$J$36) -> 20
I40: =G36 -> 1/2" Cement Backer Board | J40: =SUMIF($G$30:$G$36,I40,$J$30:$J$36) -> 20
B41: Description | C41: Location | D41: AREA (SF) | F41: QTY | H41: Waste Add-on
B43: ACT | H43: 1.03
B46: FRAMING | C46: Location | D46: QTY | F46: Waste Add-on
...

Sheet Landscaping
A1: Item/Material | B1: Description | C1: Quantities
A2: PLANTS
A3: Mixture of Plants | B3: Sanseviera-Tall, Flowering Annuals-Small, Sweet Potato Vine- Low/Hanging | C3: 7.8
A4: Bird of Paradise | B4: Tall Height | C4: 1
A5: Limelight | B5: Medium Height | C5: 2
A6: ZZ Plant | B6: Medium Height | C6: 2
A7: Golden Pathos | B7: Low Height | C7: 1
A8: Prayer Plant | B8: Low Height | C8: 1
A9: Bird's Nest Fern | B9: Low Height | C9: 1
A10: Sanseviera | B10: Low Height | C10: 1
A12: PLANTER
A13: EXTERIOR
A14: Auroa Clay Outdoor Planters Large | B14: furnished by SB and install by GC | C14: 1
A15: INTERIOR
A16: Parker Pedestal Med Planter-Alabaster, Standard Entry | B16: furnished by SB and install by GC | C16: 1
A17: Flueted Ceramic- TableTop White-Small | B17: furnished by SB and install by GC | C17: 2
A18: Flueted Ceramic- TableTop White-Medium | B18: furnished by SB and install by GC | C18: 2
A20: MISCELLANEOUS
A21: Umbrella Base | B21: furnished by SB and install by GC | C21: 1
A22: Umbrella without Valance | B22: furnished by SB and install by GC | C22: 1
A25: Notes:
A26: Included items that are furnished by Starbucks but to be intalled by GC.
A27: Plant location to be planted on table top counter not specified, so we just used the schedule in the tak-off.
A28: No specified number of plants for Design ID X0004 – Mixture of Plants, so we’re taking off the area for planting.

Sheet Opening
B1: Openings
B3: NOTES:
B4: DOOR
B5: There is a door schedule found on plan, see sheet A601.
B6: Door tag 10190 was not identified on available plans, consider it as in the passage of workroom to restroom/exit corridor.
B7: Hardware set of restrooms are consider and its quanties are 2.
B8: Doors have 1/2" undercut, and non rabbet.
B11: BASE TAKE-OFF
B12: Item | C12: Description | D12: Qty by Unit | E12: MANHOUR | G12: Waste Add-on | I12: Total | L12: Unit Material
D13: NET
B15: Interior Door
B16: Flush Hollow Metal Door, with Frame: SW7047SG, Min: 3 Coats LH Swing
B17: 3'-0''W X 7'-0''W | D17: 1 | I17: =D17 -> 1 | J17: EA | L17: 0
B19: Flush w/ Narrow Lite Panel Hollow Metal Door, Finish: PL0019 with Frame: SW6258-SG, Min: 3 Coats Double Acting
B20: 3'-0''W X 7'-0''W | D20: 2 | I20: =D20 -> 2 | J20: EA | L20: 0
B22: Door Hardware
B23: Hardware Set No. 6
B24: Hanging Items | C24: Manuf.: McKinney - Model: TA2714/MPB79 Hinge MacPro Bearing 4.5 x 4.5 Finish: 626 | D24: 6 | I24: =D24 -> 6 | J24: EA | L24: 0
B25: Securing Devices | C25: Manuf.: Yale Lock - Model: PB5425LN Lock, Shallow Coin Turn, Privacy PB5425LN-693-497 1-3/4 Finish: 626 | D25: 2 | I25: =D25 -> 2 | J25: EA | L25: 0
B26: Closing Devices | C26: Manuf.: Dorma - Model: 8916 Door Closer 8916 AF89P Finish: 689 | D26: 2 | I26: =D26 -> 2 | J26: EA | L26: 0
B27: Protective Trim Units | C27: Manuf.: Rockwood - Model: K1050 B4E Kickplate 8" x 34" Each Side 32D Finish: 630 | D27: 4 | I27: =D27 -> 4 | J27: EA | L27: 0
B28: Accessories | C28: Manuf.: Glynn Johnson - Model: GJ64 Rubber Silencer Finish: Gray | D28: 6 | I28: =D28 -> 6 | J28: EA | L28: 0
B29: Stops and Holders | C29: Manuf.: Rockwood - Model: 473 Door Stop w/ Hook Finish: 626 | D29: 2 | I29: =D29 -> 2 | J29: EA | L29: 0
B31: Hardware Set No. 11 | I31: =D31 -> 0
B32: Traffice Door Package | C32: Manuf: Eliason - Model: SCP8 36" x 84", Finish: as selected by owner | D32: 2 | I32: =D32 -> 2 | J32: EA | L32: 0
B34: Hardware Set No. 15
B35: Hanging Devices | C35: Manuf.: McKinney - Model: TA2714/MPB79 Finish: 626 | D35: 3 | I35: =D35 -> 3 | J35: EA | L35: 0
B36: Securing Devices | C36: Manuf.: Yale Lock - Model: B-PB4540SLNIC Lever Storeroom LC B-PB4540SLN-693-497 1-3/4 Finish: 626 | D36: 1 | I36: =D36 -> 1 | J36: EA | L36: 0
B37: Securing Devices | C37: Manuf.: Falcon Lock - Model: C607 7-Pin Core Combinated "A" Keyway Finish: 626 | D37: 1 | I37: =D37 -> 1 | J37: EA | L37: 0
B38: Closing Devices | C38: Manuf.: Dorma - Model: 8916 Door Closer 8916 AF89P AL Finish: 689 | D38: 1 | I38: =D38 -> 1 | J38: EA | L38: 0
B39: Protective Trim Units | C39: Manuf.: Rockwood - Model: K1050 B4E Kickplate 10" x 2" LDW Finish: 630 | D39: 1 | I39: =D39 -> 1 | J39: EA | L39: 0
B40: Accessories | C40: Manuf.: National Guard - Model: 137NA Weather Strip 17" 36" x 84" Finish: A | D40: 1 | I40: =D40 -> 1 | J40: EA | L40: 0
B41: Stops and Holders | C41: Manuf.: Rockwood - Model: 473 Door Stop w/ Hook Finish: 626 | D41: 1 | I41: =D41 -> 1 | J41: EA | L41: 0
B45: NOTES:
B46: WINDOW
B47: All windows are existing.

Sheet Millwork & Interior Trim
B1: MILLWORK
B3: NOTES:
B4: MILLWORK
B5: There is a casework schedule found on plans. See sheet I603. For items that are shown on plans are trace per enlarged plan and match it quantities.
B6: All items are in count as it specifications are already mentioned and considered.
B7: All items are per SB furnished and only GC are by install, thus no unit material cost are considered.
B8: Highlighted items on sheet I603 are not found on available plans but consider its quantity for reference.
B9: Other non-millwork items falls on finishes.
B12: BASE TAKE-OFF
B13: Item | C13: Description | D13: Qty by Unit | E13: MANHOUR | G13: Waste Add-on | I13: Total | L13: Unit Material
D14: NET
B16: MILLWORK ITEMS SHOWN ON PLANS
B17: BACKBAR | I17: =D17 -> 0 | J17: =G17 -> 0
B18: 22395_Countertop - Hand Sink Low Splash - 15in 380mm | D18: 2 | I18: =D18 -> 2 | J18: EA
B19: x0106_Countertop - Filler Backbar - Variable Length | D19: 1 | I19: =D19 -> 1 | J19: EA
B20: x0108_Countertop - Warming - RF - 92in 2335mm | D20: 1 | I20: =D20 -> 1 | J20: EA
B21: x0107_Countertop - Brew - RF - 80in 2285mm | D21: 1 | I21: =D21 -> 1 | J21: EA
B22: x0105_Countertop - Custom Rounded Wood Edge WD0077 | D22: 1 | I22: =D22 -> 1 | J22: EA
B23: 21928_Countertop - End Cap Backbar | D23: 1 | I23: =D23 -> 1 | J23: EA
B24: x0102_Countertop - CBE Rinse Sink 90lb Ice Bin | D24: 1 | I24: =D24 -> 1 | J24: EA
B25: x0104_Countertop - Custom Rounded Wood Edge WD0077 | D25: 1 | I25: =D25 -> 1 | J25: EA
B26: 21918_Countertop - Filler Frontbar - Variable Length | D26: 1 | I26: =D26 -> 1 | J26: EA
B27: 22353_Countertop - Espresso Frontbar - RF - 14in 3580mm | D27: 1 | I27: =D27 -> 1 | J27: EA
B28: 22354_Countertop - Espresso Shroud - 14in 3580mm | D28: 1 | I28: =D28 -> 1 | J28: EA
B29: 21920_Countertop - Frontbar - 15in 380mm | D29: 2 | I29: =D29 -> 2 | J29: EA
... B42: 11155_Other - Espresso Machine Pump Mount - 10x10in 255x255mm | D42: 1 | I42: =D42 -> 1 | J42: EA
I43: =D43 -> 0
B44: SALES & SEATING | I44: =D44 -> 0
B45: 20352_Cafe - Freestanding Inline 2 Unit Short - 72in 1830mm - Walnut WD0077 | D45: 1 | I45: =D45 -> 1 | J45: EA
B46: 20344_Cafe - Wall Bay on Standard 2 Unit - RF - 92in 2335mm Walnut WD0077 | D46: 1 | I46: =D46 -> 1 | J46: EA
B47: x0101_Cafe - Custom Shelving - WD0077 Walnut | D47: 1 | I47: =D47 -> 1 | J47: EA
B48: 23963_Cafe - Waste and Recycle Station Three Drop - Warm Brown Woodgrain and White PL0030 CP0002 | D48: 1 | I48: =D48 -> 1 | J48: EA
B50: MILLWORK ITEMS NOT SHOWN ON PLANS
B51: CAFE AND CABINET
B52: 21894_Cabinet - Door - 15in 380mm | D52: 7 | I52: =D52 -> 7 | J52: EA
B53: 21895_Cabinet - Door Trash - 15in 380mm | D53: 4 | I53: =D53 -> 4 | J53: EA
B54: 21896_Cabinet - Drawer - 15in 380mm | D54: 1 | I54: =D54 -> 1 | J54: EA
B55: 21905_Cabinet - Door - 30in 760mm | D55: 2 | I55: =D55 -> 2 | J55: EA
B56: 21913_Cabinet - Equipment Mounting Panel | D56: 2 | I56: =D56 -> 2 | J56: EA
B57: 22749_Cabinet - Espresso Pump Mount Panel | D57: 1 | I57: =D57 -> 1 | J57: EA
...

Sheet Specialties
B1: Specialties
B3: BASE TAKE-OFF
B5: Item | C5: Description | D5: Qty by Unit | E5: MANHOUR | G5: Waste Add-on | I5: Total
D6: NET
B8: TOILET ACCESSORIES
B9: 16" x 48" Pill Shaped Mirror | C9: West Elm #2997254 | D9: 2 | G9: =D9*H9 -> 0 | H9: 0 | I9: =SUM(D9:G9) -> 2 | J9: EA
B10: 42" x 36" Wide Arch Mirror | C10: West Elm #1682424 | D10: 1 | G10: =D10*H10 -> 0 | H10: 0 | I10: =SUM(D10:G10) -> 1 | J10: EA
B11: Counter Mounted Soap Dispenser - OFCI | D11: 2 | G11: =D11*H11 -> 0 | H11: 0 | I11: =SUM(D11:G11) -> 2 | J11: EA
B12: Recessed Mounted Baby Changing Station | D12: 2 | G12: =D12*H12 -> 0 | H12: 0 | I12: =SUM(D12:G12) -> 2 | J12: EA
B13: Surface Mounted Hand Dryer - OFCI | D13: 2 | G13: =D13*H13 -> 0 | H13: 0 | I13: =SUM(D13:G13) -> 2 | J13: EA
B14: Surface Mounted Horizontal Soap Dispenser - OFCI | D14: 2 | G14: =D14*H14 -> 0 | H14: 0 | I14: =SUM(D14:G14) -> 2 | J14: EA
B15: Surface Mounted Paper Towel Dispenser - OFCI | C15: Half Size - Translucent Gray | D15: 2 | G15: =D15*H15 -> 0 | H15: 0 | I15: =SUM(D15:G15) -> 2 | J15: EA
B16: Surface-Mounted Coat Hook - OFCI | D16: 2 | G16: =D16*H16 -> 0 | H16: 0 | I16: =SUM(D16:G16) -> 2 | J16: EA
B17: Coat Hook Strip - OFCI | D17: 1 | G17: =D17*H17 -> 0 | H17: 0 | I17: =SUM(D17:G17) -> 1 | J17: EA
B18: Hand Dryer Back Panel - OFCI | D18: 2 | G18: =D18*H18 -> 0 | H18: 0 | I18: =SUM(D18:G18) -> 2 | J18: EA
B19: Mirror - BOH - OFCI | D19: 1 | G19: =D19*H19 -> 0 | H19: 0 | I19: =SUM(D19:G19) -> 1 | J19: EA
B20: Mop Rack with 3 Holders - OFCI | D20: 4 | G20: =D20*H20 -> 0 | H20: 0 | I20: =SUM(D20:G20) -> 4 | J20: EA
B22: WIRE SHELVING
B23: Work Room Shelving - OFCI | C23: Size: 36" | D23: 11 | G23: =D23*H23 -> 0 | H23: 0 | I23: =SUM(D23:G23) -> 11 | J23: EA
B24: Work Room Shelving Cart Kit - OFCI | D24: 1 | G24: =D24*H24 -> 0 | H24: 0 | I24: =SUM(D24:G24) -> 1 | J24: EA
B25: Work Room Shelving Posts - OFCI | D25: 11 | G25: =D25*H25 -> 0 | H25: 0 | I25: =SUM(D25:G25) -> 11 | J25: EA
B26: 24" x 18" Base - OFCI | D26: 4 | G26: =D26*H26 -> 0 | H26: 0 | I26: =SUM(D26:G26) -> 4 | J26: EA
B28: WALL PROTECTION
B29: 9'-4"H Metal Corner Guard | C29: Size: 1" Color: Pewter | D29: 3 | G29: =D29*H29 -> 0 | H29: 0 | I29: =SUM(D29:G29) -> 3 | J29: EA
B30: 9'-6"H Metal Corner Guard | C30: Size: 1" Color: Pewter | D30: 12 | G30: =D30*H30 -> 0 | H30: 0 | I30: =SUM(D30:G30) -> 12 | J30: EA
B31: 11'-6"H Metal Corner Guard | C31: Size: 1" Color: Pewter | D31: 1 | G31: =D31*H31 -> 0 | H31: 0 | I31: =SUM(D31:G31) -> 1 | J31: EA
B33: FIRE PROTECTION SPECIALTIES
B34: Fire Extinguisher on Bracket | D34: 1 | G34: =D34*H34 -> 0 | H34: 0 | I34: =SUM(D34:G34) -> 1 | J34: EA
B36: SIGNAGES
B37: Restroom Signage | C37: Size: 1'-4" D x 1'-2 1/2" H Grade II Braille | D37: 1 | G37: =D37*H37 -> 0 | H37: 0 | I37: =SUM(D37:G37) -> 1 | J37: EA
B38: Accessibility Signage | D38: 1 | G38: =D38*H38 -> 0 | H38: 0 | I38: =SUM(D38:G38) -> 1 | J38: EA
B39: Exit Signage | C39: Size: 6" D x 9" H Grade II Braille | D39: 2 | G39: =D39*H39 -> 0 | H39: 0 | I39: =SUM(D39:G39) -> 2 | J39: EA
B41: FURNITURES
B42: Chair - Cafe Daphine Upholstered - OFCI | C42: Color: Black and Caramel Brown Natural WD0035 F0008 | D42: 8 | G42: =D42*H42 -> 0 | H42: 0 | I42: =SUM(D42:G42) -> 8 | J42: EA
B43: Chair - Cafe Hans 2.0 - OFCI | C43: Color: Mottled Grey | D43: 14 | G43: =D43*H43 -> 0 | H43: 0 | I43: =SUM(D43:G43) -> 14 | J43: EA
B44: Chair - Cafe Peggy - OFCI | C44: Color: Black WD0035 | D44: 14 | G44: =D44*H44 -> 0 | H44: 0 | I44: =SUM(D44:G44) -> 14 | J44: EA
B45: Chair - Cafe Peggy Upholstered - OFCI | C45: Color: Walnut and Caramel Brown Natural WD0077 F0008 | D45: 9 | G45: =D45*H45 -> 0 | H45: 0 | I45: =SUM(D45:G45) -> 9 | J45: EA
B46: Chair - Lounge Hans 2.0 - OFCI | C46: Color: Mottled Grey | D46: 6 | G46: =D46*H46 -> 0 | H46: 0 | I46: =SUM(D46:G46) -> 6 | J46: EA
B47: Chair - Lounge Lottie - OFCI | C47: Color: Banker Saddle | D47: 4 | G47: =D47*H47 -> 0 | H47: 0 | I47: =SUM(D47:G47) -> 4 | J47: EA
B48: Chair - Lounge Moon- OFCI | C48: Color: Black and Caramel Brown Natural MT0028 F0008 | D48: 6 | G48: =D48*H48 -> 0 | H48: 0 | I48: =SUM(D48:G48) -> 6 | J48: EA
...

Sheet Wood Framing
B2: NOTES:
B3: Rough Framing
B4: Assumed SYP#2 Lumber Specie
B5: Considered all blockings to be FRT (A101|Gen. Notes Item B)
B6: New Walls are specified as Metal Studs per schedule at A101
B7: Assumed 2x6 Blockings for Wall Blockings not specified in Plan
B8: 1x4 FRT blocking at openings per detail 5|I509
B9: Considered 3/4" Plywood backing at Details 2|I502 & 2|I503
B10: Considere 2x10 FRT blocking per detail 2 | I504
B12: 1.A Typical Wall Framing Takeoff
B13: DESCRIPTION | C13: Total LF/QTY (Planswift data and rounded up) | D13: OC Spacing (in.) Use 16"OC, UNO | E13: BOTTOM AND TOP PLATE, BLOCKING (LF)
E14: 2 x 6 FRT | F14: 2x4 FRT | G14: 1x4 FRT | H14: 2x10 FRT
B15: 1F
B16: 2x6 FRT Blocking | C16: 125 | E16: 181
B17: 1x4 FRT Wood Blocking (5|I509) | C17: 10 | G17: =+$C17 -> 10
B18: 1x4x9' FRT Wood Blocking (5|I509) | C18: 4 | G18: =+C18*9 -> 36
B19: 1x4x10' FRT Wood Blocking (5|I509) | C19: 2 | G19: =+C19*10 -> 20
B20: 2x4x3' FRT Vert.Blocking (6|1501) | C20: 20 | F20: =+C20*3 -> 60
B21: 2x10 FRT Blocking | C21: 20 | H21: =+$C21 -> 20
C23: =B15&" - SUB TOTAL:" -> 1F - SUB TOTAL: | E23: =ROUNDUP(SUM(E16:E22),0) -> 181 | F23: =ROUNDUP(SUM(F16:F22),0) -> 60 | G23: =ROUNDUP(SUM(G16:G22),0) -> 66 | H23: =ROUNDUP(SUM(H16:H22),0) -> 20
B25: 1.B Structural Wall Framing Takeoff
B26: DESCRIPTION | C26: Total LF/QTY (Planswift data and rounded up) | D26: Sheathing Height (FT) | E26: SHEATHING (4'x8') (SF)
E27: 3/4" x 4' x 8' Plywood
B28: 1F
B29: 3/4" Plywood Backing (H=8') (2|I502) | C29: 10 | D29: 8 | E29: =+C29*D29 -> 80
B30: 3/4" Plywood Backing (2|I503) | C30: 31 | E30: =+C30 -> 31
C32: =B28&" - SUB TOTAL:" -> 1F - SUB TOTAL: | E32: =ROUNDUP(SUM(E28:E31),0) -> 111
B34: M A T E R I A L S U M M A R Y | F34: Studs Specie | G34: SYP#2
B35: Item | C35: Description | D35: Qty | E35: Unit
B36: LUMBER
B37: Misc. Blockings
B38: 2" x 6" x 16' SYP#2 FRT | C38: Blocking at Wall | D38: =ROUNDUP(+E23/16,) -> 12 | E38: EA
B39: 2" x 4" x 16' SYP#2 FRT | C39: Blocking at Wall | D39: =+ROUNDUP(F23/16,) -> 4 | E39: EA
B40: 2" x 10" x 16' SYP#2 FRT | C40: Blocking at Wall | D40: =+ROUNDUP(H23/16,) -> 2 | E40: EA
B41: 1" x 4" x 16' SYP#2 FRT | C41: Blocking at Door Headers & Jambs | D41: =+ROUNDUP(G23/16,) -> 5 | E41: EA
B42: 3/4" x 4' x 8' Plywood | C42: Plywood Backing | D42: =+ROUNDUP(E32/32,0) -> 4 | E42: EA

Sheet Interior Painting & Finishes
B2: NOTES:
B3: Paint and interior finish specifications per print I603
B4: One coat of primer and two coats of paint are considered for all drywall and open to structure.
B5: Two coats of paint are considered for all existing drywall.
B6: One coat of primer is considered for FRP surfaces.
G8: Paint Coverages Area/Gallon
B9: BASE TAKE-OFF | G9: Primer | H9: 250SF/gal
G10: Paint | H10: 300SF/gal
B12: WALL FINISHES (INTERIOR) | E12: Length | F12: Height | G12: Sides | H12: Finish
B13: Brick, x0407 | C13: =E13*F13*G13 -> 156 | D13: SF | E13: 13 | F13: 12 | G13: 1
B14: Brick, x0407 | C14: =E14*F14*G14 -> 266 | D14: SF | E14: 14 | F14: 19 | G14: 1
B15: Brick, x0407 | C15: =E15*F15*G15 -> 234 | D15: SF | E15: 13 | F15: 18 | G15: 1
B16: Wall Cladding, MAD100 | C16: =E16*F16*G16 -> 105 | D16: SF | E16: 21 | F16: 5 | G16: 1
B17: Wall Cladding, MAD100 | C17: =E17*F17*G17 -> 40 | D17: SF | E17: 4 | F17: 10 | G17: 1
B18: Wall Cladding, MAD100 | C18: =E18*F18*G18 -> 252 | D18: SF | E18: 21 | F18: 12 | G18: 1
B19: Wall Cladding, MAD100 | C19: =E19*F19*G19 -> 48 | D19: SF | E19: 16 | F19: 3 | G19: 1
B20: Wall Cladding, MAD100 | C20: =E20*F20*G20 -> 176 | D20: SF | E20: 16 | F20: 11 | G20: 1
B21: Wall Cladding, MAD100-V | C21: =E21*F21*G21 -> 45 | D21: SF | E21: 15 | F21: 3 | G21: 1
B22: Wall Cladding, MAD200 | C22: =E22*F22*G22 -> 108 | D22: SF | E22: 18 | F22: 6 | G22: 1
B23: Wall Covering, X0403 | C23: =E23*F23*G23 -> 221 | D23: SF | E23: 17 | F23: 13 | G23: 1
B24: Wall Covering, X0403 | C24: =E24*F24*G24 -> 440 | D24: SF | E24: 55 | F24: 8 | G24: 1
... B31: Primer on FRP | C31: =E31*F31*G31 -> 1584 | D31: SF | E31: 176 | F31: 9 | G31: 1
B33: CEILING FINISHES | E33: Length | F33: Height
B34: PT on Existing Gypsum, SW7030 | C34: 122 | D34: SF
B35: PT on Gypsum, SW9090-F | C35: 102 | D35: SF
B36: PT on Gypsum, SW9090-ES | C36: 653 | D36: SF
B37: PT on Gypsum, SW9090-ES | C37: =E37*F37 -> 175 | D37: SF | E37: 35 | F37: 5
B38: PT on Gypsum, SW9090-ES | C38: =E38*F38 -> 318 | D38: SF | E38: 53 | F38: 6
B39: PT on Gypsum, SW7030 | C39: 113 | D39: SF
B40: PT on Gypsum, SW7030 | C40: =E40*F40 -> 29 | D40: SF | E40: 29 | F40: 1
B41: PT on Gypsum, SW7048 | C41: =E41*F41 -> 51 | D41: SF | E41: 51 | F41: 1
B42: PT on Gypsum, SW7048 | C42: =E42*F42 -> 255 | D42: SF | E42: 51 | F42: 5
B43: PT on Gypsum, Undefined | C43: =E43*F43 -> 40 | D43: SF | E43: 10 | F43: 4
B44: Paint to Open to Structure, SW7048 | C44: 904 | D44: SF
B45: Acoustical Baffle x0205 | C45: 174 | D45: SF
B46: Acoustical Baffle x0206 | C46: 748 | D46: SF
B47: Coffered Panel | C47: 174 | D47: SF
B48: 2x4 ACT Tile | C48: 552 | D48: SF
B49: ACT Wall Moulding | C49: 173 | D49: LF
B51: DOOR AND DOOR FRAME | E51: no. of Doors | F51: Height | G51: Width | H51: Frame Perimeter
...

Sheet HM Frame Door
B2: Description | C2: QTY (EA) | E2: Unit Material | F2: Total Material | G2: Unit Labor | H2: Total Labor
B4: DOORS
B5: TYPE D1, HM FRAME - 3'-0' x 7'-0' | C5: 7 | E5: 0 | F5: =C5*E5 -> 0 | G5: 0 | H5: =C5*G5 -> 0
B6: TYPE D2, HM FRAME - 16'-0' x 14'-0' | C6: 1 | E6: 0 | F6: =C6*E6 -> 0 | G6: 0 | H6: =C6*G6 -> 0
B7: TYPE D2, HM FRAME - 20'-0' x 14'-0' | C7: 2 | E7: 0 | F7: =C7*E7 -> 0 | G7: 0 | H7: =C7*G7 -> 0

Sheet Exterior Siding
B1: Starbucks - Exterior Siding Takeoffs
B2: 1620 S University Dr, Fort Worth, TX 76107
B3: EXTERIOR SIDINGS
B5: NOTE:
B6: Exterior Siding
B7: Only Patching and repair area were considered in takeoffs.
B8: Brick Veneer considered in the takeoffs as per plan.
B11: EXTERIOR- Windows and Doors
B12: Description/Type Windows | C12: Width (FT') | D12: Height (FT') | E12: QTY | F12: LF w/o Sill | G12: Total LF Surround | H12: Total LF Top | I12: Total LF Sill | J12: Total Window/Door Tape
F13: =G13-I13 -> 0 | G13: =E13*(D13+D13+C13+C13) -> 0 | H13: =C13*E13 -> 0 | I13: =C13*E13 -> 0 | J13: =G13 -> 0
B14: SUM | E14: =SUM(E13) -> 0 | F14: =SUM(F13) -> 0 | G14: =SUM(G13) -> 0 | H14: =SUM(H13) -> 0 | I14: =SUM(I13) -> 0 | J14: =SUM(J13) -> 0
B15: Description/Type Doors | C15: Width (FT') | D15: Height (FT') | E15: QTY | F15: SF | G15: Total LF Surround | H15: Total LF Top | I15: Total LF Threshold | J15: Total Window/Door Tape
F16: =C16*D16*E16 -> 0 | G16: =E16*(D16+D16+C16) -> 0 | H16: =C16*E16 -> 0 | I16: =C16*E16 -> 0 | J16: =G16 -> 0
B17: SUM | E17: =SUM(E16) -> 0 | F17: =SUM(F16) -> 0 | G17: =SUM(G16) -> 0 | H17: =SUM(H16) -> 0 | I17: =SUM(I16) -> 0 | J17: =SUM(J16) -> 0
B19: Sidings | C19: Size / O.C. Spacing | D19: QTY | E19: UNIT
B20: Veneer Siding
B21: Brick Veneer | C21: Patching and Repair | D21: =104.29+58.98 -> 163.27 | E21: SF | I21: =ROUNDUP(D21/1,0) -> 164
B24: Exterior Siding
B25: Siding
B26: Veneer Siding
B27: =B21 -> Brick Veneer | C27: =C21 -> Patching and Repair | D27: =ROUNDUP(D21,0) -> 164 | E27: SF

Sheet Exterior Painting
B1: BASE TAKEOFF
B2: Project: | C2: Waynesville
B3: Address: | C3: 200 Fleetwood Drive, Waynesville, Missouri 65583
B4: Date of Plans | C4: 45733
B5: Date of Bid | C5: 45965
B7: EXTERIOR FINISHES
B8: Exterior Patio Railing Finishes, 2 Coats Stain
B9: 3' H Patio Railing (at Patio)(Painted)(x2) | C9: =PRODUCT(E9:G9) -> 94.44 | D9: LF | E9: 2 | F9: 47.22 | H9: =F9*E9*3 -> 283.32
B11: Exterior Patio Railings | C11: =SUM(C8:C10) -> 94.44 | D11: LF
B12: Exterior Patio Post Finishes, Primer + 2 Coats Paint
B13: 3" Dia Patio Post (Painted)(2x) | C13: =PRODUCT(E13:G13) -> 25.02 | D13: LF | E13: 2 | F13: =4.17*3 -> 12.51 | H13: =C13*0.125 -> 3.1275
B14: 4-1/2" Dia Patio Post (Painted)(2x) | C14: =PRODUCT(E14:G14) -> 60 | D14: LF | E14: 2 | F14: =10*3 -> 30 | H14: =C14*0.1875 -> 11.25
H15: =H13+H14 -> 14.3775
B16: Exterior Patio Post | C16: =C14+C13 -> 85.02 | D16: LF
B20: NOTES:
B21: Painting:
B22: Two coats of stain paint are considered for the Exterior Patio Railings.
B23: One coat of primer and two coats of paint are considered for the Exterior Patio Posts.
B24: As per Key Note 6 , Patio Railing will be restained wood SW3524.
B25: As per Key Note 6 , Patio Post will be repainted SW7048.
