Workbook
Name BuiltIn_Print_Area: #REF!
Name BuiltIn_Print_Area: #REF!
Name BuiltIn_Print_Area: #REF!
Name BuiltIn_Print_Area: #REF!
Name BuiltIn_Print_Area___0: #REF!
Name BuiltIn_Print_Area___0: #REF!
Name BuiltIn_Print_Area___0: #REF!
Name BuiltIn_Print_Area___0___0: #REF!
Name BuiltIn_Print_Area___0___0___0: #REF!
Name BuiltIn_Print_Area___0___0___0___0: #REF!
Name BuiltIn_Print_Area___0___0___0___0___0: #REF!
Name BuiltIn_Print_Titles: #REF!
Name BuiltIn_Print_Titles___0: NA()
Name BuiltIn_Print_Titles___0___0: #REF!
Name BuiltIn_Print_Titles___0___0___0: #REF!
Name BuiltIn_Print_Titles___0___0___0___0: NA()
Name LAN: #REF!
Name PP: #REF!
Name UnitType2: #REF!
Name UnitType2: #REF!
Name URURU: #REF!
Name URURU: #REF!
Name Validation_Equipment: OFFSET('[1]EQUIPMENT DYNAMIC LIST'!$N$2,,,COUNTIF('[1]EQUIPMENT DYNAMIC LIST'!$N$2:$N$500,"?*"))
Name Validation_Fans: OFFSET('[1]FAN DYNAMIC LIST'!$Q$2,,,COUNTIF('[1]FAN DYNAMIC LIST'!$Q$2:$Q$1000,"?*"))
Name Validation_Heaters: OFFSET('[1]HEATER DYNAMIC LIST'!$Q$2,,,COUNTIF('[1]HEATER DYNAMIC LIST'!$Q$2:$Q$1000,"?*"))
Name Validation_MiniSplit: OFFSET('[1]MINI SPLIT DYNAMIC LIST'!$Q$2,,,COUNTIF('[1]MINI SPLIT DYNAMIC LIST'!$Q$2:$Q$1000,"?*"))
Name Validation_PTAC: OFFSET('[1]PTAC DYNAMIC LIST'!$Q$2,,,COUNTIF('[1]PTAC DYNAMIC LIST'!$Q$2:$Q$1000,"?*"))
Name Validation_Thermstats: OFFSET('[1]THERMOSTAT DYNAMIC LIST'!$M$2,,,COUNTIF('[1]THERMOSTAT DYNAMIC LIST'!$M$2:$M$500,"?*"))

Sheet SUMMARY
A2: GC LEGACY CONSTRUCTION
B6: Proposal Date:
B7: =+'BREAKDOWN (BUILDING)'!C1 -> Project Name: University Park Village (Starbucks 6212)
B8: =+A2 -> GC LEGACY CONSTRUCTION
B9: =+'BREAKDOWN (BUILDING)'!C3 -> Plan Date: 8/27/2025
A11: PROJECT PROPOSAL
A12: ITEM | C12: DESCRIPTION | K12: QUANTITY | L12: UOM | M12: LABOR HOURS | N12: TOTAL LABOUR (US$) | O12: TOTAL MATERIAL (US$) | P12: TOTAL AMOUNT(US$)
A14: I. | C14: MATERIALS
E15: ELECTRICAL WORKS
D16: A. | E16: SITE WORKS (not in scope) | O16: =+'BREAKDOWN (SITE)'!T12 -> 0 | P16: =+N16+O16 -> 0
D18: B. | E18: MATERIAL (NON-QUOTED)
D19: 1 | E19: =+'BREAKDOWN (BUILDING)'!C8 -> Feeders | K19: 1 | L19: lot | O19: ='BREAKDOWN (BUILDING)'!T16 -> 0 | P19: =+N19+O19 -> 0
D20: 2 | E20: =+'BREAKDOWN (BUILDING)'!C18 -> Power Supply for Lighting and Small Power | K20: 1 | L20: lot | O20: =+'BREAKDOWN (BUILDING)'!T49 -> 9217.2023 | P20: =+N20+O20 -> 9217.2023
D21: 3 | E21: =+'BREAKDOWN (BUILDING)'!C51 -> Low Voltage System | K21: 1 | L21: lot | O21: ='BREAKDOWN (BUILDING)'!T58 -> 238.1868 | P21: =+N21+O21 -> 238.1868
D22: 4 | E22: Testing and Commissioning | K22: 1 | L22: lot | O22: 1500 | P22: =+N22+O22 -> 1500
D24: C. | E24: MATERIAL (QUOTED)
D25: 1 | E25: =+'BREAKDOWN (BUILDING)'!C61 -> Panelboards and Equipments | K25: 1 | L25: lot | O25: ='BREAKDOWN (BUILDING)'!T73 -> 0 | P25: =+N25+O25 -> 0
D26: 2 | E26: =+'BREAKDOWN (BUILDING)'!C74 -> Lighting Fixtures and Lighting Controls (Owner Supplied) | K26: 1 | L26: lot | O26: 0 | P26: =+N26+O26 -> 0
D27: 3 | E27: Others | O27: 0 | P27: =+N27+O27 -> 0
D29: D. | E29: SALES TAX (9.5% of A + B + C) | K29: 1 | L29: lot | O29: 0 | P29: =SUM(P15:P27)*Q29 -> 1040.762 | Q29: 0.095
C31: TOTAL MATERIAL COST | P31: =SUM(P13:P30) -> 11996.151
A33: II. | C33: LABOR
D34: 1 | E34: Direct Labor | M34: =+'BREAKDOWN (BUILDING)'!P108+'BREAKDOWN (SITE)'!P12 -> 797.55 | N34: =+M34*$Q$37 -> 141963.9 | O34: 0 | P34: =+N34+O34 -> 141963.9
D35: 2 | E35: Non Productive Labor (20% of Direct Labor) | M35: =+M34*Q35 -> 159.51 | N35: =+M35*$Q$37 -> 28392.78 | O35: 0 | P35: =+N35+O35 -> 28392.78 | Q35: 0.2
C37: TOTAL LABOR HOURS AND LABOR COST | M37: =SUM(M34:M36) -> 957.06 | P37: =SUM(P34:P36) -> 170356.68 | Q37: 178
A39: III. | C39: DIRECT JOB EXPENSES
D41: 1 | E41: Scissor Lifts | K41: 3 | L41: equipment month | O41: 1000 | P41: =+O41*K41 -> 3000
D42: 2 | E42: Title 24 | K42: 1 | L42: lot | O42: 1500 | P42: =+O42*K42 -> 1500
D43: 3 | E43: Temp Power/Lighting | K43: 1 | L43: lot | O43: 1500 | P43: =+O43*K43 -> 1500
D44: 4 | E44: Hauling Equipment (if needed) | P44: =+O44*K44 -> 0
D45: 5 | E45: Excavation Equipment (if needed) | P45: 0
C47: TOTAL JOB EXPENSES | P47: =SUM(P39:P46) -> 6000
A49: IV. | C49: MISCELLANEOUS
D51: 1 | E51: Demolition, Safe-Off (if needed) | K51: 1 | L51: lot | P51: =+N51+O51 -> 0
C53: TOTAL MISCELLANEOUS | P53: =SUM(P48:P52) -> 0
A55: V. | C55: SUBCONTRACTS, if any | P55: 0
A57: VI. | C57: DIRECT COST (I + II + III + IV + V) | P57: =+P31+P37+P47+P53+P55 -> 188352.83
A59: VII. | C59: COMPANY OVERHEAD (10% OF TOTAL DIRECT COST) | K59: 1 | L59: lot | P59: =+P57*$Q$59 -> 18835.283 | Q59: 0.1
A61: VIII. | C61: COMPANY PROFIT (15% OF TOTAL DIRECT COST) | K61: 1 | L61: lot | P61: =+P57*$Q$61 -> 28252.925 | Q61: 0.15
A63: IX. | C63: BONDS, if any | P63: 0
...

Sheet BREAKDOWN (BUILDING)
C1: Project Name: University Park Village (Starbucks 6212)
C2: Address: 1620 S University Dr, Fort Worth, TX 76107 | M2: Labor Rate: | N2: 178 | O2: Per Hour | P2: Source: | Q2: NECA
C3: Plan Date: 8/27/2025
B4: Electrical | C4: Electrical | I4: 1ST FLOOR | K4: ROOF PLAN | N4: TOTAL | P4: Total Labor Hrs | Q4: Labor Hours | R4: Total Labor Cost | S4: Material Pricing | T4: Total Material Pricing | U4: Total | V4: REFERENCE
B5: Item No. | C5: Description | D5: Added Description | I5: Qty | J5: Lin. Ft. | K5: Qty | L5: Lin. Ft. | N5: Qty | O5: Lin. Ft. | V5: LABOR HOURS
C6: MAIN BUILDING ELECTRICAL WORKS | E6: CONTRACTOR | G6: CLIENT / VENDOR
E7: PROVIDE | F7: INSTALL | G7: PROVIDE | H7: INSTALL
B8: A.1 | C8: Feeders
C9: Feeder Wires and Conduit
C10: ='TAKEOFF DETAIL'!B14 -> 1-1/4" EMT Conduit | E10: X | F10: X | J10: ='TAKEOFF DETAIL'!BU14 -> 30 | O10: =J10+L10 -> 30 | P10: =IF(N10>0,N10*Q10,O10*Q10) -> 1.86 | Q10: 0.062 | R10: =P10*$N$2 -> 331.08 | T10: =(N10+O10)*S10 -> 0 | U10: =+R10+T10 -> 331.08 | V10: NECA
C11: ='TAKEOFF DETAIL'!B23 -> Copper Wire, 1#3 AWG | E11: X | F11: X | J11: ='TAKEOFF DETAIL'!BU23 -> 120 | O11: =J11+L11 -> 120 | P11: =IF(N11>0,N11*Q11,O11*Q11) -> 1.8 | Q11: 0.015 | R11: =P11*$N$2 -> 320.4 | T11: =(N11+O11)*S11 -> 0 | U11: =+R11+T11 -> 320.4 | V11: NECA
C12: ='TAKEOFF DETAIL'!B24 -> Copper Wire, 1#8G AWG | E12: X | F12: X | J12: ='TAKEOFF DETAIL'!BU24 -> 40 | O12: =J12+L12 -> 40 | P12: =IF(N12>0,N12*Q12,O12*Q12) -> 0.36 | Q12: 0.009 | R12: =P12*$N$2 -> 64.08 | T12: =(N12+O12)*S12 -> 0 | U12: =+R12+T12 -> 64.08 | V12: NECA
C13: Conduit Fittings, support and Wire connectors | E13: X | F13: X | I13: 1 | N13: =I13+K13 -> 1 | P13: =IF(N13>0,N13*Q13,O13*Q13) -> 0 | R13: =P13*$N$2 -> 0 | T13: =(N13+O13)*S13 -> 0 | U13: =+R13+T13 -> 0
C15: Feeder Wires and Conduit | P15: =SUM(P9:P14) -> 4.02 | R15: =SUM(R9:R14) -> 715.56 | T15: =SUM(T9:T14) -> 0 | U15: =SUM(U9:U14) -> 715.56
B16: A.1 | C16: Feeders Total | P16: =P15 -> 4.02 | R16: =R15 -> 715.56 | T16: =T15 -> 0 | U16: =U15 -> 715.56
B18: A.3 | C18: Power Supply for Lighting and Small Power
C19: Wiring Devices (Power Receptacles, Etc. includes boxes)
C20: ='TAKEOFF DETAIL'!B26 -> Junction Box | E20: X | F20: X | I20: ='TAKEOFF DETAIL'!BH26+'TAKEOFF DETAIL'!L61 -> 263 | K20: ='TAKEOFF DETAIL'!BR26 -> 0 | N20: =I20+K20 -> 263 | P20: =IF(N20>0,N20*Q20,O20*Q20) -> 131.5 | Q20: 0.5 | R20: =P20*$N$2 -> 23407 | T20: =(N20+O20)*S20 -> 0 | U20: =+R20+T20 -> 23407 | V20: NECA
C21: ='TAKEOFF DETAIL'!B27 -> Junction Box, Weatherproof | E21: X | F21: X | I21: ='TAKEOFF DETAIL'!BH27 -> 0 | K21: ='TAKEOFF DETAIL'!BR27 -> 10 | N21: =I21+K21 -> 10 | P21: =IF(N21>0,N21*Q21,O21*Q21) -> 5 | Q21: 0.5 | R21: =P21*$N$2 -> 890 | T21: =(N21+O21)*S21 -> 0 | U21: =+R21+T21 -> 890 | V21: NECA
C22: ='TAKEOFF DETAIL'!B28 -> Duplex Receptacle | E22: X | F22: X | I22: ='TAKEOFF DETAIL'!BH28 -> 32 | K22: ='TAKEOFF DETAIL'!BR28 -> 0 | N22: =I22+K22 -> 32 | P22: =IF(N22>0,N22*Q22,O22*Q22) -> 12.8 | Q22: 0.4 | R22: =P22*$N$2 -> 2278.4 | T22: =(N22+O22)*S22 -> 0 | U22: =+R22+T22 -> 2278.4 | V22: NECA
C23: ='TAKEOFF DETAIL'!B29 -> Duplex Dedicated Receptacle | E23: X | F23: X | I23: ='TAKEOFF DETAIL'!BH29 -> 7 | K23: ='TAKEOFF DETAIL'!BR29 -> 0 | N23: =I23+K23 -> 7 | P23: =IF(N23>0,N23*Q23,O23*Q23) -> 2.8 | Q23: 0.4 | R23: =P23*$N$2 -> 498.4 | T23: =(N23+O23)*S23 -> 0 | U23: =+R23+T23 -> 498.4 | V23: NECA
C24: ='TAKEOFF DETAIL'!B30 -> Duplex Receptacle, with Surge Protection Device | E24: X | F24: X | I24: ='TAKEOFF DETAIL'!BH30 -> 2 | K24: ='TAKEOFF DETAIL'!BR30 -> 0 | N24: =I24+K24 -> 2 | P24: =IF(N24>0,N24*Q24,O24*Q24) -> 0.9 | Q24: 0.45 | R24: =P24*$N$2 -> 160.2 | T24: =(N24+O24)*S24 -> 0 | U24: =+R24+T24 -> 160.2 | V24: NECA
C25: =+'TAKEOFF DETAIL'!B65 -> Duplex Receptacle, GFCI Type WP | E25: X | F25: X | I25: =+'TAKEOFF DETAIL'!L65 -> 2 | K25: ='TAKEOFF DETAIL'!BR30 -> 0 | N25: =I25+K25 -> 2 | P25: =IF(N25>0,N25*Q25,O25*Q25) -> 0.9 | Q25: 0.45 | R25: =P25*$N$2 -> 160.2 | T25: =(N25+O25)*S25 -> 0 | U25: =+R25+T25 -> 160.2 | V25: NECA
C26: ='TAKEOFF DETAIL'!B31 -> Duplex Receptacle, Floor Mounted | E26: X | F26: X | I26: ='TAKEOFF DETAIL'!BH31 -> 4 | K26: ='TAKEOFF DETAIL'!BR31 -> 0 | N26: =I26+K26 -> 4 | P26: =IF(N26>0,N26*Q26,O26*Q26) -> 4 | Q26: 1 | R26: =P26*$N$2 -> 712 | T26: =(N26+O26)*S26 -> 0 | U26: =+R26+T26 -> 712 | V26: NECA
C27: ='TAKEOFF DETAIL'!B32 -> Quadruplex Receptacle | E27: X | F27: X | I27: ='TAKEOFF DETAIL'!BH32 -> 10 | K27: ='TAKEOFF DETAIL'!BR32 -> 0 | N27: =I27+K27 -> 10 | P27: =IF(N27>0,N27*Q27,O27*Q27) -> 8 | Q27: 0.8 | R27: =P27*$N$2 -> 1424 | T27: =(N27+O27)*S27 -> 0 | U27: =+R27+T27 -> 1424 | V27: NECA
C28: ='TAKEOFF DETAIL'!B33 -> Special Purpose Receptacle, NEMA 6-50R | E28: X | F28: X | I28: ='TAKEOFF DETAIL'!BH33 -> 2 | K28: ='TAKEOFF DETAIL'!BR33 -> 0 | N28: =I28+K28 -> 2 | P28: =IF(N28>0,N28*Q28,O28*Q28) -> 2 | Q28: 1 | R28: =P28*$N$2 -> 356 | T28: =(N28+O28)*S28 -> 0 | U28: =+R28+T28 -> 356 | V28: NECA | W28: https://www.mscdirect.com/product/details/48670590
C29: ='TAKEOFF DETAIL'!B34 -> Special Purpose Receptacle, NEMA 5-15R | E29: X | F29: X | I29: ='TAKEOFF DETAIL'!BH34 -> 2 | K29: ='TAKEOFF DETAIL'!BR34 -> 0 | N29: =I29+K29 -> 2 | P29: =IF(N29>0,N29*Q29,O29*Q29) -> 2 | Q29: 1 | R29: =P29*$N$2 -> 356 | T29: =(N29+O29)*S29 -> 0 | U29: =+R29+T29 -> 356 | V29: NECA
C30: ='TAKEOFF DETAIL'!B35 -> Special Purpose Receptacle, NEMA 14-50R | E30: X | F30: X | I30: ='TAKEOFF DETAIL'!BH35 -> 2 | K30: ='TAKEOFF DETAIL'!BR35 -> 0 | N30: =I30+K30 -> 2 | P30: =IF(N30>0,N30*Q30,O30*Q30) -> 2 | Q30: 1 | R30: =P30*$N$2 -> 356 | T30: =(N30+O30)*S30 -> 0 | U30: =+R30+T30 -> 356 | V30: NECA | W30: https://www.mscdirect.com/product/details/48670665
C31: ='TAKEOFF DETAIL'!B36 -> Special Purpose Receptacle, NEMA 6-30R | E31: X | F31: X | I31: ='TAKEOFF DETAIL'!BH36 -> 2 | K31: ='TAKEOFF DETAIL'!BR36 -> 0 | N31: =I31+K31 -> 2 | P31: =IF(N31>0,N31*Q31,O31*Q31) -> 2 | Q31: 1 | R31: =P31*$N$2 -> 356 | T31: =(N31+O31)*S31 -> 0 | U31: =+R31+T31 -> 356 | V31: NECA | W31: https://www.mscdirect.com/product/details/60512597
C32: ='TAKEOFF DETAIL'!B37 -> LeGrand Plugmold (MODEL#: BK20GB509TRUAC) | E32: X | F32: X | I32: ='TAKEOFF DETAIL'!BH37 -> 3 | K32: ='TAKEOFF DETAIL'!BR37 -> 0 | N32: =I32+K32 -> 3 | P32: =IF(N32>0,N32*Q32,O32*Q32) -> 6 | Q32: 2 | R32: =P32*$N$2 -> 1068 | T32: =(N32+O32)*S32 -> 0 | U32: =+R32+T32 -> 1068 | V32: NECA | W32: https://www.fergusonhome.com/legrand-20gb509truac/s2057263?srsltid=AfmBOoqJXTpd5-ZjDsxTNyuVEugW0DsiyVGCqS0ikTJyKgVWGh5bQuUW
C34: Wiring Devices (Power Receptacles, Etc. includes boxes) | P34: =SUM(P19:P33) -> 179.9 | R34: =SUM(R19:R33) -> 32022.2 | T34: =SUM(T19:T33) -> 0 | U34: =SUM(U19:U33) -> 32022.2
C35: Conduit and Wires (For Lighting and Small Power)
C36: =+'TAKEOFF DETAIL'!B11 -> 1/2" EMT Conduit | E36: X | F36: X | J36: ='TAKEOFF DETAIL'!BH11+'TAKEOFF DETAIL'!L57 -> 4540 | L36: ='TAKEOFF DETAIL'!BR11 -> 290 | O36: =J36+L36 -> 4830 | P36: =IF(N36>0,N36*Q36,O36*Q36) -> 217.35 | Q36: 0.045 | R36: =P36*$N$2 -> 38688.3 | S36: 0.424 | T36: =(N36+O36)*S36 -> 2047.92 | U36: =+R36+T36 -> 40736.22 | V36: NECA
C37: =+'TAKEOFF DETAIL'!B12 -> 3/4" EMT Conduit | E37: X | F37: X | J37: ='TAKEOFF DETAIL'!BH12 -> 350 | L37: ='TAKEOFF DETAIL'!BR12 -> 110 | O37: =J37+L37 -> 460 | P37: =IF(N37>0,N37*Q37,O37*Q37) -> 23 | Q37: 0.05 | R37: =P37*$N$2 -> 4094 | S37: 0.7509 | T37: =(N37+O37)*S37 -> 345.414 | U37: =+R37+T37 -> 4439.414 | V37: NECA
C38: =+'TAKEOFF DETAIL'!B13 -> 1" EMT Conduit | E38: X | F38: X | J38: ='TAKEOFF DETAIL'!BH13 -> 0 | L38: ='TAKEOFF DETAIL'!BR13 -> 60 | O38: =J38+L38 -> 60 | P38: =IF(N38>0,N38*Q38,O38*Q38) -> 3.3 | Q38: 0.055 | R38: =P38*$N$2 -> 587.4 | S38: 1.272 | T38: =(N38+O38)*S38 -> 76.32 | U38: =+R38+T38 -> 663.72 | V38: NECA
C39: ='TAKEOFF DETAIL'!B16 -> Copper Wire, 2#12 AWG + 1#12G AWG | E39: X | F39: X | J39: ='TAKEOFF DETAIL'!BH16+'TAKEOFF DETAIL'!L59 -> 6090 | L39: ='TAKEOFF DETAIL'!BR16 -> 290 | O39: =J39+L39 -> 6380 | P39: =IF(N39>0,N39*Q39,O39*Q39) -> 114.84 | Q39: =0.006*3 -> 0.018 | R39: =P39*$N$2 -> 20441.52 | S39: =0.18628*3 -> 0.55884 | T39: =(N39+O39)*S39 -> 3565.3992 | U39: =+R39+T39 -> 24006.919 | V39: NECA
C40: ='TAKEOFF DETAIL'!B17 -> Copper Wire, 2#10 AWG + 1#10G AWG | E40: X | F40: X | J40: ='TAKEOFF DETAIL'!BH17 -> 220 | L40: ='TAKEOFF DETAIL'!BR17 -> 0 | O40: =J40+L40 -> 220 | P40: =IF(N40>0,N40*Q40,O40*Q40) -> 4.62 | Q40: =0.007*3 -> 0.021 | R40: =P40*$N$2 -> 822.36 | S40: =0.28491*3 -> 0.85473 | T40: =(N40+O40)*S40 -> 188.0406 | U40: =+R40+T40 -> 1010.4006 | V40: NECA
C41: ='TAKEOFF DETAIL'!B18 -> Copper Wire, 2#8 AWG + 1#10G AWG | E41: X | F41: X | J41: ='TAKEOFF DETAIL'!BH18 -> 20 | L41: ='TAKEOFF DETAIL'!BR18 -> 0 | O41: =J41+L41 -> 20 | P41: =IF(N41>0,N41*Q41,O41*Q41) -> 0.5 | Q41: =0.009*2+0.007*1 -> 0.025 | R41: =P41*$N$2 -> 89 | S41: =0.54097*2+0.28491*1 -> 1.36685 | T41: =(N41+O41)*S41 -> 27.337 | U41: =+R41+T41 -> 116.337 | V41: NECA
C42: ='TAKEOFF DETAIL'!B19 -> Copper Wire, 3#12 AWG + 1#12G AWG | E42: X | F42: X | J42: ='TAKEOFF DETAIL'!BH19 -> 70 | L42: ='TAKEOFF DETAIL'!BR19 -> 70 | O42: =J42+L42 -> 140 | P42: =IF(N42>0,N42*Q42,O42*Q42) -> 3.36 | Q42: =0.006*4 -> 0.024 | R42: =P42*$N$2 -> 598.08 | S42: =0.18628*4 -> 0.74512 | T42: =(N42+O42)*S42 -> 104.3168 | U42: =+R42+T42 -> 702.3968 | V42: NECA
C43: ='TAKEOFF DETAIL'!B20 -> Copper Wire, 3#10 AWG + 1#10G AWG | E43: X | F43: X | J43: ='TAKEOFF DETAIL'!BH20 -> 0 | L43: ='TAKEOFF DETAIL'!BR20 -> 50 | O43: =J43+L43 -> 50 | P43: =IF(N43>0,N43*Q43,O43*Q43) -> 1.4 | Q43: =0.007*4 -> 0.028 | R43: =P43*$N$2 -> 249.2 | S43: =0.28491*4 -> 1.13964 | T43: =(N43+O43)*S43 -> 56.982 | U43: =+R43+T43 -> 306.182 | V43: NECA
...

Sheet BREAKDOWN (SITE)
C1: =+'BREAKDOWN (BUILDING)'!C1 -> Project Name: University Park Village (Starbucks 6212)
C2: =+'BREAKDOWN (BUILDING)'!C2 -> Address: 1620 S University Dr, Fort Worth, TX 76107 | M2: Labor Rate: | N2: 178 | O2: Per Hour | P2: Source: | Q2: NECA
C3: =+'BREAKDOWN (BUILDING)'!C3 -> Plan Date: 8/27/2025
B4: Electrical | C4: Electrical | I4: 1ST FLOOR | K4: 2ND FLOOR | N4: TOTAL | P4: Total Labor Hrs | Q4: Labor Hours | R4: Total Labor Cost | S4: Material Pricing | T4: Total Material Pricing | U4: Total | V4: REFERENCE
B5: Item No. | C5: Description | D5: Added Description | I5: Qty | J5: Lin. Ft. | K5: Qty | L5: Lin. Ft. | N5: Qty | O5: Lin. Ft. | V5: LABOR HOURS
C6: EXTERIOR ELECTRICAL WORKS | E6: CONTRACTOR | G6: CLIENT / VENDOR
E7: PROVIDE | F7: INSTALL | G7: PROVIDE | H7: INSTALL
B8: A.1 | C8: EXTERIOR ELECTRICAL WORKS (NOT IN SCOPE)
C9: Exterior Electrical Works
B12: A.1 | C12: EXTERIOR ELECTRICAL WORKS TOTAL | P12: =+P11 -> 0 | R12: =+R11 -> 0 | T12: =+T11 -> 0 | U12: =+U11 -> 0
O29: `

Sheet TAKEOFF DETAIL
B2: =+'BREAKDOWN (BUILDING)'!C1 -> Project Name: University Park Village (Starbucks 6212)
B3: =+'BREAKDOWN (BUILDING)'!C2 -> Address: 1620 S University Dr, Fort Worth, TX 76107
B4: =+'BREAKDOWN (BUILDING)'!C3 -> Plan Date: 8/27/2025
B6: DESCRIPTION OF WORK | C6: UNIT | D6: FIRST FLOOR | BH6: TOTAL (Power) | BI6: ROOF | BR6: TOTAL (Power) | BS6: FEEDER | BU6: TOTAL (Feeder) | BW6: DEVICE DROP | BX6: TERMINATION | BY6: PANELBOARD DROP | BZ6: SERVICE WIRE LOOP
D7: Panel: "A" | W7: Panel: "B" | AM7: Panel: "C" | AW7: Panel: "B" | BA7: Panel: "C" | BI7: Panel Name: PANEL " A " (EXISTING) - SHEET#: 003 | BM7: Panel Name: PANEL " A " (EXISTING) - SHEET#: 003 | BS7: Panel " C " (NEW) to Panel " A " (EXISTING) | BT7: --------
D8: Ckt #: 1 | E8: Ckt #: 3 | F8: Ckt #: 7,9 | G8: Ckt #: 11,13 | H8: Ckt #: 15 | I8: Ckt #: 19 | J8: Ckt #: 20 | K8: Ckt #: 21 | L8: Ckt #: 22 | M8: Ckt #: 23 | N8: Ckt #: 24,26 | O8: Ckt #: 25 | P8: Ckt #: 28,30 | Q8: Ckt #: 32 | R8: Ckt #: 34 | S8: Ckt #: 36 | T8: Ckt #: 38 | U8: Ckt #: 40 | V8: Ckt #: 42 | W8: Ckt #: 2 | X8: Ckt #: 4 | Y8: Ckt #: 5 | Z8: Ckt #: 7 | AA8: Ckt #: 8 | AB8: Ckt #: 9 | AC8: Ckt #: 10 | AD8: Ckt #: 11 | AE8: Ckt #: 12 | AF8: Ckt #: 14 | AG8: Ckt #: 16 | AH8: Ckt #: 18 | AI8: Ckt #: 20 | AJ8: Ckt #: 23,25 | AK8: Ckt #: 29,31 | AL8: Ckt #: 37,39 | AM8: Ckt #: 1 | AN8: Ckt #: 3 | AO8: Ckt #: 5 | AP8: Ckt #: 11 | AQ8: Ckt #: 13 | AR8: Ckt #: 14 | AS8: Ckt #: 15 | AT8: Ckt #: 16 | AU8: Ckt #: 18 | AV8: Ckt #: 25 | AW8: Ckt #: 27 | AX8: Ckt #: 34 | AY8: Ckt #: 36 | AZ8: Ckt #: 41 | BA8: Ckt #: 2 | BB8: Ckt #: 4 | BC8: Ckt #: 9 | BD8: Ckt #: 19 | BE8: Ckt #: 20 | BF8: Ckt #: 21 | BG8: Ckt #: 23 | BI8: Ckt #: 2,4,6 | BJ8: Ckt #: 8,10,12 | BK8: Ckt #: 14,16,18 | BL8: -------- | BM8: Ckt #: 6 | BN8: Ckt #: 8 | BO8: Ckt #: 10,12 | BP8: Ckt #: 17 | BQ8: --------
B9: POWER SYSTEM | D9: C.O. + Dis. Switch | E9: C.O. | F9: C.O. | G9: C.O. | H9: C.O. | I9: C.O. | J9: C.O. | K9: C.O. | L9: C.O. | M9: C.O. | N9: C.O. | O9: C.O. | P9: C.O. | Q9: C.O. | R9: C.O. | S9: C.O. | T9: C.O. | U9: C.O. | V9: C.O. | W9: C.O. | X9: C.O. | Y9: C.O. | Z9: C.O. | AA9: C.O. | AB9: C.O. | AC9: C.O. | AD9: C.O. | AE9: C.O. | AF9: C.O. | AG9: C.O. | AH9: C.O. | AI9: C.O. | AJ9: J-BOX | AK9: C.O. | AL9: C.O. | AM9: C.O. | AN9: C.O. | AO9: C.O. | AP9: C.O. | AQ9: C.O. | AR9: C.O. | AS9: C.O. | AT9: C.O. | AU9: C.O. | AV9: C.O. | AW9: C.O. | AX9: J-BOX | AY9: J-BOX | AZ9: C.O. | BA9: C.O. | BB9: J-BOX | BC9: C.O. | BD9: C.O. | BE9: J-BOX | BF9: C.O. | BG9: C.O. | BH9: FIRST FLOOR | BI9: Dis. Switch | BJ9: Dis. Switch | BK9: Dis. Switch | BM9: J-BOX | BN9: J-BOX | BO9: J-BOX | BP9: J-BOX | BR9: ROOF
B10: Conduit | BW10: 10 | BX10: 10 | BY10: 10 | BZ10: 0
B11: 1/2" EMT Conduit | C11: ft | E11: =20+SUM(E28:E48)*$BW$10+$BY$10 -> 40 | H11: =30+SUM(H28:H48)*$BW$10+$BY$10 -> 50 | I11: =30+SUM(I28:I48)*$BW$10+$BY$10 -> 50 | J11: =20+SUM(J28:J48)*$BW$10+$BY$10 -> 40 | K11: =20+SUM(K28:K48)*$BW$10+$BY$10 -> 40 | L11: =20+SUM(L28:L48)*$BW$10+$BY$10 -> 40 | M11: =20+SUM(M28:M48)*$BW$10+$BY$10 -> 40 | O11: =20+SUM(O28:O48)*$BW$10+$BY$10 -> 40 | Q11: =20+SUM(Q28:Q48)*$BW$10+$BY$10 -> 60 | R11: =30+SUM(R28:R48)*$BW$10+$BY$10 -> 50 | S11: =20+SUM(S28:S48)*$BW$10+$BY$10 -> 40 | T11: =20+SUM(T28:T48)*$BW$10+$BY$10 -> 50 | U11: =20+SUM(U28:U48)*$BW$10+$BY$10 -> 60 | V11: =10+40+SUM(V28:V48)*$BW$10+$BY$10 -> 70 | W11: =20+40+SUM(W28:W48)*$BW$10+$BY$10 -> 80 | X11: =20+40+SUM(X28:X48)*$BW$10+$BY$10 -> 80 | Y11: =10+40+SUM(Y28:Y48)*$BW$10+$BY$10 -> 70 | Z11: =10+40+SUM(Z28:Z48)*$BW$10+$BY$10 -> 70 | AA11: =20+40+SUM(AA28:AA48)*$BW$10+$BY$10 -> 80 | AB11: =10+40+SUM(AB28:AB48)*$BW$10+$BY$10 -> 70 | AC11: =20+40+SUM(AC28:AC48)*$BW$10+$BY$10 -> 80 | AD11: =30+40+SUM(AD28:AD48)*$BW$10+$BY$10 -> 90 | AE11: =10+40+SUM(AE28:AE48)*$BW$10+$BY$10 -> 70 | AF11: =10+40+SUM(AF28:AF48)*$BW$10+$BY$10 -> 70 | AG11: =40+SUM(AG28:AG48)*$BW$10+$BY$10 -> 60 | AH11: =40+SUM(AH28:AH48)*$BW$10+$BY$10 -> 60 | AI11: =50+SUM(AI28:AI48)*$BW$10+$BY$10 -> 70 | AJ11: =50+SUM(AJ28:AJ48)*$BW$10+$BY$10 -> 60 | AM11: =40+SUM(AM28:AM48)*$BW$10+$BY$10 -> 60 | AN11: =40+SUM(AN28:AN48)*$BW$10+$BY$10 -> 60 | AO11: =40+SUM(AO28:AO48)*$BW$10+$BY$10 -> 60 | AP11: =20+SUM(AP28:AP48)*$BW$10+$BY$10 -> 40 | AQ11: =40+SUM(AQ28:AQ48)*$BW$10+$BY$10 -> 70 | AR11: =20+40+SUM(AR28:AR48)*$BW$10+$BY$10 -> 80 | AS11: =40+SUM(AS28:AS48)*$BW$10+$BY$10 -> 60 | AT11: =20+40+SUM(AT28:AT48)*$BW$10+$BY$10 -> 80 | AU11: =20+40+SUM(AU28:AU48)*$BW$10+$BY$10 -> 80 | AV11: =20+SUM(AV28:AV48)*$BW$10+$BY$10 -> 40 | AW11: =80+SUM(AW28:AW48)*$BW$10+$BY$10 -> 110 | AX11: =60+SUM(AX28:AX48)*$BW$10+$BY$10 -> 70 | AY11: =70+SUM(AY28:AY48)*$BW$10+$BY$10 -> 80 | AZ11: =10+40+SUM(AZ28:AZ48)*$BW$10+$BY$10 -> 70 | BA11: =20+SUM(BA28:BA48)*$BW$10+$BY$10 -> 40 | BB11: =60+SUM(BB28:BB48)*$BW$10+$BY$10 -> 100 | BC11: =100+SUM(BC28:BC48)*$BW$10+$BY$10 -> 150 | BD11: =50+SUM(BD28:BD48)*$BW$10+$BY$10 -> 90 | BE11: =40+SUM(BE28:BE48)*$BW$10+$BY$10 -> 50 | BF11: =20+SUM(BF28:BF48)*$BW$10+$BY$10 -> 40 | BG11: =20+SUM(BG28:BG48)*$BW$10+$BY$10 -> 40 | BH11: =SUM(D11:BG11) -> 3150 | BM11: =70+10+SUM(BM28:BM48)*$BW$10+$BY$10 -> 90 | BN11: =50+10+SUM(BN28:BN48)*$BW$10+$BY$10 -> 70 | BO11: =40+10+SUM(BO28:BO48)*$BW$10+$BY$10 -> 60 | BP11: =50+10+SUM(BP28:BP48)*$BW$10+$BY$10 -> 70 | BR11: =SUM(BI11:BQ11) -> 290 | BU11: =SUM(BS11:BT11) -> 0
B12: 3/4" EMT Conduit | C12: ft | D12: =20+10+SUM(D28:D48)*$BW$10+$BY$10 -> 60 | F12: =40+SUM(F28:F48)*$BW$10+$BY$10 -> 60 | G12: =40+SUM(G28:G48)*$BW$10+$BY$10 -> 60 | N12: =30+SUM(N28:N48)*$BW$10+$BY$10 -> 50 | P12: =40+SUM(P28:P48)*$BW$10+$BY$10 -> 60 | AK12: =10+SUM(AK28:AK48)*$BW$10+$BY$10 -> 30 | AL12: =10+SUM(AL28:AL48)*$BW$10+$BY$10 -> 30 | BH12: =SUM(D12:BG12) -> 350 | BJ12: =40+10+SUM(BJ28:BJ48)*$BW$10+$BY$10 -> 70 | BK12: =10+10+SUM(BK28:BK48)*$BW$10+$BY$10 -> 40 | BR12: =SUM(BI12:BQ12) -> 110 | BU12: =SUM(BS12:BT12) -> 0
B13: 1" EMT Conduit | C13: ft | BH13: =SUM(D13:BG13) -> 0 | BI13: =30+10+SUM(BI28:BI48)*$BW$10+$BY$10 -> 60 | BR13: =SUM(BI13:BQ13) -> 60 | BU13: =SUM(BS13:BT13) -> 0
B14: 1-1/4" EMT Conduit | C14: ft | BH14: =SUM(D14:BG14) -> 0 | BR14: =SUM(BI14:BQ14) -> 0 | BS14: =10+$BY$10+$BY$10 -> 30 | BU14: =SUM(BS14:BT14) -> 30
B15: Wires
B16: Copper Wire, 2#12 AWG + 1#12G AWG | C16: ft | E16: =+(SUM(E28:E48)*$BX$10+$BZ$10*2+E11) -> 50 | H16: =+(SUM(H28:H48)*$BX$10+$BZ$10*2+H11) -> 60 | I16: =+(SUM(I28:I48)*$BX$10+$BZ$10*2+I11) -> 60 | J16: =+(SUM(J28:J48)*$BX$10+$BZ$10*2+J11) -> 50 | K16: =+(SUM(K28:K48)*$BX$10+$BZ$10*2+K11) -> 50 | L16: =+(SUM(L28:L48)*$BX$10+$BZ$10*2+L11) -> 50 | M16: =+(SUM(M28:M48)*$BX$10+$BZ$10*2+M11) -> 50 | O16: =+(SUM(O28:O48)*$BX$10+$BZ$10*2+O11) -> 50 | Q16: =+(SUM(Q28:Q48)*$BX$10+$BZ$10*2+Q11) -> 90 | R16: =+(SUM(R28:R48)*$BX$10+$BZ$10*2+R11) -> 60 | S16: =+(SUM(S28:S48)*$BX$10+$BZ$10*2+S11) -> 50 | T16: =+(SUM(T28:T48)*$BX$10+$BZ$10*2+T11) -> 70 | U16: =+(SUM(U28:U48)*$BX$10+$BZ$10*2+U11) -> 90 | V16: =+(SUM(V28:V48)*$BX$10+$BZ$10*2+V11) -> 80 | W16: =+(SUM(W28:W48)*$BX$10+$BZ$10*2+W11) -> 90 | X16: =+(SUM(X28:X48)*$BX$10+$BZ$10*2+X11) -> 90 | ... AI16: =+(SUM(AI28:AI48)*$BX$10+$BZ$10*2+AI11) -> 80 | AM16: =+(SUM(AM28:AM48)*$BX$10+$BZ$10*2+AM11) -> 70 | AN16: =+(SUM(AN28:AN48)*$BX$10+$BZ$10*2+AN11) -> 70 | AO16: =+(SUM(AO28:AO48)*$BX$10+$BZ$10*2+AO11) -> 70 | AP16: =+(SUM(AP28:AP48)*$BX$10+$BZ$10*2+AP11) -> 50 | AQ16: =+(SUM(AQ28:AQ48)*$BX$10+$BZ$10*2+AQ11) -> 90 | AR16: =+(SUM(AR28:AR48)*$BX$10+$BZ$10*2+AR11) -> 90 | AS16: =+(SUM(AS28:AS48)*$BX$10+$BZ$10*2+AS11) -> 70 | AT16: =+(SUM(AT28:AT48)*$BX$10+$BZ$10*2+AT11) -> 90 | ... AW16: =+(SUM(AW28:AW48)*$BX$10+$BZ$10*2+AW11) -> 130 | AX16: =+(SUM(AX26)*$BX$10+$BZ$10*2+AX11) -> 80 | AY16: =+(SUM(AY26)*$BX$10+$BZ$10*2+AY11) -> 90 | AZ16: =+(SUM(AZ28:AZ48)*$BX$10+$BZ$10*2+AZ11) -> 80 | BA16: =+(SUM(BA28:BA48)*$BX$10+$BZ$10*2+BA11) -> 50 | BB16: =+(SUM(BB26)*$BX$10+$BZ$10*2+BB11) -> 110 | BC16: =+(SUM(BC28:BC48)*$BX$10+$BZ$10*2+BC11) -> 190 | BD16: =+(SUM(BD28:BD48)*$BX$10+$BZ$10*2+BD11) -> 120 | BE16: =+(SUM(BE26)*$BX$10+$BZ$10*2+BE11) -> 60 | BF16: =+(SUM(BF28:BF48)*$BX$10+$BZ$10*2+BF11) -> 50 | BG16: =+(SUM(BG28:BG48)*$BX$10+$BZ$10*2+BG11) -> 50 | BH16: =SUM(D16:BG16) -> 3690 | BM16: =+(SUM(BM27)*$BX$10+$BZ$10*2+BM11) -> 100 | BN16: =+(SUM(BN27)*$BX$10+$BZ$10*2+BN11) -> 80 | BP16: =+(SUM(BP27)*$BX$10+$BZ$10*2+BP11) -> 110 | BR16: =SUM(BI16:BQ16) -> 290 | BU16: =SUM(BS16:BT16) -> 0
B17: Copper Wire, 2#10 AWG + 1#10G AWG | C17: ft | D17: =+(SUM(D28:D48)*$BX$10+$BZ$10*2+D12) -> 80 | F17: =+(SUM(F28:F48)*$BX$10+$BZ$10*2+F12) -> 70 | G17: =+(SUM(G28:G48)*$BX$10+$BZ$10*2+G12) -> 70 | BH17: =SUM(D17:BG17) -> 220 | BR17: =SUM(BI17:BQ17) -> 0 | BU17: =SUM(BS17:BT17) -> 0
B18: Copper Wire, 2#8 AWG + 1#10G AWG | C18: ft | AK18: =+(SUM(AK28:AK48)*$BX$10+$BZ$10*2+AK11) -> 10 | AL18: =+(SUM(AL28:AL48)*$BX$10+$BZ$10*2+AL11) -> 10 | BH18: =SUM(D18:BG18) -> 20 | BR18: =SUM(BI18:BQ18) -> 0 | BU18: =SUM(BS18:BT18) -> 0
B19: Copper Wire, 3#12 AWG + 1#12G AWG | C19: ft | AJ19: =+(SUM(AJ26)*$BX$10+$BZ$10*2+AJ11) -> 70 | BH19: =SUM(D19:BG19) -> 70 | BO19: =+(SUM(BO27)*$BX$10+$BZ$10*2+BO11) -> 70 | BR19: =SUM(BI19:BQ19) -> 70 | BU19: =SUM(BS19:BT19) -> 0
B20: Copper Wire, 3#10 AWG + 1#10G AWG | C20: ft | BH20: =SUM(D20:BG20) -> 0 | BK20: =+(SUM(BK28:BK48)*$BX$10+$BZ$10*2+BK12) -> 50 | BR20: =SUM(BI20:BQ20) -> 50 | BU20: =SUM(BS20:BT20) -> 0
B21: Copper Wire, 3#8 AWG + 1#10G AWG | C21: ft | N21: =+(SUM(N28:N48)*$BX$10+$BZ$10*2+N12) -> 60 | P21: =+(SUM(P28:P48)*$BX$10+$BZ$10*2+P12) -> 70 | BH21: =SUM(D21:BG21) -> 130 | BJ21: =+(SUM(BJ28:BJ48)*$BX$10+$BZ$10*2+BJ12) -> 80 | BR21: =SUM(BI21:BQ21) -> 80 | BU21: =SUM(BS21:BT21) -> 0
B22: Copper Wire, 3#4 AWG + 1#10G AWG | C22: ft | BH22: =SUM(D22:BG22) -> 0 | BI22: =+(SUM(BI28:BI48)*$BX$10+$BZ$10*2+BI13) -> 70 | BR22: =SUM(BI22:BQ22) -> 70 | BU22: =SUM(BS22:BT22) -> 0
B23: Copper Wire, 1#3 AWG | C23: ft | BH23: =SUM(D23:BG23) -> 0 | BR23: =SUM(BI23:BQ23) -> 0 | BS23: =(BS14+$BX$10)*3 -> 120 | BU23: =SUM(BS23:BT23) -> 120
B24: Copper Wire, 1#8G AWG | C24: ft | BH24: =SUM(D24:BG24) -> 0 | BR24: =SUM(BI24:BQ24) -> 0 | BS24: =(BS14+$BX$10)*1 -> 40 | BU24: =SUM(BS24:BT24) -> 40
B25: Boxes and Wiring Devices
B26: Junction Box | C26: ea | D26: =SUM(D28:D47)*1+D32 -> 1 | E26: =SUM(E28:E47)*1+E32 -> 1 | F26: =SUM(F28:F47)*1+F32 -> 1 | G26: =SUM(G28:G47)*1+G32 -> 1 | H26: =SUM(H28:H47)*1+H32 -> 1 | I26: =SUM(I28:I47)*1+I32 -> 1 | J26: =SUM(J28:J47)*1+J32 -> 1 | K26: =SUM(K28:K47)*1+K32 -> 1 | ... T26: =SUM(T28:T47)*1+T32 -> 2 | U26: =SUM(U28:U47)*1+U32+1 -> 5 | V26: =SUM(V28:V47)*1+V32 -> 1 | W26: =SUM(W28:W47)*1+W32 -> 2 | X26: =SUM(X28:X47)*1+X32 -> 1 | Y26: =SUM(Y28:Y47)*1+Y32 -> 1 | Z26: =SUM(Z28:Z47)*1+Z32 -> 1 | AA26: =SUM(AA28:AA47)*1+AA32 -> 1 | AB26: =SUM(AB28:AB47)*1+AB32 -> 1 | AC26: =SUM(AC28:AC47)*1+AC32 -> 2 | ... AI26: =SUM(AI28:AI47)*1+AI32 -> 2 | AJ26: 1 | AK26: =SUM(AK28:AK47)*1+AK32 -> 1 | AL26: =SUM(AL28:AL47)*1+AL32 -> 1 | AM26: =SUM(AM28:AM47)*1+AM32 -> 2 | AN26: =SUM(AN28:AN47)*1+AN32 -> 1 | AO26: =SUM(AO28:AO47)*1+AO32 -> 1 | AP26: =SUM(AP28:AP47)*1+AP32 -> 1 | AQ26: =SUM(AQ28:AQ47)*1+AQ32 -> 3 | AR26: =SUM(AR28:AR47)*1+AR32 -> 1 | ... AW26: =SUM(AW28:AW47)*1+AW32 -> 2 | AX26: 1 | AY26: 1 | AZ26: =SUM(AZ28:AZ47)*1+AZ32 -> 1 | BA26: =SUM(BA28:BA47)*1+BA32 -> 1 | BB26: 1 | BC26: =SUM(BC28:BC47)*1+BC32 -> 4 | BD26: =SUM(BD28:BD47)*1+BD32 -> 3 | BE26: 1 | BF26: =SUM(BF28:BF47)*1+BF32 -> 1 | BG26: =SUM(BG28:BG47)*1+BG32 -> 1 | BH26: =SUM(D26:BG26) -> 79 | BR26: =SUM(BI26:BQ26) -> 0 | BU26: =SUM(BS26:BT26) -> 0
B27: Junction Box, Weatherproof | C27: ea | BH27: =SUM(D27:BG27) -> 0 | BI27: =SUM(BI28:BI47)*1+BI32 -> 1 | BJ27: =SUM(BJ28:BJ47)*1+BJ32 -> 1 | BK27: =SUM(BK28:BK47)*1+BK32 -> 1 | BM27: 1 | BN27: 1 | BO27: 1 | BP27: 4 | BR27: =SUM(BI27:BQ27) -> 10 | BU27: =SUM(BS27:BT27) -> 0
B28: Duplex Receptacle | C28: ea | I28: 1 | J28: 1 | K28: 1 | L28: 1 | Q28: 2 | S28: 1 | T28: 2 | U28: 2 | X28: 1 | Y28: 1 | Z28: 1 | AA28: 1 | AB28: 1 | AD28: 1 | AO28: 1 | AP28: 1 | AQ28: 1 | AS28: 1 | AU28: 1 | AV28: 1 | AW28: 2 | BC28: 4 | BD28: 3 | BH28: =SUM(D28:BG28) -> 32 | BR28: =SUM(BI28:BQ28) -> 0 | BU28: =SUM(BS28:BT28) -> 0
B29: Duplex Dedicated Receptacle | C29: ea | E29: 1 | H29: 1 | M29: 1 | O29: 1 | Q29: 1 | AN29: 1 | AR29: 1 | BH29: =SUM(D29:BG29) -> 7 | BR29: =SUM(BI29:BQ29) -> 0 | BU29: =SUM(BS29:BT29) -> 0
B30: Duplex Receptacle, with Surge Protection Device | C30: ea | AG30: 1 | AH30: 1 | BH30: =SUM(D30:BG30) -> 2 | BR30: =SUM(BI30:BQ30) -> 0 | BU30: =SUM(BS30:BT30) -> 0
B31: Duplex Receptacle, Floor Mounted | C31: ea | AZ31: 1 | BA31: 1 | BF31: 1 | BG31: 1 | BH31: =SUM(D31:BG31) -> 4 | BR31: =SUM(BI31:BQ31) -> 0 | BU31: =SUM(BS31:BT31) -> 0
B32: Quadruplex Receptacle | C32: ea | R32: 1 | U32: 1 | W32: 1 | AC32: 1 | AE32: 1 | AF32: 1 | AI32: 1 | AM32: 1 | AQ32: 1 | AT32: 1 | BH32: =SUM(D32:BG32) -> 10 | BR32: =SUM(BI32:BQ32) -> 0 | BU32: =SUM(BS32:BT32) -> 0
B33: Special Purpose Receptacle, NEMA 6-50R | C33: ea | AK33: 1 | AL33: 1 | BH33: =SUM(D33:BG33) -> 2 | BR33: =SUM(BI33:BQ33) -> 0 | BU33: =SUM(BS33:BT33) -> 0
B34: Special Purpose Receptacle, NEMA 5-15R | C34: ea | D34: 1 | V34: 1 | BH34: =SUM(D34:BG34) -> 2 | BR34: =SUM(BI34:BQ34) -> 0 | BU34: =SUM(BS34:BT34) -> 0
B35: Special Purpose Receptacle, NEMA 14-50R | C35: ea | N35: 1 | P35: 1 | BH35: =SUM(D35:BG35) -> 2 | BR35: =SUM(BI35:BQ35) -> 0 | BU35: =SUM(BS35:BT35) -> 0
B36: Special Purpose Receptacle, NEMA 6-30R | C36: ea | F36: 1 | G36: 1 | BH36: =SUM(D36:BG36) -> 2 | BR36: =SUM(BI36:BQ36) -> 0 | BU36: =SUM(BS36:BT36) -> 0
B37: LeGrand Plugmold (MODEL#: BK20GB509TRUAC) | C37: ea | BB37: 3 | BH37: =SUM(D37:BG37) -> 3 | BR37: =SUM(BI37:BQ37) -> 0 | BU37: =SUM(BS37:BT37) -> 0
B38: Boards and Equipments
B39: Panel " C ", 100A MLO, 120/208V, 3P, 4W, 10KAIC, Surface Mtd., in NEMA 1 Enclosure | C39: assy | BH39: =SUM(D39:BG39) -> 0 | BR39: =SUM(BI39:BQ39) -> 0 | BS39: 1 | BU39: =SUM(BS39:BT39) -> 1
B40: Branches:
B41: 1 - 15A, 2P, Circuit Breaker
B42: 18 - 20A, 1P, Circuit Breaker
...
