Workbook

Sheet Summary
B2: Project Name | C2: University Park Village Starbucks | G2: Total SQFT | H2: 2652
B3: Address | C3: 1620 S University DR, Fort Worth, TX 76107 | G3: Number of Units | H3: 1
B4: Plan Date | C4: June 17, 2025 | G4: Labor Rate: | H4: 172.5
G5: Quotation ref. no.
O6: PRICING PER SYSTEM
B7: Item No. | C7: Description | D7: Qty | E7: Lin. Ft. | F7: Total Labor Hrs | G7: Material Pricing | H7: Total | O7: Item No. | P7: Description | Q7: Qty | R7: Lin. Ft. | S7: Total Labor Hrs | T7: Material Pricing | U7: Total | V7: Total After Tax and Management | W7: Total after profit
B8: Demolition | C8: Saw cutting ,removal of exisiting fixtures and pipes | E8: =Demolition!E5 -> 159.5 | F8: =Demolition!G27 -> 15.319 | G8: =Demolition!K27 -> 0 | H8: =G8+(F8*$H$4) -> 2642.5275 | I8: =Demolition!M27 -> 2642.5275 | O8: Demolition | P8: Saw cutting ,removal of exisiting fixtures and pipes | Q8: =Demolition!D27 -> 8 | R8: =Demolition!E27 -> 396.3 | S8: =Demolition!G27 -> 15.319 | T8: =Demolition!K27 -> 0 | U8: =T8+S8*$H$4 -> 2642.5275 | V8: =U8+(U8/SUM($U$8:$U$40))*SUM($H$19:$H$21) -> 3715.4592 | W8: =V8+V8/SUM($V$8:$V$40)*$V$41 -> 5038.3797
B9: Exterior | C9: Trenching , installation and connection of pipes to Utilities | E9: ='Exterior and Interceptor'!H310 -> 0 | F9: ='Exterior and Interceptor'!J310 -> 0 | G9: ='Exterior and Interceptor'!N310 -> 0 | H9: =G9+(F9*$H$4) -> 0 | I9: ='Exterior and Interceptor'!P310 -> 0 | O9: Exterior
B10: First floor underslab roughing ins | C10: Trenching , installation of undergorund Main pipes | E10: ='First Floor Underslab'!H321 -> 216.9 | F10: ='First Floor Underslab'!J321 -> 0 | G10: ='First Floor Underslab'!N321 -> 0 | H10: =G10+(F10*$H$4) -> 0 | I10: ='First Floor Underslab'!P321 -> 0 | O10: Sanitary and Vent Piping | R10: ='Exterior and Interceptor'!H109 -> 0 | S10: ='Exterior and Interceptor'!J119 -> 0 | T10: ='Exterior and Interceptor'!N119 -> 0 | U10: =T10+S10*$H$4 -> 0 | V10: =U10+(U10/SUM($U$8:$U$40))*SUM($H$19:$H$21) -> 0 | W10: =V10+V10/SUM($V$8:$V$40)*$V$41 -> 0
B11: Equipment | C11: Water heater and recirculating pump | D11: ='Fixture+Pipe Qty'!F76 -> 21 | F11: ='Fixture+Pipe Qty'!I76 -> 42.81 | G11: ='Fixture+Pipe Qty'!M76 -> 0 | H11: =G11+(F11*$H$4) -> 7384.725 | I11: ='Fixture+Pipe Qty'!O76 -> 7384.725 | O11: Water Piping | R11: ='Exterior and Interceptor'!H179 -> 0 | S11: ='Exterior and Interceptor'!J188 -> 0 | T11: ='Exterior and Interceptor'!N188 -> 0 | U11: =T11+S11*$H$4 -> 0 | V11: =U11+(U11/SUM($U$8:$U$40))*SUM($H$19:$H$21) -> 0 | W11: =V11+V11/SUM($V$8:$V$40)*$V$41 -> 0
B12: Fixtures | C12: Plumbing Fixtures and fixture trimmings | D12: ='Fixture+Pipe Qty'!F141 -> 27 | F12: ='Fixture+Pipe Qty'!I141 -> 35.25 | G12: ='Fixture+Pipe Qty'!M141 -> 0 | H12: =G12+(F12*$H$4) -> 6080.625 | I12: ='Fixture+Pipe Qty'!O141 -> 6080.625 | O12: Gas Piping | R12: ='Exterior and Interceptor'!H239 -> 0 | S12: ='Exterior and Interceptor'!J248 -> 0 | T12: ='Exterior and Interceptor'!N248 -> 0 | U12: =T12+S12*$H$4 -> 0 | V12: =U12+(U12/SUM($U$8:$U$40))*SUM($H$19:$H$21) -> 0 | W12: =V12+V12/SUM($V$8:$V$40)*$V$41 -> 0
B13: Specialties, Valves | D13: ='Fixture+Pipe Qty'!F242 -> 38 | F13: ='Fixture+Pipe Qty'!I242 -> 28.122 | G13: ='Fixture+Pipe Qty'!M242 -> 0 | H13: =G13+(F13*$H$4) -> 4851.045 | I13: ='Fixture+Pipe Qty'!O242 -> 4851.045 | J13: =Demolition!M34+'Exterior and Interceptor'!P363+'First Floor Underslab'!P330+'Fixture+Pipe Qty'!O643 -> 60822.113 | O13: Storm Piping | R13: ='Exterior and Interceptor'!H297 -> 0 | S13: ='Exterior and Interceptor'!J307 -> 0 | T13: ='Exterior and Interceptor'!N307 -> 0 | U13: =T13+S13*$H$4 -> 0
B14: Piping, fittings and supports | E14: ='Fixture+Pipe Qty'!G558 -> 1421.86 | F14: ='Fixture+Pipe Qty'!I558+'Fixture+Pipe Qty'!I634 -> 235.96121 | G14: ='Fixture+Pipe Qty'!M558+'Fixture+Pipe Qty'!M634 -> 0 | H14: =G14+(F14*$H$4) -> 40703.309 | I14: ='Fixture+Pipe Qty'!O558+'Fixture+Pipe Qty'!O634 -> 39202.559 | J14: =SUM(H8:H16) -> 62322.863 | K14: =J14-J13 -> 1500.75 | O14: Equipment | P14: Water heater and recirculating pump | Q14: ='Fixtures + Piping computation'!E51 -> 21 | S14: ='Fixture+Pipe Qty'!I76 -> 42.81 | T14: ='Fixture+Pipe Qty'!M76 -> 0 | U14: =T14+S14*$H$4 -> 7384.725 | V14: =U14+(U14/SUM($U$8:$U$40))*SUM($H$19:$H$21) -> 10383.107 | W14: =V14+V14/SUM($V$8:$V$40)*$V$41 -> 14080.099
B15: Grease Interceptor | C15: ='Exterior and Interceptor'!D342 -> 0 | D15: 0 | F15: ='Exterior and Interceptor'!J353 -> 0 | G15: ='Exterior and Interceptor'!N353 -> 0 | H15: =G15+(F15*$H$4) -> 0 | I15: ='Exterior and Interceptor'!P353 -> 0 | O15: Fixtures | P15: Plumbing Fixtures and fixture trimmings | Q15: ='Fixtures + Piping computation'!E28 -> 27 | S15: ='Fixture+Pipe Qty'!I141 -> 35.25 | T15: ='Fixture+Pipe Qty'!M141 -> 0 | U15: =T15+S15*$H$4 -> 6080.625 | V15: =U15+(U15/SUM($U$8:$U$40))*SUM($H$19:$H$21) -> 8549.5096 | W15: =V15+V15/SUM($V$8:$V$40)*$V$41 -> 11593.634
B16: Misc | C16: Hauling of materials | F16: =Demolition!G32+'Exterior and Interceptor'!J361+'First Floor Underslab'!J328+'Fixture+Pipe Qty'!I642 -> 3.82975 | G16: =Demolition!K32+'Exterior and Interceptor'!N361+'First Floor Underslab'!N328+'Fixture+Pipe Qty'!M642 -> 0 | H16: =G16+(F16*$H$4) -> 660.63187 | I16: =Demolition!M32+'Exterior and Interceptor'!P361+'First Floor Underslab'!P328+'Fixture+Pipe Qty'!O642 -> 660.63187 | O16: Specialties, Valves
I17: =SUM(I8:I16) -> 60822.113 | O17: Sanitary Specialties | Q17: ='Fixture+Pipe Qty'!F159 -> 26 | S17: ='Fixture+Pipe Qty'!I159 -> 15.75 | T17: ='Fixture+Pipe Qty'!M159 -> 0 | U17: =T17+S17*$H$4 -> 2716.875 | V17: =U17+(U17/SUM($U$8:$U$40))*SUM($H$19:$H$21) -> 3819.9937 | W17: =V17+V17/SUM($V$8:$V$40)*$V$41 -> 5180.1345
B18: Overhead and Profit | O18: Water Specialties | Q18: ='Fixture+Pipe Qty'!F172 -> 8 | S18: ='Fixture+Pipe Qty'!I172 -> 4 | T18: ='Fixture+Pipe Qty'!M172 -> 0 | U18: =T18+S18*$H$4 -> 690 | V18: =U18+(U18/SUM($U$8:$U$40))*SUM($H$19:$H$21) -> 970.15712 | W18: =V18+V18/SUM($V$8:$V$40)*$V$41 -> 1315.5897
C19: Sales Tax | H19: =G19*F19 -> 0 | O19: Gas Specialties | Q19: ='Fixture+Pipe Qty'!F199 -> 18 | S19: ='Fixture+Pipe Qty'!I199 -> 8.372 | T19: ='Fixture+Pipe Qty'!M199 -> 0 | U19: =T19+S19*$H$4 -> 1444.17 | V19: =U19+(U19/SUM($U$8:$U$40))*SUM($H$19:$H$21) -> 2030.5389 | W19: =V19+V19/SUM($V$8:$V$40)*$V$41 -> 2753.5293
C20: Permits | H20: =SUM(H8:H16)*0.005 -> 311.61432 | O20: Storm Specialties | Q20: ='Fixture+Pipe Qty'!F209 -> 0 | S20: ='Fixture+Pipe Qty'!I209 -> 0 | T20: ='Fixture+Pipe Qty'!M209 -> 0 | U20: =T20+S20*$H$4 -> 0 | V20: =U20+(U20/SUM($U$8:$U$40))*SUM($H$19:$H$21) -> 0 | W20: =V20+V20/SUM($V$8:$V$39)*$V$41 -> 0
C21: Project Management-Mobilization , demobilization, testing and start up ,1 yr warranty costs, tools and utilities | F21: =(SUM(F8:F16)/4) -> 90.32299 | H21: =F21*H4 -> 15580.716 | O21: Condensate Specialties | Q21: ='Fixture+Pipe Qty'!F219 -> 0 | S21: ='Fixture+Pipe Qty'!I219 -> 0 | T21: ='Fixture+Pipe Qty'!M219 -> 0 | U21: =T21+S21*$H$4 -> 0 | V21: =U21+(U21/SUM($U$8:$U$40))*SUM($H$19:$H$21) -> 0 | W21: =V21+V21/SUM($V$8:$V$39)*$V$41 -> 0
C22: Contigency | F22: 0.02 | H22: =SUM(H8:H16)*F22 -> 1246.4573
C23: Profit | G23: 0.3 | H23: =SUM(H8:H16)*G23 -> 18696.859 | O23: Compressed Air Specialties | Q23: ='Fixture+Pipe Qty'!F229 -> 0 | S23: ='Fixture+Pipe Qty'!I229 -> 0 | T23: ='Fixture+Pipe Qty'!M229 -> 0 | U23: =T23+S23*$H$4 -> 0 | V23: =U23+(U23/SUM($U$8:$U$40))*SUM($H$19:$H$21) -> 0 | W23: =V23+V23/SUM($V$8:$V$39)*$V$41 -> 0
O24: Other Specialties | Q24: ='Fixture+Pipe Qty'!F239 -> 0 | S24: ='Fixture+Pipe Qty'!I239 -> 0 | T24: ='Fixture+Pipe Qty'!M239 -> 0 | U24: =T24+S24*$H$4 -> 0 | V24: =U24+(U24/SUM($U$8:$U$40))*SUM($H$19:$H$21) -> 0 | W24: =V24+V24/SUM($V$8:$V$39)*$V$41 -> 0
B25: TOTAL | H25: =SUM(H8:H24) -> 98158.509 | J25: Price per sqft | K25: =H25/H2 -> 37.013013 | O25: Piping
J26: Price per Unit | K26: =H25/H3 -> 98158.509 | O26: Sanitary and Vent Piping | R26: ='First Floor Underslab'!H48+'Fixture+Pipe Qty'!G387 -> 358.73 | S26: ='First Floor Underslab'!J59+'Fixture+Pipe Qty'!I387 -> 8.78735 | T26: ='First Floor Underslab'!N59+'Fixture+Pipe Qty'!M387 -> 0 | U26: =T26+S26*$H$4 -> 1515.8179 | V26: =U26+(U26/SUM($U$8:$U$40))*SUM($H$19:$H$21) -> 2131.2775 | W26: =V26+V26/SUM($V$8:$V$40)*$V$41 -> 2890.1368
B27: Project Information | C27: Renovation of a single story coffee shop building in Fort Worth, TX. | O27: Water and Insulation Piping | R27: ='First Floor Underslab'!H102+'Fixture+Pipe Qty'!G288 -> 974.12 | S27: ='First Floor Underslab'!J111+'Fixture+Pipe Qty'!I288+'Fixture+Pipe Qty'!I606 -> 70.7795 | T27: ='First Floor Underslab'!N111+'Fixture+Pipe Qty'!M606+'Fixture+Pipe Qty'!M288 -> 0 | U27: =T27+S27*$H$4 -> 12209.464 | V27: =U27+(U27/SUM($U$8:$U$40))*SUM($H$19:$H$21) -> 17166.809 | W27: =V27+V27/SUM($V$8:$V$40)*$V$41 -> 23279.196
J28: =(H23+H21)/I17 -> 0.56357093 | O28: Gas Piping | R28: ='First Floor Underslab'!H206+'Fixture+Pipe Qty'!G443 -> 96.8 | S28: ='First Floor Underslab'!J215+'Fixture+Pipe Qty'!I443 -> 11.6061 | T28: ='First Floor Underslab'!N215+'Fixture+Pipe Qty'!M443 -> 0 | U28: =T28+S28*$H$4 -> 2002.0523 | V28: =U28+(U28/SUM($U$8:$U$40))*SUM($H$19:$H$21) -> 2814.9351 | W28: =V28+V28/SUM($V$8:$V$40)*$V$41 -> 3817.2165
B29: Scope of Work | O29: Storm Piping | R29: ='First Floor Underslab'!H153+'Fixture+Pipe Qty'!G488 -> 0 | S29: ='First Floor Underslab'!J162+'Fixture+Pipe Qty'!I618+'Fixture+Pipe Qty'!I488 -> 0 | T29: ='First Floor Underslab'!N162+'Fixture+Pipe Qty'!M488+'Fixture+Pipe Qty'!M618 -> 0 | U29: =T29+S29*$H$4 -> 0
O30: Condensate Piping | R30: ='First Floor Underslab'!H257+'Fixture+Pipe Qty'!G501 -> 88 | S30: ='First Floor Underslab'!J266+'Fixture+Pipe Qty'!I501+'Fixture+Pipe Qty'!I630 -> 3.124 | T30: ='First Floor Underslab'!N266+'Fixture+Pipe Qty'!M630+'Fixture+Pipe Qty'!M501 -> 0 | U30: =T30+S30*$H$4 -> 538.89
C31: DEMOLITION
B32: Removal | C32: Plumbing fixtures such as water closet, lavatory, hand sink, mop sinks and 3-comp sinks including its associated pipe.
C33: Gas piping up to gas meter
C35: WATER PIPE SYSTEM | O35: Compressed Air Piping | R35: ='Fixture+Pipe Qty'!G530 -> 0 | S35: ='Fixture+Pipe Qty'!I530 -> 0 | T35: ='Fixture+Pipe Qty'!M530 -> 0 | U35: =T35+S35*$H$4 -> 0
B36: Supply and installation | C36: =IF('Fixture+Pipe Qty'!C249='Fixture+Pipe Qty'!C260,'Fixture+Pipe Qty'!C249,'Fixture+Pipe Qty'!C249 & 'Fixture+Pipe Qty'!C260) & " cold and hot water pipe from existing point of connection to plumbing fixtures." -> Copper Type L Hard cold and hot water pipe from existing point of connection to plumbing fixtures. | O36: Other Pipes | R36: ='First Floor Underslab'!H309+'Fixture+Pipe Qty'!G545 -> 121.11 | S36: ='First Floor Underslab'!J318+'Fixture+Pipe Qty'!I545 -> 7.27826 | T36: ='First Floor Underslab'!N318+'Fixture+Pipe Qty'!M545 -> 0 | U36: =T36+S36*$H$4 -> 1255.4999
C37: Copper Type L hard cold water-softened pipe from brine tank to water heater and dishwasher
C38: Copper Type L hard filtered water to starbucks equipment
C39: =IF('Fixture+Pipe Qty'!C566='Fixture+Pipe Qty'!C577,'Fixture+Pipe Qty'!C566,'Fixture+Pipe Qty'!C566 & " & " & 'Fixture+Pipe Qty'!C577) & " for domestic cold and hot water, soft water and filtered water" -> 1/2" thick Fiberglass Insulation & 1" thick Fiberglass Insulation for domestic cold and hot water, soft water and filtered water | O39: Grease Interceptor | Q39: ='Exterior and Interceptor'!G342 -> 0 | S39: ='Exterior and Interceptor'!J353 -> 0 | T39: ='Exterior and Interceptor'!N353 -> 0 | U39: =T39+S39*$H$4 -> 0 | V39: =U39+(U39/SUM($U$8:$U$40))*SUM($H$19:$H$21) -> 0 | W39: =V39+V39/SUM($V$8:$V$40)*$V$41 -> 0
C40: Plumbing equipment and fixtures trimmings. | O40: Misc. | S40: =F16 -> 3.82975 | T40: =G16 -> 0 | U40: =H16 -> 660.63187 | V40: =U40+(U40/SUM($U$8:$U$40))*SUM($H$19:$H$21) -> 928.86481 | W40: =V40+V40/SUM($V$8:$V$40)*$V$41 -> 1259.5949
C41: Water pipe valves and specialties as indicated in the plan | O41: Profit | V41: =H23 -> 18696.859
P42: TOTAL | V42: =SUM(V12:V41) -> 67492.051 | W42: =SUM(W12:W41) -> 66169.131
...

Sheet Notes, Assumptions
B2: Project Name | C2: =Summary!C2 -> University Park Village Starbucks
B3: Address | C3: =Summary!C3 -> 1620 S University DR, Fort Worth, TX 76107
B4: Plan Date | C4: =Summary!C4 -> June 17, 2025
B6: General Assumptions
B7: Assumed 1' pipe allowance per fixture
B8: Pipe wastage at 15%
B9: Consider lead-free bronze type ball valves
B10: Consider 1/2" thick fiberglass insulation for domestic water and 1" thick for hot water
B11: Consider copper pipe type L hard pipe for domestic water
B12: Consider PVC sch.40 for sanitary and vent pipes
B13: Consider copper type M condensate drain of starbucks equipment insulated with 1/2" thick closed-cell insulation
B14: Consider copper type DWV for indirect waste of plumbing fixtures
B15: Consider PVC sch.40, 3" gas water heater vent flue
B16: Assumed that the gas line to be demolished is the same quantity as for the new installation
B19: Assumptions / Take-off considerations | C19: Illustration | D19: SHEET NO.
B21: Type of Pipe Material
B22: =Summary!C35 -> WATER PIPE SYSTEM
B23: =IF('Fixture+Pipe Qty'!C249='Fixture+Pipe Qty'!C260,'Fixture+Pipe Qty'!C249,'Fixture+Pipe Qty'!C249 & 'Fixture+Pipe Qty'!C260) & " Cold and hot water pipe" -> Copper Type L Hard Cold and hot water pipe | D23: P501 PLUMBING DETAILS P001 PLUMBING NOTES
B24: =IF('Fixture+Pipe Qty'!C566='Fixture+Pipe Qty'!C577,'Fixture+Pipe Qty'!C566,'Fixture+Pipe Qty'!C566 & " & " & 'Fixture+Pipe Qty'!C577) & " for domestic cold and hot water." -> 1/2" thick Fiberglass Insulation & 1" thick Fiberglass Insulation for domestic cold and hot water. | C24: Assumed only | D24: P101 PLUMBING SUPPLY PLAN
B25: Backflow preventer shall be by Landlord | D25: P101 PLUMBING SUPPLY PLAN
D26: P101 PLUMBING SUPPLY PLAN
B27: Provide shut-off valve each equipment and fixture | D27: P001 PLUMBING NOTES
B29: =Summary!#REF! -> #REF!
B30: =IF('Fixture+Pipe Qty'!C362='Fixture+Pipe Qty'!C370,'Fixture+Pipe Qty'!C362,'Fixture+Pipe Qty'!C362 & 'Fixture+Pipe Qty'!C370) &" sewer and vent pipes " -> PVC Sch. 40 sewer and vent pipes | C30: Assumed only
B31: Consider Copper DWV for the indirect waste line | D31: P502 PLUMBING DETAILS
B33: Consider Copper type M for the condensate drains of starbucks equipment | D33: P001 PLUMBING NOTES
B34: =Summary!C48 -> GAS SYSTEM
B35: Black steel sch.40 for gas line | C35: Assumed only
B38: Others

Sheet Demolition
C2: Description | D2: Qty | E2: Lin. Ft. | F2: Unit Labor | G2: Total Labor Hrs | H2: Total Labor | I2: Unit Materials | J2: Install Materials | K2: Total Materials | L2: Total
B4: Demolition
C5: SAW CUT | E5: =23.8+57.5+78.2 -> 159.5 | G5: =F5*E5 -> 0 | H5: =G5*Summary!$H$4 -> 0 | L5: =K5+H5 -> 0
B7: PIPES
C8: Gas pipe up to 1" | E8: ='Fixture+Pipe Qty'!G434+'Fixture+Pipe Qty'!G435 -> 54.78 | F8: 0.038 | G8: =(D8+E8)*F8 -> 2.08164 | H8: =G8*Summary!$H$4 -> 359.0829 | K8: =((D8+E8)*I8)+((D8+E8)*J8) -> 0 | L8: =K8+H8 -> 359.0829
C9: Gas pipe 1-1/2" to 2" | E9: ='Fixture+Pipe Qty'!G436+'Fixture+Pipe Qty'!G437 -> 42.02 | F9: 0.068 | G9: =(D9+E9)*F9 -> 2.85736 | H9: =G9*Summary!$H$4 -> 492.8946 | K9: =((D9+E9)*I9)+((D9+E9)*J9) -> 0 | L9: =K9+H9 -> 492.8946
C10: Domestic water | E10: =10+(10*2*4) -> 90 | F10: 0.022 | G10: =(D10+E10)*F10 -> 1.98 | H10: =G10*Summary!$H$4 -> 341.55 | K10: =((D10+E10)*I10)+((D10+E10)*J10) -> 0 | L10: =K10+H10 -> 341.55
C11: Sanitary and vent | E11: =10*5 -> 50 | F11: 0.038 | G11: =(D11+E11)*F11 -> 1.9 | H11: =G11*Summary!$H$4 -> 327.75 | K11: =((D11+E11)*I11)+((D11+E11)*J11) -> 0 | L11: =K11+H11 -> 327.75
B14: INSULATION
B17: FIXTURE
C18: Water closet | D18: 1 | F18: 0.95 | G18: =(D18+E18)*F18 -> 0.95 | H18: =G18*Summary!$H$4 -> 163.875 | K18: =((D18+E18)*I18)+((D18+E18)*J18) -> 0 | L18: =K18+H18 -> 163.875
C19: Lavatory | D19: 1 | F19: 0.85 | G19: =(D19+E19)*F19 -> 0.85 | H19: =G19*Summary!$H$4 -> 146.625 | K19: =((D19+E19)*I19)+((D19+E19)*J19) -> 0 | L19: =K19+H19 -> 146.625
C20: Hand sink | D20: 1 | F20: 0.85 | G20: =(D20+E20)*F20 -> 0.85 | H20: =G20*Summary!$H$4 -> 146.625 | K20: =((D20+E20)*I20)+((D20+E20)*J20) -> 0 | L20: =K20+H20 -> 146.625
C21: 3-comp sink | D21: 1 | F21: 0.85 | G21: =(D21+E21)*F21 -> 0.85 | H21: =G21*Summary!$H$4 -> 146.625 | K21: =((D21+E21)*I21)+((D21+E21)*J21) -> 0 | L21: =K21+H21 -> 146.625
C22: floor sink | D22: 3 | F22: 0.5 | G22: =(D22+E22)*F22 -> 1.5 | H22: =G22*Summary!$H$4 -> 258.75 | K22: =((D22+E22)*I22)+((D22+E22)*J22) -> 0 | L22: =K22+H22 -> 258.75
C23: Mop sink | D23: 1 | F23: 1.5 | G23: =(D23+E23)*F23 -> 1.5 | H23: =G23*Summary!$H$4 -> 258.75 | K23: =((D23+E23)*I23)+((D23+E23)*J23) -> 0 | L23: =K23+H23 -> 258.75
B24: EQUIPMENT
C27: SUMTOTAL | D27: =SUM(D4:D26) -> 8 | E27: =SUM(E4:E26) -> 396.3 | G27: =SUM(G5:G26) -> 15.319 | H27: =SUM(H3:H6) -> 0 | K27: =SUM(K3:K26) -> 0 | L27: =SUM(L3:L26) -> 2642.5275 | M27: =SUM(L4:L26) -> 2642.5275
B29: Miscellaneous
B30: Hauling of materials | C30: Assume 25% of total labor hrs of pipe installation | D30: 1 lot | G30: =G27*0.25 -> 3.82975 | H30: =G30*Summary!$H$4 -> 660.63187 | L30: =K30+H30 -> 660.63187
G32: =G30 -> 3.82975 | H32: =H30 -> 660.63187 | I32: =SUM(I30:I31) -> 0 | J32: =SUM(J30:J31) -> 0 | M32: =SUM(L29:L31) -> 660.63187
M34: =SUM(M4:M33) -> 3303.1594

Sheet Exterior and Interceptor
D2: Description | E2: Supply | F2: Install | G2: Qty | H2: LF | I2: Unit Labor | J2: Total Labor Hrs | K2: Total Labor Cost | L2: Unit Materials | M2: Install Materials | N2: Total Material Cost | O2: Total L&M
C5: EXTERIOR WORKS
U7: TRENCH DEPTH (FT)
T8: PIPE DIA (IN) | U8: 6 | V8: 8 | W8: 10 | X8: 12 | Y8: 14 | Z8: 16
C9: SANITARY EXTERIOR | R9: =IF(F9="X", IF(G9<>"", IF(OR(I9<>"",L9<>""), "✔", "ERROR"),"ERROR"),0) -> 0 | T9: 0"-8" | U9: 450 | V9: 383 | W9: 338 | X9: 270 | Y9: 225 | Z9: 180
C11: TRENCHING | D11: TRENCH DETAILS
D12: Depth of Trench (FT) | H12: 6 | I12: =IFERROR(INDEX($U$28:$AF$79,MATCH(D30,$T$28:$T$79,0),MATCH(E30,$U$24:$AF$24,0)),0) -> 0
D13: Linear FT of Top Soil Finish | H13: 0
D14: Linear FT of Top Pavement/Concrete Finish | G14: =I30 -> 0 | H14: 0
D15: TRENCHING WORK
D16: Staking (FT) | E16: X | F16: X | H16: =SUM(H13:H14) -> 0 | I16: =8/500*(120/65) -> 0.029538462 | J16: =(G16+H16)*I16 -> 0 | K16: =J16*Summary!$H$4 -> 0 | O16: =N16+K16 -> 0
D17: Excavation, Bedding, Pipe Laying, and Backfilling(FT) | E17: X | F17: X | H17: =SUM(H13:H14) -> 0 | I17: =IF(H12>0,8/IFERROR(INDEX($U$9:$Z$9,MATCH(H12,$U$8:$Z$8,0)),U9)*300/65*2,0) -> 0.16410256 | J17: =(G17+H17)*I17 -> 0 | K17: =J17*Summary!$H$4 -> 0 | O17: =N17+K17 -> 0
D18: Backfilling Materials (TONNAGE) +10% | E18: X | F18: X | H18: =G30*1.1 -> 0 | L18: 30 | N18: =L18*(H18+G18) -> 0 | O18: =N18+K18 -> 0
D19: Testing (FT) | E19: X | F19: X | H19: =SUM(H13:H14) -> 0 | I19: =8/500*(100/65) -> 0.024615385 | J19: =(G19+H19)*I19 -> 0 | K19: =J19*Summary!$H$4 -> 0 | O19: =N19+K19 -> 0
D20: SPOILS
D21: Bedding Spoils (TONNAGE) | E21: X | F21: X | H21: =(((H13+H14)*D30*E30))/27*1.4*1.4/25 -> 0 | I21: =8/50*(128/65) -> 0.31507692 | J21: =(G21+H21)*I21 -> 0 | K21: =J21*Summary!$H$4 -> 0 | O21: =N21+K21 -> 0
D22: Backfill Spoils (TONNAGE) | E22: X | F22: X | H22: =(H14*E30*H12)/27*1.4*1.4 -> 0 | I22: =8/50*(128/65) -> 0.31507692 | J22: =(G22+H22)*I22 -> 0 | K22: =J22*Summary!$H$4 -> 0 | O22: =N22+K22 -> 0
D23: Dump Fees ($450 per 25 TON of excavation) | E23: X | F23: X | H23: =SUM(H21:H22) -> 0 | L23: 450 | N23: =L23*ROUNDUP((H23+G23)/25,0) -> 0 | O23: =N23+K23 -> 0
D24: OTHERS
C25: Yes | D25: Rock Excavation ($187.5/hr + $3000 for mobilization) | E25: X | F25: X | G25: =IF(C25="YES",ROUNDUP(J17,0),0) -> 0 | L25: =1500/8 -> 187.5 | N25: =IF(G25>0,L25*(H25+G25)+3000,0) -> 0 | O25: =N25+K25 -> 0
D26: Trench Safety Rental ($30/hr) | E26: X | F26: X | G26: =IF(H12>5,ROUNDUP(J17,0),0) -> 0 | L26: 30 | N26: =L26*(H26+G26) -> 0 | O26: =N26+K26 -> 0
C28: Calcs
C29: PIPE DIAMETER (Inches) | D29: DEPTH (FT) | E29: WIDTH (FT) | F29: VOLUME OF GRAVEL BEDDING (CU YD) | G29: TONNAGE
C30: 6 | D30: =1.5+C30/12 -> 2 | E30: =2+C30/12 -> 2.5 | F30: =(((H13+H14)*D30*E30)+(H14*E30*(H12-D30)))/27 -> 0 | G30: =ROUNDUP(F30*1.3,0) -> 0
D31: (If depth not given, assume 1.5ft plus Pipe diameter )
D32: (If width not given, assume 2ft plus Pipe diameter )
D34: TRENCH DETAILS
D35: Depth of Trench (FT) | H35: 0 | I35: =IFERROR(INDEX($U$28:$AF$79,MATCH(D53,$T$28:$T$79,0),MATCH(E53,$U$24:$AF$24,0)),0) -> 0
D36: Linear FT of Top Soil Finish | H36: 0
D37: Linear FT of Top Pavement/Concrete Finish | G37: =I53 -> 0 | H37: 0
D38: TRENCHING WORK
D39: Staking (FT) | E39: X | F39: X | H39: =SUM(H36:H37) -> 0 | I39: =8/500*(120/65) -> 0.029538462 | J39: =(G39+H39)*I39 -> 0 | K39: =J39*Summary!$H$4 -> 0 | O39: =N39+K39 -> 0
D40: Excavation, Bedding, Pipe Laying, and Backfilling(FT) | E40: X | F40: X | H40: =SUM(H36:H37) -> 0 | I40: =IF(H35>0,8/IFERROR(INDEX($U$9:$Z$9,MATCH(H35,$U$8:$Z$8,0)),U32)*300/65*2,0) -> 0 | J40: =(G40+H40)*I40 -> 0 | K40: =J40*Summary!$H$4 -> 0 | O40: =N40+K40 -> 0
D41: Backfilling Materials (TONNAGE) +10% | E41: X | F41: X | H41: =G53*1.1 -> 0 | L41: 30 | N41: =L41*(H41+G41) -> 0 | O41: =N41+K41 -> 0
D42: Testing (FT) | E42: X | F42: X | H42: =SUM(H36:H37) -> 0 | I42: =8/500*(100/65) -> 0.024615385 | J42: =(G42+H42)*I42 -> 0 | K42: =J42*Summary!$H$4 -> 0 | O42: =N42+K42 -> 0
D43: SPOILS
D44: Bedding Spoils (TONNAGE) | E44: X | F44: X | H44: =(((H36+H37)*D53*E53))/27*1.4*1.4/25 -> 0 | I44: =8/50*(128/65) -> 0.31507692 | J44: =(G44+H44)*I44 -> 0 | K44: =J44*Summary!$H$4 -> 0 | O44: =N44+K44 -> 0
D45: Backfill Spoils (TONNAGE) | E45: X | F45: X | H45: =(H37*E53*H35)/27*1.4*1.4 -> 0 | I45: =8/50*(128/65) -> 0.31507692 | J45: =(G45+H45)*I45 -> 0 | K45: =J45*Summary!$H$4 -> 0 | O45: =N45+K45 -> 0
D46: Dump Fees ($450 per 25 TON of excavation) | E46: X | F46: X | H46: =SUM(H44:H45) -> 0 | L46: 450 | N46: =L46*ROUNDUP((H46+G46)/25,0) -> 0 | O46: =N46+K46 -> 0
D47: OTHERS
...

Sheet First Floor Underslab
D2: Description | E2: Supply | F2: Install | G2: Qty | H2: LF | I2: Unit Labor | J2: Total Labor Hrs | K2: Total Labor Cost | L2: Unit Materials | M2: Install Materials | N2: Total Material Cost | O2: Total L&M
C5: INTERIOR UNDERSLAB WORKS
U7: TRENCH DEPTH (FT)
T8: PIPE DIA (IN) | U8: 6 | V8: 8 | W8: 10 | X8: 12 | Y8: 14 | Z8: 16
C9: SANITARY UNDERSLAB | R9: =IF(F9="X", IF(G9<>"", IF(OR(I9<>"",L9<>""), "✔", "ERROR"),"ERROR"),0) -> 0 | T9: 0"-8" | U9: 400 | V9: =383-57 -> 326 | W9: 288 | X9: 230 | Y9: 190 | Z9: 150
C11: TRENCHING | D11: TRENCH DETAILS
D12: Depth of Trench (FT) | I12: =IFERROR(INDEX($U$26:$AF$49,MATCH(D28,$T$26:$T$49,0),MATCH(E28,$U$22:$AF$22,0)),0) -> 0
D13: Linear FT of Top Pavement/Concrete Finish | G13: =I28 -> 0
D14: TRENCHING WORK
D15: Staking (FT) | E15: X | F15: X | H15: =SUM(H13:H13) -> 0 | I15: =8/500*(120/65) -> 0.029538462 | J15: =(G15+H15)*I15 -> 0 | K15: =J15*Summary!$H$4 -> 0 | O15: =N15+K15 -> 0
D16: Excavation, Bedding, Pipe Laying, and Backfilling(FT) | E16: X | F16: X | H16: =SUM(H13:H13) -> 0 | I16: =IF(H12>0,8/IFERROR(INDEX($U$9:$Z$9,MATCH(H12,$U$8:$Z$8,0)),$U$9)*300/65*2,0) -> 0 | J16: =(G16+H16)*I16 -> 0 | K16: =J16*Summary!$H$4 -> 0 | O16: =N16+K16 -> 0
D17: Backfilling Materials (TONNAGE) +10% | E17: X | F17: X | H17: =G28*1.1 -> 0 | L17: 30 | N17: =L17*(H17+G17) -> 0 | O17: =N17+K17 -> 0
D18: Testing (FT) | E18: X | F18: X | H18: =SUM(H13:H13) -> 0 | I18: =8/500*(100/65) -> 0.024615385 | J18: =(G18+H18)*I18 -> 0 | K18: =J18*Summary!$H$4 -> 0 | O18: =N18+K18 -> 0
D19: SPOILS
D20: Backfill Spoils (TONNAGE) | E20: X | F20: X | H20: =(H13*E28*D28)/27*1.4*1.1 -> 0 | I20: =8/50*(128/65) -> 0.31507692 | J20: =(G20+H20)*I20 -> 0 | K20: =J20*Summary!$H$4 -> 0 | O20: =N20+K20 -> 0
D21: Dump Fees ($450 per 25 TON of excavation) | E21: X | F21: X | H21: =SUM(H20:H20) -> 0 | L21: 450 | N21: =L21*ROUNDUP((H21+G21)/25,0) -> 0 | O21: =N21+K21 -> 0
D22: OTHERS
C23: 0 | D23: Rock Excavation ($187.5/hr + $3000 for mobilization) | E23: X | F23: X | G23: =IF(C23="YES",ROUNDUP(J16,0),0) -> 0 | L23: =1500/8 -> 187.5 | N23: =IF(G23>0,L23*(H23+G23)+3000,0) -> 0 | O23: =N23+K23 -> 0
D24: Trench Safety Rental ($30/hr) | E24: X | F24: X | G24: =IF(H12>5,ROUNDUP(J16,0),0) -> 0 | L24: 30 | N24: =L24*(H24+G24) -> 0 | O24: =N24+K24 -> 0
C26: Calcs
C27: PIPE DIAMETER (Inches) | D27: DEPTH (FT) | E27: WIDTH (FT) | F27: VOLUME OF GRAVEL BEDDING (CU YD) | G27: TONNAGE
C28: 4 | D28: =1.5+C28/12 -> 1.8333333 | E28: =2+C28/12 -> 2.3333333 | F28: =(H13*E28*D28)/27 -> 0 | G28: =ROUNDUP(F28*1.3,0) -> 0
D29: (If depth not given, assume 1.5ft plus Pipe diameter )
D30: (If width not given, assume 2ft plus Pipe diameter )
D33: SANITARY TRENCHING TOTAL | J33: =SUM(J10:J32) -> 0 | K33: =SUM(K10:K32) -> 0 | N33: =SUM(N10:N32) -> 0
C35: SANITARY AND VENT PIPING
C37: Sleeve underground | D37: PVC Sch. 40
D38: 1-1/2" | E38: X | F38: X | M38: 0 | N38: =((G38+H38)*L38)+((G38+H38)*M38) -> 0 | O38: =N38+K38 -> 0
C39: Sleeve for CW and CWF | D39: 3" | E39: X | F39: X | H39: =10.6+10.6 -> 21.2 | M39: 0 | N39: =((G39+H39)*L39)+((G39+H39)*M39) -> 0 | O39: =N39+K39 -> 0
D40: 4" | E40: X | F40: X | M40: 0 | N40: =((G40+H40)*L40)+((G40+H40)*M40) -> 0 | O40: =N40+K40 -> 0
C42: Grease Waste | D42: PVC Sch. 40
D43: 2" | E43: X | F43: X | H43: 23.8 | M43: 0 | N43: =((G43+H43)*L43)+((G43+H43)*M43) -> 0 | O43: =N43+K43 -> 0
D44: 3" | E44: X | F44: X | H44: 57.5 | M44: 0 | N44: =((G44+H44)*L44)+((G44+H44)*M44) -> 0 | O44: =N44+K44 -> 0
D45: 4" | E45: X | F45: X | H45: =78.2+5 -> 83.2 | M45: 0 | N45: =((G45+H45)*L45)+((G45+H45)*M45) -> 0 | O45: =N45+K45 -> 0
C46: Allownce 5% | E46: X | F46: X | G46: 1 | N46: =SUM(N38:N45)*0.05 -> 0 | O46: =N46+K46 -> 0
D48: SANITARY, VENT AND STORM PIPE TOTAL | H48: =SUM(H34:H46) -> 185.7 | J48: =SUM(J34:J47) -> 0 | K48: =SUM(K34:K47) -> 0 | N48: =SUM(N34:N47) -> 0
C50: INTERIOR UTILITY TAPPING CONNECTION
C52: Sanitary | E52: X | F52: X | J52: =(G52+H52)*I52 -> 0 | K52: =J52*Summary!$H$4 -> 0 | L52: 0 | M52: 0 | N52: =((G52+H52)*L52)+((G52+H52)*M52) -> 0 | O52: =N52+K52 -> 0
C53: Grease | E53: X | F53: X | G53: 1 | J53: =(G53+H53)*I53 -> 0 | K53: =J53*Summary!$H$4 -> 0 | L53: 0 | M53: 0 | N53: =((G53+H53)*L53)+((G53+H53)*M53) -> 0 | O53: =N53+K53 -> 0
C54: Vent | E54: X | F54: X | J54: =(G54+H54)*I54 -> 0 | K54: =J54*Summary!$H$4 -> 0 | L54: 0 | M54: 0 | N54: =((G54+H54)*L54)+((G54+H54)*M54) -> 0 | O54: =N54+K54 -> 0
...

Sheet Fixture+Pipe Qty
C2: Description | D2: Supply | E2: Install | F2: Qty | G2: Lin. Ft. | H2: Unit Labor | I2: Total Labor Hrs | J2: Total Labor | K2: Unit Materials | L2: Install Materials | M2: Total Materials | N2: Total
B3: Project Name | C3: =Summary!C2 -> University Park Village Starbucks
B4: Address | C4: =Summary!C3 -> 1620 S University DR, Fort Worth, TX 76107
B5: Plan Date | C5: =Summary!C4 -> June 17, 2025
B9: INTERIOR WORKS
B13: EQUIPMENT | C13: Brand and Model Name | Q13: =IF(E13="X", IF(F13<>"", IF(OR(H13<>"",K13<>""), "✔", "ERROR"),"ERROR"),0) -> 0
B15: =IF('Fixtures + Piping computation'!C31>0,'Fixtures + Piping computation'!B31 & " (" &'Fixtures + Piping computation'!C31 & ")",'Fixtures + Piping computation'!C31) -> Water heater (22232) | C15: Bradford White, EF-60-125E-3N(A) | D15: X | E15: X | F15: ='Fixtures + Piping computation'!D184 -> 1 | H15: 10 | I15: =(F15+G15)*H15 -> 10 | J15: =I15*Summary!$H$4 -> 1725 | M15: =((F15+G15)*K15)+((F15+G15)*L15) -> 0 | N15: =M15+J15 -> 1725
B16: Accessories
B17: ='Fixtures + Piping computation'!B72 -> Expansion tank | C17: ST-12 280FPH12 | D17: X | E17: X | F17: ='Fixtures + Piping computation'!E72 -> 1 | M17: =((F17+G17)*K17)+((F17+G17)*L17) -> 0 | N17: =M17+J17 -> 0
B18: ='Fixtures + Piping computation'!B73 -> Shut-off valve 1" | C18: Nibco, T-585-66-LF | D18: X | E18: X | F18: ='Fixtures + Piping computation'!E73 -> 3 | M18: =((F18+G18)*K18)+((F18+G18)*L18) -> 0 | N18: =M18+J18 -> 0
B19: ='Fixtures + Piping computation'!B74 -> Check valve 1" | C19: NIBCO T-413-Y-LF | D19: X | E19: X | F19: ='Fixtures + Piping computation'!E74 -> 1 | M19: =((F19+G19)*K19)+((F19+G19)*L19) -> 0 | N19: =M19+J19 -> 0
B20: ='Fixtures + Piping computation'!B75 -> Vacuum relief valve 3/4" | C20: LFN-36 | D20: X | E20: X | F20: ='Fixtures + Piping computation'!E75 -> 1 | M20: =((F20+G20)*K20)+((F20+G20)*L20) -> 0 | N20: =M20+J20 -> 0
B21: ='Fixtures + Piping computation'!B76 -> Straps | D21: X | E21: X | F21: ='Fixtures + Piping computation'!E76 -> 2 | M21: =((F21+G21)*K21)+((F21+G21)*L21) -> 0 | N21: =M21+J21 -> 0
B22: ='Fixtures + Piping computation'!B77 -> Drain pan | D22: X | E22: X | F22: ='Fixtures + Piping computation'!E77 -> 1 | M22: =((F22+G22)*K22)+((F22+G22)*L22) -> 0 | N22: =M22+J22 -> 0
B23: ='Fixtures + Piping computation'!B78 -> T&P relief valve | C23: Included in the water heater | D23: X | E23: X | F23: ='Fixtures + Piping computation'!E78 -> 1 | M23: =((F23+G23)*K23)+((F23+G23)*L23) -> 0 | N23: =M23+J23 -> 0
B24: ='Fixtures + Piping computation'!B79 -> Concentric valve | C24: AOS 100111100 | D24: X | E24: X | F24: ='Fixtures + Piping computation'!E79 -> 1 | M24: =((F24+G24)*K24)+((F24+G24)*L24) -> 0 | N24: =M24+J24 -> 0
B25: ='Fixtures + Piping computation'!B80 -> Condensate Neutralization | C25: 100289339 | D25: X | E25: X | F25: ='Fixtures + Piping computation'!E80 -> 1 | M25: =((F25+G25)*K25)+((F25+G25)*L25) -> 0 | N25: =M25+J25 -> 0
B27: ='Fixtures + Piping computation'!C185 -> Recirculating pump (X2500) | C27: BELL & GOSSETT, NBF-12U/LW 3/4" | D27: X | E27: X | F27: ='Fixtures + Piping computation'!D185 -> 1 | H27: 4 | I27: =(F27+G27)*H27 -> 4 | J27: =I27*Summary!$H$4 -> 690 | M27: =((F27+G27)*K27)+((F27+G27)*L27) -> 0 | N27: =M27+J27 -> 690
B28: Accessories
B29: Union | D29: X | E29: X | F29: 2 | M29: =((F29+G29)*K29)+((F29+G29)*L29) -> 0 | N29: =M29+J29 -> 0
B30: ='Fixtures + Piping computation'!B83 -> Shut-off valve 3/4" | C30: Nibco, T-585-66-LF | D30: X | E30: X | F30: ='Fixtures + Piping computation'!E83 -> 2 | M30: =((F30+G30)*K30)+((F30+G30)*L30) -> 0 | N30: =M30+J30 -> 0
B31: ='Fixtures + Piping computation'!B84 -> Check valve 3/4" | C31: NIBCO T-413-Y-LF | D31: X | E31: X | F31: ='Fixtures + Piping computation'!E84 -> 1 | M31: =((F31+G31)*K31)+((F31+G31)*L31) -> 0 | N31: =M31+J31 -> 0
B32: ='Fixtures + Piping computation'!B85 -> Aquastat | C32: 563-2 3/4 | D32: X | E32: X | F32: ='Fixtures + Piping computation'!E85 -> 1 | M32: =((F32+G32)*K32)+((F32+G32)*L32) -> 0 | N32: =M32+J32 -> 0
B33: ='Fixtures + Piping computation'!B86 -> Timer | C33: TACO 265-3 24HR | D33: X | E33: X | F33: ='Fixtures + Piping computation'!E86 -> 1 | M33: =((F33+G33)*K33)+((F33+G33)*L33) -> 0 | N33: =M33+J33 -> 0
B35: =IF('Fixtures + Piping computation'!C33>0,'Fixtures + Piping computation'!B33 & " (" &'Fixtures + Piping computation'!C33 & ")",'Fixtures + Piping computation'!C33) -> Filter - RO (12501 (SB-VD)) | C35: Connection only | D35: SB | E35: VD | F35: ='Fixtures + Piping computation'!D186 -> 1 | H35: 1 | I35: =(F35+G35)*H35 -> 1 | J35: =I35*Summary!$H$4 -> 172.5 | M35: =((F35+G35)*K35)+((F35+G35)*L35) -> 0 | N35: =M35+J35 -> 172.5
B36: =IF('Fixtures + Piping computation'!C34>0,'Fixtures + Piping computation'!B34 & " (" &'Fixtures + Piping computation'!C34 & ")",'Fixtures + Piping computation'!C34) -> Filter - Booster Pump (23355 (SB-VD)) | C36: Connection only | D36: SB | E36: VD | F36: ='Fixtures + Piping computation'!D187 -> 1 | H36: 1 | I36: =(F36+G36)*H36 -> 1 | J36: =I36*Summary!$H$4 -> 172.5 | M36: =((F36+G36)*K36)+((F36+G36)*L36) -> 0 | N36: =M36+J36 -> 172.5
B37: =IF('Fixtures + Piping computation'!C35>0,'Fixtures + Piping computation'!B35 & " (" &'Fixtures + Piping computation'!C35 & ")",'Fixtures + Piping computation'!C35) -> Filter-Water softener (13082 (SB-VD)) | C37: Connection only | D37: SB | E37: VD | F37: ='Fixtures + Piping computation'!D188 -> 1 | H37: 1 | I37: =(F37+G37)*H37 -> 1 | J37: =I37*Summary!$H$4 -> 172.5 | M37: =((F37+G37)*K37)+((F37+G37)*L37) -> 0 | N37: =M37+J37 -> 172.5
B38: =IF('Fixtures + Piping computation'!C36>0,'Fixtures + Piping computation'!B36 & " (" &'Fixtures + Piping computation'!C36 & ")",'Fixtures + Piping computation'!C36) -> Filter-Pre-filtration (13076 (SB-VD)) | C38: Connection only | D38: SB | E38: VD | F38: ='Fixtures + Piping computation'!D189 -> 1 | H38: 1 | I38: =(F38+G38)*H38 -> 1 | J38: =I38*Summary!$H$4 -> 172.5 | M38: =((F38+G38)*K38)+((F38+G38)*L38) -> 0 | N38: =M38+J38 -> 172.5
B39: =IF('Fixtures + Piping computation'!C37>0,'Fixtures + Piping computation'!B37 & " (" &'Fixtures + Piping computation'!C37 & ")",'Fixtures + Piping computation'!C37) -> Filter-Polyglass vessel (12899 (SB-VD)) | C39: Connection only | D39: SB | E39: VD | F39: ='Fixtures + Piping computation'!D190 -> 2 | H39: 1 | I39: =(F39+G39)*H39 -> 2 | J39: =I39*Summary!$H$4 -> 345 | M39: =((F39+G39)*K39)+((F39+G39)*L39) -> 0 | N39: =M39+J39 -> 345
B40: =IF('Fixtures + Piping computation'!C38>0,'Fixtures + Piping computation'!B38 & " (" &'Fixtures + Piping computation'!C38 & ")",'Fixtures + Piping computation'!C38) -> Filter-Brine Tank (12896 (SB-VD)) | C40: Connection only | D40: SB | E40: VD | F40: ='Fixtures + Piping computation'!D191 -> 1 | H40: 1 | I40: =(F40+G40)*H40 -> 1 | J40: =I40*Summary!$H$4 -> 172.5 | M40: =((F40+G40)*K40)+((F40+G40)*L40) -> 0 | N40: =M40+J40 -> 172.5
B41: =IF('Fixtures + Piping computation'!C39>0,'Fixtures + Piping computation'!B39 & " (" &'Fixtures + Piping computation'!C39 & ")",'Fixtures + Piping computation'!C39) -> Filter - RO storage tank (12507 (SB-VD)) | C41: Connection only | D41: SB | E41: VD | F41: ='Fixtures + Piping computation'!D192 -> 1 | H41: 1 | I41: =(F41+G41)*H41 -> 1 | J41: =I41*Summary!$H$4 -> 172.5 | M41: =((F41+G41)*K41)+((F41+G41)*L41) -> 0 | N41: =M41+J41 -> 172.5
B42: =IF('Fixtures + Piping computation'!C40>0,'Fixtures + Piping computation'!B40 & " (" &'Fixtures + Piping computation'!C40 & ")",'Fixtures + Piping computation'!C40) -> Booster pump (BP) | C42: Connection only | D42: SB | E42: VD | F42: ='Fixtures + Piping computation'!D193 -> 1 | H42: 1 | I42: =(F42+G42)*H42 -> 1 | J42: =I42*Summary!$H$4 -> 172.5 | M42: =((F42+G42)*K42)+((F42+G42)*L42) -> 0 | N42: =M42+J42 -> 172.5
B43: Accessories
B44: Shut-off valve 3/4" | C44: Nibco, T-585-66-LF | D44: X | E44: X | F44: 11 | H44: 0.25 | I44: =(F44+G44)*H44 -> 2.75 | J44: =I44*Summary!$H$4 -> 474.375 | M44: =((F44+G44)*K44)+((F44+G44)*L44) -> 0 | N44: =M44+J44 -> 474.375
B45: Water hammer arrester 3/4" | D45: X | E45: X | F45: 1 | H45: 0.19 | I45: =(F45+G45)*H45 -> 0.19 | J45: =I45*Summary!$H$4 -> 32.775 | M45: =((F45+G45)*K45)+((F45+G45)*L45) -> 0 | N45: =M45+J45 -> 32.775
B47: =IF('Fixtures + Piping computation'!C43>0,'Fixtures + Piping computation'!B43 & " (" &'Fixtures + Piping computation'!C43 & ")",'Fixtures + Piping computation'!C43) -> Espresso (19742 (OSM)) | D47: SB | E47: X | F47: ='Fixtures + Piping computation'!D196 -> 2 | H47: 2.25 | I47: =(F47+G47)*H47 -> 4.5 | J47: =I47*Summary!$H$4 -> 776.25 | L47: ='Pricing Master Sheet'!E53 -> 0 | M47: =((F47+G47)*K47)+((F47+G47)*L47) -> 0 | N47: =M47+J47 -> 776.25
B48: Accessories
B49: Dual check valve 3/4", ASSE 1024 | C49: 3/4" LF7RU2-2 Dual Check Valve (Lead Free) | D49: X | E49: X | F49: =F47 -> 2 | M49: =((F49+G49)*K49)+((F49+G49)*L49) -> 0 | N49: =M49+J49 -> 0
B50: Shut-off valve 3/4" | C50: Nibco, T-585-66-LF | D50: X | E50: X | F50: =F47 -> 2 | M50: =((F50+G50)*K50)+((F50+G50)*L50) -> 0 | N50: =M50+J50 -> 0
B51: Water hammer arrester 1/2" | D51: X | E51: X | F51: 1 | M51: =((F51+G51)*K51)+((F51+G51)*L51) -> 0 | N51: =M51+J51 -> 0
...

Sheet Fixtures + Piping computation
B2: Project Name | C2: =Summary!C2 -> University Park Village Starbucks
B3: Address | C3: =Summary!C3 -> 1620 S University DR, Fort Worth, TX 76107
B4: Plan Date | C4: =Summary!C4 -> June 17, 2025
B6: FIXTURES | D6: 1st Level | E6: TOTAL
B7: Water Closet | C7: 22558 | D7: 2 | E7: =D7 -> 2
B8: Mop Sink | C8: 10995 /10922 (OSM) | D8: 1 | E8: =D8 -> 1
B9: Sink WH | C9: 10116 /21352 (OSM) | D9: 2 | E9: =D9 -> 2
B10: Sink with CTOP rinser | C10: 22768 (OSM) | D10: 2 | E10: =D10 -> 2
B11: CTOP-F water tower | C11: 10153 (OSM) | D11: =D10 -> 2 | E11: =D11 -> 2
B12: CTOP-F metered | C12: 11003 (OSM) | D12: =D10 -> 2 | E12: =D12 -> 2
B13: CTOP-F-Insta hot2 | C13: 22642 (OSM) | D13: =D10 -> 2 | E13: =D13 -> 2
B14: Sink-hand w/ side splash | C14: 14688/13588 (OSM) | D14: 1 | E14: =D14 -> 1
B15: 3-Comp SST | C15: 13264 (OSM) | D15: 1 | E15: =D15 -> 1
B16: 3-comp F- pre-rinse with sprayer | C16: 10447 (OSM) | D16: =D15 -> 1 | E16: =D16 -> 1
B17: 3-comp F- pre-rinse swing | C17: 10804 (OSM) | D17: =D15 -> 1 | E17: =D17 -> 1
B18: Sink-rinse drop-in SST | C18: 10549/10152 (OSM) | D18: 1 | E18: =D18 -> 1
B19: Sink water filling | C19: 18473 (OSM) | D19: =1 -> 1 | E19: =D19 -> 1
B20: SW F-water tower | C20: 10153 (OSM) | D20: =D19 -> 1 | E20: =D20 -> 1
B21: SW F-double lab | C21: 10215 (OSM) | D21: =D19 -> 1 | E21: =D21 -> 1
B22: SW-F-Insta hot2 | C22: 22642 (OSM) | D22: =D21 -> 1 | E22: =D22 -> 1
B23: Sink drop-in | C23: 22630 (OSM) | D23: =1 -> 1 | E23: =D23 -> 1
B24: Sink F-water tower | C24: 10153 (OSM) | D24: =D23 -> 1 | E24: =D24 -> 1
B25: Sink F-single lab | C25: 10943 (OSM) | D25: =D23 -> 1 | E25: =D25 -> 1
B26: Faucet-single handle | C26: 10597 (OSM) | D26: 2 | E26: =D26 -> 2
B28: TOTAL FIXTURES | D28: =SUM(D7:D27) -> 27 | E28: =SUM(E7:E27) -> 27
B30: EQUIPMENT
B31: Water heater | C31: 22232 | D31: 1 | E31: =D31 -> 1
B32: Recirculating pump | C32: X2500 | D32: 1 | E32: =D32 -> 1
B33: Filter - RO | C33: 12501 (SB-VD) | D33: 1 | E33: =D33 -> 1
B34: Filter - Booster Pump | C34: 23355 (SB-VD) | D34: 1 | E34: =D34 -> 1
B35: Filter-Water softener | C35: 13082 (SB-VD) | D35: 1 | E35: =D35 -> 1
B36: Filter-Pre-filtration | C36: 13076 (SB-VD) | D36: 1 | E36: =D36 -> 1
B37: Filter-Polyglass vessel | C37: 12899 (SB-VD) | D37: 2 | E37: =D37 -> 2
B38: Filter-Brine Tank | C38: 12896 (SB-VD) | D38: 1 | E38: =D38 -> 1
B39: Filter - RO storage tank | C39: 12507 (SB-VD) | D39: 1 | E39: =D39 -> 1
B40: Booster pump | C40: BP | D40: 1 | E40: =D40 -> 1
B42: KITCHEN EQUIPMENT
B43: Espresso | C43: 19742 (OSM) | D43: 2 | E43: =D43 -> 2
B44: Ice Bin | C44: 19728 (OSM) | D44: 2 | E44: =D44 -> 2
B45: Ice Bin | C45: 18029 (OSM) | D45: 1 | E45: =D45 -> 1
...

Sheet Pricing Master Sheet
A1: Vendor Quotation :
A2: Date:
A6: ='[1]Fixture+Pipe Pricing'!B82 -> Water Closet (22558) | C6: 1 | D6: 111.597.00.1 geberit / davis sales grp | E6: =B6*C6 -> 0
C7: 1 | D7: johnny bolts | E7: =B7*C7 -> 0
E8: =SUM(E6:E7) -> 0
A10: ='[1]Fixture+Pipe Pricing'!B88 -> Sink Restroom (10116) | C10: 1 | D10: 760-1 1-1/4X6 CAST GRID DRAIN | E10: =B10*C10 -> 0
C11: 1 | D11: 701-1 1-1/4 CP 17GA P-TRAP | E11: =B11*C11 -> 0
C12: 2 | D12: EFSV-12CX38C UPONOR ANGLE STOP | E12: =B12*C12 -> 0
C13: 2 | D13: 1-20A CP 3/8X20 LAV RISER | E13: =B13*C13 -> 0
C14: 2 | D14: 1099B 5/8 OD CP FLANGE | E14: =B14*C14 -> 0
E15: =SUM(E10:E14) -> 0
A17: ='[1]Fixture+Pipe Pricing'!B90 -> Sink Rinse Drop In (10549) | C17: 2 | D17: EFSV-12CX38C UPONOR ANGLE STOP | E17: =B17*C17 -> 0
C18: 2 | D18: EF-FC-38DT-20 3/8C X 20 CONN | E18: =B18*C18 -> 0
C19: 2 | D19: 1099B 5/8 OD CP FLANGE | E19: =B19*C19 -> 0
E20: =SUM(E17:E19) -> 0
A23: ='[1]Fixture+Pipe Pricing'!B96 -> Sink 3 Comp (13264) | C23: 2 | D23: EFSV-12CX38C UPONOR ANGLE STOP | E23: =B23*C23 -> 0
C24: 2 | D24: EF-FC-38DT-20 3/8C X 20 CONN | E24: =B24*C24 -> 0
C25: 2 | D25: 1099B 5/8 OD CP FLANGE | E25: =B25*C25 -> 0
E26: =SUM(E23:E25) -> 0
A28: ='[1]Fixture+Pipe Pricing'!B101 -> Sink Hand (14688) | C28: 1 | D28: 760-1 1-1/4X6 CAST GRID DRAIN | E28: =B28*C28 -> 0
C29: 1 | D29: 701-1 1-1/4 CP 17GA P-TRAP | E29: =B29*C29 -> 0
C30: 2 | D30: EFSV-12CX38C UPONOR ANGLE STOP | E30: =B30*C30 -> 0
C31: 2 | D31: EF-FC-38DT-20 3/8C X 20 CONN | E31: =B31*C31 -> 0
C32: 2 | D32: 1099B 5/8 OD CP FLANGE | E32: =B32*C32 -> 0
E33: =SUM(E28:E32) -> 0
A35: ='[1]Fixture+Pipe Pricing'!B105 -> Sink Water Filling Station (18743) | C35: 2 | D35: EFSV-12CX38C UPONOR ANGLE STOP | E35: =B35*C35 -> 0
C36: 2 | D36: EF-FC-38DT-20 3/8C X 20 CONN | E36: =B36*C36 -> 0
C37: 2 | D37: 1099B 5/8 OD CP FLANGE | E37: =B37*C37 -> 0
E38: =SUM(E35:E37) -> 0
A40: ='[1]Fixture+Pipe Pricing'!B107 -> Sink Rinse Drop In (22630) | C40: 2 | D40: EFSV-12CX38C UPONOR ANGLE STOP | E40: =B40*C40 -> 0
C41: 2 | D41: EF-FC-38DT-20 3/8C X 20 CONN | E41: =B41*C41 -> 0
C42: 2 | D42: 1099B 5/8 OD CP FLANGE | E42: =B42*C42 -> 0
E43: =SUM(E40:E42) -> 0
A45: ='[1]Fixture+Pipe Pricing'!B109 -> Sink Countertop Rinser (22768) | C45: 2 | D45: EFSV-12CX38C UPONOR ANGLE STOP | E45: =B45*C45 -> 0
C46: 2 | D46: EF-FC-38DT-20 3/8C X 20 CONN | E46: =B46*C46 -> 0
C47: 2 | D47: 1099B 5/8 OD CP FLANGE | E47: =B47*C47 -> 0
E48: =SUM(E45:E47) -> 0
A50: ='[1]Fixture+Pipe Pricing'!B38 -> Espresso Machine (19742)
C51: 2 | D51: EF-FC-38DT-20 3/8C X 20 CONN | E51: =B51*C51 -> 0
C52: 2 | D52: 1099B 5/8 OD CP FLANGE | E52: =B52*C52 -> 0
...

Sheet Unit Prices
B3: Pipe sizes, labor and cost | H3: Specialties/Valves, labor and cost
B4: Material | C4: Size | D4: Labor rate | E4: Material Cost | H4: Material | I4: Size | J4: Description | K4: Labor rate | L4: Material Cost | N4: Fixture | O4: Notes | P4: Labor Rate | Q4: Material Cost | S4: Equipment | T4: Notes | U4: Labor Rate | V4: Material Cost
B5: COPPER | N5: WATER CLOSET
B6: Copper Type M Hard | C6: 1/2" | D6: 0.032 | E6: 2.2032 | H6: SAN. SPECIALTIES | N6: Floor mount, flush tank, ADA | P6: 2.1 | S6: GREASE/OIL INTERCEPTOR
B7: Copper Type M Hard | C7: 3/4" | D7: 0.035 | E7: 3.4608 | H7: Floor drain | I7: 2" | K7: 0.5 | N7: Floor mount, flush valve, ADA | P7: 2.6 | S7: Park/Trooper GT-1500 Concrete | U7: 36 | V7: 10662.7
B8: Copper Type M Hard | C8: 1" | D8: 0.038 | E8: 5.292 | H8: Floor drain | I8: 3" | K8: 0.5 | N8: Floor mount, auto flush valve, ADA | P8: 3.2 | S8: 24" Riser Ext | T8: Add 2 qty | V8: 234.94
B9: Copper Type M Hard | C9: 1-1/4" | D9: 0.042 | E9: 8.1102 | H9: Floor drain | I9: 4" | K9: 0.5 | N9: Wall mount, flush valve, ADA | P9: 3.55
B10: Copper Type M Hard | C10: 1-1/2" | D10: 0.046 | E10: 11.1636 | N10: Wall mount, auto flush valve, ADA | P10: 3.8
B11: Copper Type M Hard | C11: 2" | D11: 0.053 | E11: 17.1696 | H11: Floor cleanout | I11: 2" | K11: 0.35 | S11: ELECTRIC WATER HEATER
B12: Copper Type M Hard | C12: 2-1/2" | D12: 0.06 | E12: 25.0068 | H12: Floor cleanout | I12: 3" | K12: 0.45 | N12: URINAL W/ TRIM | S12: Lowboy Water Heater up to 50 gal | T12: w/ wall mount and straps | U12: 4
B13: Copper Type M Hard | C13: 3" | D13: 0.066 | E13: 33.1968 | H13: Floor cleanout | I13: 4" | K13: 0.5 | N13: Wall mount, flush valve, ADA | P13: 3.2 | S13: Tall & Short Water Heater up to 90 gal | U13: 3.5
B14: Copper Type L Hard | C14: 1/2" | D14: 0.032 | E14: 3.565 | H14: Floor cleanout | I14: 6" | K14: 0.5 | N14: Stall type, flush valve, ADA | P14: 5 | S14: Tall & Short Water Heater 90 gal - 120 gal | U14: 4
B15: Copper Type L Hard | C15: 3/4" | D15: 0.035 | E15: 6.4285 | H15: Floor cleanout | I15: 8" | K15: 0.55 | N15: +0.6 for carrier | P15: 0.6 | S15: Tall & Short Water Heater up to 250 gal | U15: 6
B16: Copper Type L Hard | C16: 1" | D16: 0.038 | E16: 7.683 | N16: +0.6 for electronic flush valve | P16: 0.6 | S16: Tankless Water Heater 5.5kw | U16: 4
B17: Copper Type L Hard | C17: 1-1/4" | D17: 0.042 | E17: 13.2465 | H17: Wall cleanout | I17: 2" | K17: 0.35 | S17: Tankless Water Heater 9.5kw | U17: 4.25
B18: Copper Type L Hard | C18: 1-1/2" | D18: 0.046 | E18: 22.391 | H18: Wall cleanout | I18: 3" | K18: 0.35 | N18: LAVATORY W/ TRIM | S18: Tankless Water Heater 12kw | U18: 4.5
B19: Copper Type L Hard | C19: 2" | D19: 0.053 | E19: 22.8915 | H19: Wall cleanout | I19: 4" | K19: 0.4 | N19: Wall hung, basic faucet, ADA | P19: 2.7 | S19: Tankless Water Heater 28kw | U19: 4.75
B20: Copper Type L Hard | C20: 2-1/2" | D20: 0.06 | E20: 28.628 | H20: Wall cleanout | I20: 6" | K20: 0.4 | N20: Counter top, basic faucet, ADA | P20: 2 | S20: Point of Use Water Heater | T20: up to any KW w/ piping considered | U20: 2
B21: Copper Type L Hard | C21: 3" | D21: 0.066 | E21: 44.5515 | H21: Wall cleanout | I21: 8" | K21: 0.55 | N21: Undermount, basic faucet, ADA | P21: 2
B22: Copper Type L Hard | C22: 4" | D22: 0.08 | E22: 73.6795 | N22: -0.5 if carrier is installed already (wall hung only) | P22: -0.5 | S22: GAS WATER HEATER
B23: Copper Type K Soft | C23: 1/2" | D23: 0.032 | E23: 7.57 | H23: Floor sink 9" x 9" | K23: 1 | N23: +1.0 for electronic sensor faucet | P23: 1 | S23: Tall & Short Gas Water Heater up to 100 gal | U23: 4
B24: Copper Type K Soft | C24: 3/4" | D24: 0.035 | E24: 14.2 | H24: Floor sink 12" x 12" | K24: 1 | N24: +0.2 for P-trap insulation | P24: 0.2 | S24: Tankless Gas Water Heater up to 140 MBH | T24: Use the labor rate as N for Rack system | U24: 4
B25: Copper Type K Soft | C25: 1" | D25: 0.038 | E25: 18.55 | H25: Floor sink 15" x 15" | K25: 1.15 | N25: +0.35 for mixing valve | P25: 0.35 | S25: Tankless Gas Water Heater up to 199 MBH | T25: Use the labor rate as N for Rack system | U25: 4.5
B26: Copper Type K Soft | C26: 1-1/4" | D26: 0.042 | E26: 38.08 | H26: Floor sink 18" x 18" | K26: 1.25 | S26: Tankless Gas Water Heater up to 235 MBH | T26: Use the labor rate as N for Rack system | U26: 5
B27: Copper Type K Soft | C27: 1-1/2" | D27: 0.046 | E27: 49.51 | H27: Floor sink 24" x 24" | K27: 1.5 | N27: KITCHEN SINK W/ TRIM | S27: For Tankless Rack System | T27: Use LR = (no. of unit/10+1)xN
B28: Copper Type K Soft | C28: 2" | D28: 0.053 | E28: 90.31 | N28: Counter top, single compartment, stainless steel, ADA | P28: 2
B29: Copper Type K Soft | C29: 2-1/2" | D29: 0.06 | E29: 137.35 | H29: Downspout Nozzle | I29: 4" | J29: Josam 25024 SS | K29: 0.65 | L29: 678.71 | N29: Counter top, double compartment, stainless steel, ADA | P29: 2.15 | S29: GAS WATER HEATER VENT
B30: Copper Type K Soft | C30: 3" | D30: 0.066 | E30: 191.05 | H30: Downspout Nozzle | I30: 4" | J30: Josam 25014 BS (Bronze) | K30: 0.65 | L30: 252.75 | N30: Three compartment, stainless steel, ADA | P30: 2.6 | S30: 2" | T30: add additional rate if exceed 25ft | U30: 2
B31: Copper Type K Hard | C31: 1/2" | D31: 0.032 | E31: 6.81228 | H31: Downspout Nozzle | I31: 6" | J31: Josam 25016 BS (Bronze) | K31: 0.65 | L31: 438 | N31: +0.2 for P-trap insulation | P31: 0.2 | S31: 3" | T31: add additional rate if exceed 25ft | U31: 2
B32: Copper Type K Hard | C32: 3/4" | D32: 0.035 | E32: 12.43584 | N32: +0.35 for mixing valve | P32: 0.35 | S32: 4" | T32: add additional rate if exceed 25ft | U32: 2
B33: Copper Type K Hard | C33: 1" | D33: 0.038 | E33: 16.16964 | N33: +0.35 for pulldown wall mount 2 handle faucet (3-comp) | P33: 0.35 | S33: 6" | T33: add additional rate if exceed 25ft | U33: 2
B34: Copper Type K Hard | C34: 1-1/4" | D34: 0.042 | E34: 20.29968 | N34: +2 for garbage disposer 1/2-3/4 hp | P34: 2
B35: Copper Type K Hard | C35: 1-1/2" | D35: 0.046 | E35: 26.77668 | S35: ELECTRIC WATER HEATER PIPING
B36: Copper Type K Hard | C36: 2" | D36: 0.053 | E36: 39.86784 | H36: WATER SPECIALTIES | N36: LAUNDRY SINK W/ TRIM | S36: Note: Piping considered are the following; 2x Ball Valves, 1x Check Valve, 1x Expansion Tank, 1x Vacuum Relief Valve
B37: Copper Type K Hard | C37: 2-1/2" | D37: 0.06 | E37: 58.5978 | H37: BALL VALVE | N37: Single compartment stainless steel | P37: 2.25 | S37: 3/4" | U37: 3
B38: Copper Type K Hard | C38: 3" | D38: 0.066 | E38: 80.87868 | H38: Threaded End, Brass, 2-piece body | I38: 1/2" | J38: Nibco T-FP600A | K38: 0.21 | L38: 22.0115 | S38: 1" | U38: 3
B39: Copper Type K Hard | C39: 4" | D39: 0.08 | E39: 104.51592 | H39: Threaded End, Brass, 2-piece body | I39: 3/4" | J39: Nibco T-FP600A | K39: 0.25 | L39: 28.4487 | N39: HAND SINK W/ TRIM | S39: 1-1/4" | U39: 3.5
B40: Copper Type L Hard C&C | C40: 1/2" | D40: 0.032 | E40: 10.82 | H40: Threaded End, Brass, 2-piece body | I40: 1" | J40: Nibco T-FP600A | K40: 0.3 | L40: 45.9249 | N40: Wall mount, knee pedal, stainless steel | P40: 2.7 | S40: 1-1/2" | U40: 3.75
B41: Copper Type L Hard C&C | C41: 3/4" | D41: 0.035 | E41: 17.21 | H41: Threaded End, Brass, 2-piece body | I41: 1-1/4" | J41: Nibco T-FP600A | K41: 0.4 | L41: 87.4874 | N41: +0.1 for splash guard | P41: 0.1 | S41: 2" | U41: 4
B42: Copper Type L Hard C&C | C42: 1" | D42: 0.038 | E42: 24.76 | H42: Threaded End, Brass, 2-piece body | I42: 1-1/2" | J42: Nibco T-FP600A | K42: 0.45 | L42: 120.7906 | S42: 2-1/2" | U42: 5
...
