Workbook
Name UnitType2: #REF!
Name UnitType2: #REF!
Name UnitType2: #REF!
Name UnitType2: #REF!
Name Validation_Equipment: OFFSET('[1]EQUIPMENT DYNAMIC LIST'!$N$2,,,COUNTIF('[1]EQUIPMENT DYNAMIC LIST'!$N$2:$N$500,"?*"))
Name Validation_Fans: OFFSET('[1]FAN DYNAMIC LIST'!$Q$2,,,COUNTIF('[1]FAN DYNAMIC LIST'!$Q$2:$Q$1000,"?*"))
Name Validation_Heaters: OFFSET('[1]HEATER DYNAMIC LIST'!$Q$2,,,COUNTIF('[1]HEATER DYNAMIC LIST'!$Q$2:$Q$1000,"?*"))
Name Validation_MiniSplit: OFFSET('[1]MINI SPLIT DYNAMIC LIST'!$Q$2,,,COUNTIF('[1]MINI SPLIT DYNAMIC LIST'!$Q$2:$Q$1000,"?*"))
Name Validation_PTAC: OFFSET('[1]PTAC DYNAMIC LIST'!$Q$2,,,COUNTIF('[1]PTAC DYNAMIC LIST'!$Q$2:$Q$1000,"?*"))
Name Validation_Thermstats: OFFSET('[1]THERMOSTAT DYNAMIC LIST'!$M$2,,,COUNTIF('[1]THERMOSTAT DYNAMIC LIST'!$M$2:$M$500,"?*"))

Sheet Summary
B2: Project Name | C2: University Park Village | G2: Total SQFT | H2: 2808
B3: Address | C3: 1620 S University DR, Fort Worth, TX 76107 | G3: Number of Units | H3: 1
B4: Plan Date | C4: 45962 | G4: Labor Rate:
G5: Quotation ref. no
B7: Item No. | C7: Description | D7: Qty | E7: Lin. Ft. | F7: Total Labor hrs | G7: Material Pricing | H7: Total
B8: Demolition | D8: =DEMOLITION!F10 -> 4 | F8: =DEMOLITION!I10 -> 2.5 | G8: =DEMOLITION!L10 -> 0 | H8: =G8+(F8*$H$4) -> 0 | I8: =DEMOLITION!O10 -> 0
B9: Heating and Airconditioning
C10: Equipment | D10: ='HVAC COST'!F33 -> 4 | F10: ='HVAC COST'!I33 -> 70.438867 | G10: ='HVAC COST'!L33 -> 0 | H10: =G10+(F10*$H$4) -> 0 | I10: ='HVAC COST'!N33 -> 0
C11: Ductwork and Accessories | E11: ='HVAC COST'!G153 -> 346.94 | F11: ='HVAC COST'!I75+'HVAC COST'!I153 -> 123.18982 | G11: ='HVAC COST'!L75+'HVAC COST'!L153+'HVAC COST'!L154 -> 0 | H11: =G11+(F11*$H$4) -> 0 | I11: ='HVAC COST'!N75+'HVAC COST'!N153+'HVAC COST'!N154 -> 0
C12: Duct Insulation | D12: ='HVAC COST'!F82 -> 4.1650167 | F12: ='HVAC COST'!I82 -> 16.328053 | G12: ='HVAC COST'!L82 -> 0 | H12: =G12+(F12*$H$4) -> 0 | I12: ='HVAC COST'!N82 -> 0
B13: General Exhaust System | H13: =G13+(F13*$H$4) -> 0
C14: Equipment | D14: ='HVAC COST'!F51 -> 2 | F14: ='HVAC COST'!I51 -> 15.202033 | G14: ='HVAC COST'!L51 -> 0 | H14: =G14+(F14*$H$4) -> 0 | I14: ='HVAC COST'!N51 -> 0
C15: Ductworks and accessories | E15: ='HVAC COST'!G165 -> 59.53 | F15: ='HVAC COST'!I165 -> 9.01491 | G15: ='HVAC COST'!L165+'HVAC COST'!L166 -> 0 | H15: =G15+(F15*$H$4) -> 0 | I15: ='HVAC COST'!N165+'HVAC COST'!N166 -> 0
B17: Testing and commissioning | D17: 1 lot | F17: ='HVAC COST'!I175 -> 33.75 | G17: ='HVAC COST'!L175 -> 0 | H17: =G17+(F17*$H$4) -> 0 | I17: ='HVAC COST'!N175 -> 0
B18: Miscellaneous | D18: 1 lot | F18: ='HVAC COST'!I216+DEMOLITION!I13 -> 276.24248 | G18: ='HVAC COST'!L216+DEMOLITION!L13 -> 0 | H18: =G18+(F18*$H$4) -> 0 | I18: ='HVAC COST'!N216+DEMOLITION!O13 -> 0 | K18: =SUM(H8:H18) -> 0 | L18: =K19-K18 -> 0
I19: =SUM(I8:I18) -> 0 | K19: ='HVAC COST'!N217+DEMOLITION!O14 -> 0
B20: Overhead and Profit
C21: Permits and fees | H21: =SUM(H8:H18)*0.005 -> 0
C22: Project Management-Mobilization , demobilization, 1 yr warranty costs, tools and utilities | F22: =SUM(F8:F18)/4 -> 136.66654 | H22: =F22*H4 -> 0 | I22: =SUM(I8:I18)*0.1 -> 0
C23: Contigency | G23: 0.02 | H23: =G23*(SUM(H8:H18)+H22) -> 0
C24: Profit | H24: =G24*(SUM(H8:H18)+H22+H23) -> 0
B26: TOTAL | H26: =SUM(H8:H25) -> 0 | J26: Price per sqft | K26: =H26/H2 -> 0
J27: Price per Unit | K27: =H26/H3 -> 0
B28: Project Information | C28: Demolition & Renovation of University Park Village 1620 S University DR, Fort Worth, TX 76107
J29: =H16+H15 -> 0
B30: Scope of Work | J30: =J29/I13 -> #DIV/0! | L30: =H26-L29 -> 0
B32: Supply and Installation | C32: Heating & Airconditioning System
C33: Sheet metal duct and fittings for Rectangular Duct( Supply ,return and outside air)
C34: GI Sheet metal and fittings for Round Duct( Supply ,return and outside air)
C35: Flexible duct for AHU supply air
C36: Duct insulation( Supply and return)
C37: Equipment including support
C38: Rooftop Unit
C39: Air Curtain Unit
C40: Duct specialties and air outlets
B41: Supply and Installation | C41: General Exhaust System
C42: Sheet metal duct and fittings( Exhaust)
C43: Equipment including support
C44: Exhaust Fan
C45: Duct specialties and air outlets
...

Sheet HVAC COST
C2: Description | D2: Supply | E2: Install | F2: Qty | G2: Lin. Ft. | H2: Unit Labor | I2: Total Labor hrs | J2: Total Labor Cost | K2: Unit Material Cost | L2: Total Material Cost | M2: Total
A3: x | B3: Project Name: | C3: =Summary!C2 -> University Park Village
B4: Address: | C4: =Summary!C3 -> 1620 S University DR, Fort Worth, TX 76107
B5: Plan Date: | C5: =Summary!C4 -> 45962
B7: HEATING & AIRCONDITIONING
B8: EQUIPMENT
P10: =IF(E10="X",IF(F10<>"",IF(OR(H10<>"",M10<>""),"✔","ERROR"), "ERROR"), 0) -> 0 | Q10: =IF(D10="X", IF(F10<>"", IF(AND(L10<>"",M10<>""), "✔", "ERROR"), "ERROR"),0) -> 0
B11: ROOFTOP UNIT | P11: =IF(E11="X",IF(F11<>"",IF(OR(H11<>"",M11<>""),"✔","ERROR"), "ERROR"), 0) -> 0 | Q11: =IF(D11="X", IF(F11<>"", IF(AND(L11<>"",M11<>""), "✔", "ERROR"), "ERROR"),0) -> 0
B12: ='MAT - TAKEOFF'!H63 -> ROOFTOP UNIT; RTU-1_TRANE YHK120_10 TONS | C12: =IFERROR(MID(B12, FIND("_", B12) + 1, FIND("_", B12, FIND("_", B12) + 1) - FIND("_", B12) - 1), "") -> TRANE YHK120 | D12: X | E12: X | F12: ='MAT - TAKEOFF'!I63 -> 1 | H12: 14.6 | I12: =((G12+F12)*H12) -> 14.6 | J12: =(I12)*Summary!$H$4 -> 0 | L12: =((F12+G12)*K12) -> 0 | M12: =L12+J12 -> 0 | P12: =IF(E12="X",IF(F12<>"",IF(OR(H12<>"",M12<>""),"✔","ERROR"), "ERROR"), 0) -> ✔ | Q12: =IF(D12="X", IF(F12<>"", IF(AND(L12<>"",M12<>""), "✔", "ERROR"), "ERROR"),0) -> ✔
B13: ='MAT - TAKEOFF'!H64 -> ROOFTOP UNIT; RTU-2_TRANE YHK090*_7.5 TONS | C13: =IFERROR(MID(B13, FIND("_", B13) + 1, FIND("_", B13, FIND("_", B13) + 1) - FIND("_", B13) - 1), "") -> TRANE YHK090* | D13: X | E13: X | F13: ='MAT - TAKEOFF'!I64 -> 1 | H13: 12.6 | I13: =((G13+F13)*H13) -> 12.6 | J13: =(I13)*Summary!$H$4 -> 0 | L13: =((F13+G13)*K13) -> 0 | M13: =L13+J13 -> 0 | P13: =IF(E13="X",IF(F13<>"",IF(OR(H13<>"",M13<>""),"✔","ERROR"), "ERROR"), 0) -> ✔ | Q13: =IF(D13="X", IF(F13<>"", IF(AND(L13<>"",M13<>""), "✔", "ERROR"), "ERROR"),0) -> ✔
B14: ='MAT - TAKEOFF'!H65 -> ROOFTOP UNIT; RTU-3_TRANE YHK036*_3 TONS | C14: =IFERROR(MID(B14, FIND("_", B14) + 1, FIND("_", B14, FIND("_", B14) + 1) - FIND("_", B14) - 1), "") -> TRANE YHK036* | D14: X | E14: X | F14: ='MAT - TAKEOFF'!I65 -> 1 | H14: 9.6 | I14: =((G14+F14)*H14) -> 9.6 | J14: =(I14)*Summary!$H$4 -> 0 | L14: =((F14+G14)*K14) -> 0 | M14: =L14+J14 -> 0 | P14: =IF(E14="X",IF(F14<>"",IF(OR(H14<>"",M14<>""),"✔","ERROR"), "ERROR"), 0) -> ✔ | Q14: =IF(D14="X", IF(F14<>"", IF(AND(L14<>"",M14<>""), "✔", "ERROR"), "ERROR"),0) -> ✔
J15: =(I15)*Summary!$H$4 -> 0 | P15: =IF(E15="X",IF(F15<>"",IF(OR(H15<>"",M15<>""),"✔","ERROR"), "ERROR"), 0) -> 0 | Q15: =IF(D15="X", IF(F15<>"", IF(AND(L15<>"",M15<>""), "✔", "ERROR"), "ERROR"),0) -> 0
B16: ACCESSORIES | J16: =(I16)*Summary!$H$4 -> 0 | L16: =((F16+G16)*K16) -> 0 | M16: =L16+J16 -> 0 | P16: =IF(E16="X",IF(F16<>"",IF(OR(H16<>"",M16<>""),"✔","ERROR"), "ERROR"), 0) -> 0 | Q16: =IF(D16="X", IF(F16<>"", IF(AND(L16<>"",M16<>""), "✔", "ERROR"), "ERROR"),0) -> 0
B17: THERMOSTAT | D17: X | E17: X | F17: =SUM(F12:F14) -> 3 | H17: 0.75 | I17: =((G17+F17)*H17) -> 2.25 | J17: =(I17)*Summary!$H$4 -> 0 | L17: =((F17+G17)*K17) -> 0 | M17: =L17+J17 -> 0 | P17: =IF(E17="X",IF(F17<>"",IF(OR(H17<>"",M17<>""),"✔","ERROR"), "ERROR"), 0) -> ✔ | Q17: =IF(D17="X", IF(F17<>"", IF(AND(L17<>"",M17<>""), "✔", "ERROR"), "ERROR"),0) -> ✔
B18: TEMPERATURE SENSOR | D18: X | E18: X | F18: ='MAT - TAKEOFF'!I68 -> 3 | H18: 0.45 | I18: =((G18+F18)*H18) -> 1.35 | J18: =(I18)*Summary!$H$4 -> 0 | L18: =((F18+G18)*K18) -> 0 | M18: =L18+J18 -> 0
B19: TEMPERATURE SENSOR CONTROL WIRING | C19: ASSUME 15FT | D19: X | E19: X | G19: =F18*15 -> 45 | H19: 0.03 | I19: =((G19+F19)*H19) -> 1.35 | J19: =(I19)*Summary!$H$4 -> 0 | L19: =((F19+G19)*K19) -> 0 | M19: =L19+J19 -> 0
B20: OVERFLOW SWITCH | D20: X | E20: X | F20: =F17 -> 3 | H20: =COMPUTATION!F558 -> 0.5 | I20: =((G20+F20)*H20) -> 1.5 | J20: =(I20)*Summary!$H$4 -> 0 | L20: =((F20+G20)*K20) -> 0 | M20: =L20+J20 -> 0 | P20: =IF(E20="X",IF(F20<>"",IF(OR(H20<>"",M20<>""),"✔","ERROR"), "ERROR"), 0) -> ✔ | Q20: =IF(D20="X", IF(F20<>"", IF(AND(L20<>"",M20<>""), "✔", "ERROR"), "ERROR"),0) -> ✔
B21: ROOF CURB | D21: X | E21: X | F21: =F17 -> 3 | H21: 4 | I21: =((G21+F21)*H21) -> 12 | J21: =(I21)*Summary!$H$4 -> 0 | L21: =((F21+G21)*K21) -> 0 | M21: =L21+J21 -> 0 | P21: =IF(E21="X",IF(F21<>"",IF(OR(H21<>"",M21<>""),"✔","ERROR"), "ERROR"), 0) -> ✔ | Q21: =IF(D21="X", IF(F21<>"", IF(AND(L21<>"",M21<>""), "✔", "ERROR"), "ERROR"),0) -> ✔
B22: ='MAT - TAKEOFF'!H66 -> SMOKE DETECTOR | D22: X | E22: X | F22: ='MAT - TAKEOFF'!I66 -> 2 | H22: 0.45 | I22: =((G22+F22)*H22) -> 0.9 | J22: =(I22)*Summary!$H$4 -> 0 | L22: =((F22+G22)*K22) -> 0 | M22: =L22+J22 -> 0 | P22: =IF(E22="X",IF(F22<>"",IF(OR(H22<>"",M22<>""),"✔","ERROR"), "ERROR"), 0) -> ✔ | Q22: =IF(D22="X", IF(F22<>"", IF(AND(L22<>"",M22<>""), "✔", "ERROR"), "ERROR"),0) -> ✔
B23: FLEXIBLE CONNECTOR | D23: X | E23: X | F23: =SUM(F12:F14)*2 -> 6 | H23: 0.65 | I23: =((G23+F23)*H23) -> 3.9 | J23: =(I23)*Summary!$H$4 -> 0 | L23: =((F23+G23)*K23) -> 0 | M23: =L23+J23 -> 0 | P23: =IF(E23="X",IF(F23<>"",IF(OR(H23<>"",M23<>""),"✔","ERROR"), "ERROR"), 0) -> ✔ | Q23: =IF(D23="X", IF(F23<>"", IF(AND(L23<>"",M23<>""), "✔", "ERROR"), "ERROR"),0) -> ✔
B24: CO2 SENSOR | D24: X | E24: X | F24: ='MAT - TAKEOFF'!I5 -> 2 | H24: 0.45 | I24: =((G24+F24)*H24) -> 0.9 | J24: =(I24)*Summary!$H$4 -> 0 | L24: =((F24+G24)*K24) -> 0 | M24: =L24+J24 -> 0
B25: CO2 SENSOR CONTROL WIRING | C25: ASSUME 15FT | D25: X | E25: X | G25: =F24*15 -> 30 | H25: 0.03 | I25: =((G25+F25)*H25) -> 0.9 | J25: =(I25)*Summary!$H$4 -> 0 | L25: =((F25+G25)*K25) -> 0 | M25: =L25+J25 -> 0
J26: =(I26)*Summary!$H$4 -> 0 | P26: =IF(E26="X",IF(F26<>"",IF(OR(H26<>"",M26<>""),"✔","ERROR"), "ERROR"), 0) -> 0 | Q26: =IF(D26="X", IF(F26<>"", IF(AND(L26<>"",M26<>""), "✔", "ERROR"), "ERROR"),0) -> 0
B27: AIR CURTAIN UNIT | J27: =(I27)*Summary!$H$4 -> 0 | P27: =IF(E27="X",IF(F27<>"",IF(OR(H27<>"",M27<>""),"✔","ERROR"), "ERROR"), 0) -> 0 | Q27: =IF(D27="X", IF(F27<>"", IF(AND(L27<>"",M27<>""), "✔", "ERROR"), "ERROR"),0) -> 0
B28: ='MAT - TAKEOFF'!H2 -> AIR CURTAIN; X0702_ MARS STD242 | D28: X | E28: X | F28: ='MAT - TAKEOFF'!I2 -> 1 | H28: 3 | I28: =((G28+F28)*H28) -> 3 | J28: =(I28)*Summary!$H$4 -> 0 | L28: =((F28+G28)*K28) -> 0 | M28: =L28+J28 -> 0 | P28: =IF(E28="X",IF(F28<>"",IF(OR(H28<>"",M28<>""),"✔","ERROR"), "ERROR"), 0) -> ✔ | Q28: =IF(D28="X", IF(F28<>"", IF(AND(L28<>"",M28<>""), "✔", "ERROR"), "ERROR"),0) -> ✔
J29: =(I29)*Summary!$H$4 -> 0 | P29: =IF(E29="X",IF(F29<>"",IF(OR(H29<>"",M29<>""),"✔","ERROR"), "ERROR"), 0) -> 0 | Q29: =IF(D29="X", IF(F29<>"", IF(AND(L29<>"",M29<>""), "✔", "ERROR"), "ERROR"),0) -> 0
B30: EQUIPMENT IDENTIFICATION | D30: X | E30: X | F30: 1 | H30: =SUM(F12:F14,F28)*(10/60) -> 0.66666667 | I30: =((G30+F30)*H30) -> 0.66666667 | J30: =(I30)*Summary!$H$4 -> 0 | L30: =((F30+G30)*K30) -> 0 | M30: =L30+J30 -> 0 | P30: =IF(E30="X",IF(F30<>"",IF(OR(H30<>"",M30<>""),"✔","ERROR"), "ERROR"), 0) -> ✔ | Q30: =IF(D30="X", IF(F30<>"", IF(AND(L30<>"",M30<>""), "✔", "ERROR"), "ERROR"),0) -> ✔
B31: EQUIPMENT SUPPORT | D31: X | E31: X | F31: 1 | H31: =SUM(H12:H14,H28)*0.1 -> 3.98 | I31: =((G31+F31)*H31) -> 3.98 | J31: =(I31)*Summary!$H$4 -> 0 | L31: =((F31+G31)*K31) -> 0 | M31: =L31+J31 -> 0 | P31: =IF(E31="X",IF(F31<>"",IF(OR(H31<>"",M31<>""),"✔","ERROR"), "ERROR"), 0) -> ✔ | Q31: =IF(D31="X", IF(F31<>"", IF(AND(L31<>"",M31<>""), "✔", "ERROR"), "ERROR"),0) -> ✔
B32: MISCELLANEOUS AND CONSUMABLES | D32: X | E32: X | F32: 1 | H32: =SUM(H10:H29)*0.02 -> 0.9422 | I32: =((G32+F32)*H32) -> 0.9422 | J32: =(I32)*Summary!$H$4 -> 0 | L32: =((F32+G32)*K32) -> 0 | M32: =L32+J32 -> 0 | P32: =IF(E32="X",IF(F32<>"",IF(OR(H32<>"",M32<>""),"✔","ERROR"), "ERROR"), 0) -> ✔ | Q32: =IF(D32="X", IF(F32<>"", IF(AND(L32<>"",M32<>""), "✔", "ERROR"), "ERROR"),0) -> ✔
F33: =SUM(F12:F14,F28) -> 4 | I33: =SUM(I10:I32) -> 70.438867 | L33: =SUM(L10:L32) -> 0 | N33: =SUM(M10:M32) -> 0
B35: GENERAL EXHAUST SYSTEM
B37: EQUIPMENT
B38: EXHAUST EQUIPMENT
B39: ='MAT - TAKEOFF'!H16 -> EXHAUST FAN; X0632_GREENHECK G-090-VG_300 CFM | C39: =IFERROR(MID(B39, FIND("_", B39) + 1, FIND("_", B39, FIND("_", B39) + 1) - FIND("_", B39) - 1), "") -> GREENHECK G-090-VG | D39: X | E39: X | F39: ='MAT - TAKEOFF'!I16 -> 1 | H39: 4 | I39: =((G39+F39)*H39) -> 4 | J39: =(I39)*Summary!$H$4 -> 0 | L39: =((F39+G39)*K39) -> 0 | M39: =L39+J39 -> 0 | P39: =IF(E39="X",IF(F39<>"",IF(OR(H39<>"",M39<>""),"✔","ERROR"), "ERROR"), 0) -> ✔ | Q39: =IF(D39="X", IF(F39<>"", IF(AND(L39<>"",M39<>""), "✔", "ERROR"), "ERROR"),0) -> ✔
B40: ='MAT - TAKEOFF'!H17 -> EXHAUST FAN; X0633_ GREENHECK G-080-VG_150 CFM | C40: =IFERROR(MID(B40, FIND("_", B40) + 1, FIND("_", B40, FIND("_", B40) + 1) - FIND("_", B40) - 1), "") -> GREENHECK G-080-VG | D40: X | E40: X | F40: ='MAT - TAKEOFF'!I17 -> 1 | H40: 3.5 | I40: =((G40+F40)*H40) -> 3.5 | J40: =(I40)*Summary!$H$4 -> 0 | L40: =((F40+G40)*K40) -> 0 | M40: =L40+J40 -> 0 | P40: =IF(E40="X",IF(F40<>"",IF(OR(H40<>"",M40<>""),"✔","ERROR"), "ERROR"), 0) -> ✔ | Q40: =IF(D40="X", IF(F40<>"", IF(AND(L40<>"",M40<>""), "✔", "ERROR"), "ERROR"),0) -> ✔
C41: =IFERROR(MID(B41, FIND("_", B41) + 1, FIND("_", B41, FIND("_", B41) + 1) - FIND("_", B41) - 1), "") | J41: =(I41)*Summary!$H$4 -> 0 | P41: =IF(E41="X",IF(F41<>"",IF(OR(H41<>"",M41<>""),"✔","ERROR"), "ERROR"), 0) -> 0 | Q41: =IF(D41="X", IF(F41<>"", IF(AND(L41<>"",M41<>""), "✔", "ERROR"), "ERROR"),0) -> 0
B42: ACCESSORIES | C42: =IFERROR(MID(B42, FIND("_", B42) + 1, FIND("_", B42, FIND("_", B42) + 1) - FIND("_", B42) - 1), "") | J42: =(I42)*Summary!$H$4 -> 0 | P42: =IF(E42="X",IF(F42<>"",IF(OR(H42<>"",M42<>""),"✔","ERROR"), "ERROR"), 0) -> 0 | Q42: =IF(D42="X", IF(F42<>"", IF(AND(L42<>"",M42<>""), "✔", "ERROR"), "ERROR"),0) -> 0
B43: ='MAT - TAKEOFF'!H67 -> SPEED CONTROLLER | C43: =IFERROR(MID(B43, FIND("_", B43) + 1, FIND("_", B43, FIND("_", B43) + 1) - FIND("_", B43) - 1), "") | D43: X | E43: X | F43: =SUM(F39:F40) -> 2 | H43: 0.155 | I43: =((G43+F43)*H43) -> 0.31 | J43: =(I43)*Summary!$H$4 -> 0 | L43: =((F43+G43)*K43) -> 0 | M43: =L43+J43 -> 0 | P43: =IF(E43="X",IF(F43<>"",IF(OR(H43<>"",M43<>""),"✔","ERROR"), "ERROR"), 0) -> ✔ | Q43: =IF(D43="X", IF(F43<>"", IF(AND(L43<>"",M43<>""), "✔", "ERROR"), "ERROR"),0) -> ✔
B44: CONTROL WIRING | C44: ASSUME 10FT | D44: X | E44: X | G44: =F43*10 -> 20 | H44: 0.03 | I44: =((G44+F44)*H44) -> 0.6 | J44: =(I44)*Summary!$H$4 -> 0 | L44: =((F44+G44)*K44) -> 0 | M44: =L44+J44 -> 0 | P44: =IF(E44="X",IF(G44<>"",IF(OR(H44<>"",M44<>""),"✔","ERROR"), "ERROR"), 0) -> ✔ | Q44: =IF(D44="X", IF(G44<>"", IF(AND(L44<>"",M44<>""), "✔", "ERROR"), "ERROR"),0) -> ✔
B45: ='MAT - TAKEOFF'!H18 -> EXHAUST ROOF CURB | C45: =IFERROR(MID(B45, FIND("_", B45) + 1, FIND("_", B45, FIND("_", B45) + 1) - FIND("_", B45) - 1), "") | D45: X | E45: X | F45: =F43 -> 2 | H45: 2 | I45: =((G45+F45)*H45) -> 4 | J45: =(I45)*Summary!$H$4 -> 0 | L45: =((F45+G45)*K45) -> 0 | M45: =L45+J45 -> 0 | P45: =IF(E45="X",IF(F45<>"",IF(OR(H45<>"",M45<>""),"✔","ERROR"), "ERROR"), 0) -> ✔ | Q45: =IF(D45="X", IF(F45<>"", IF(AND(L45<>"",M45<>""), "✔", "ERROR"), "ERROR"),0) -> ✔
...

Sheet DEMOLITION
C2: Description | F2: Qty | G2: Lin. Ft. | H2: Unit Labor | I2: Total Labor Hrs | J2: Total Labor | K2: Unit Materials | L2: Install Materials | M2: Total Materials | N2: Total
B4: Demolition
B5: EQUIPMENT
B7: ='MAT - TAKEOFF'!H19 -> EXISTING EXHAUST FAN TO BE DEMOLISHED | F7: ='MAT - TAKEOFF'!I19 -> 1 | H7: 2 | I7: =((G7+F7)*H7)/8 -> 0.25 | J7: =(I7)*Summary!$H$4 -> 0 | N7: =M7+J7 -> 0
B8: ='MAT - TAKEOFF'!H20 -> EXISTING ROOFTOP UNIT TO BE DEMOLISHED | F8: ='MAT - TAKEOFF'!I20 -> 3 | H8: 6 | I8: =((G8+F8)*H8)/8 -> 2.25 | J8: =(I8)*Summary!$H$4 -> 0 | N8: =M8+J8 -> 0
C10: SUMTOTAL | F10: =SUM(F7:F9) -> 4 | G10: =SUM(G7:G9) -> 0 | I10: =SUM(I3:I9) -> 2.5 | J10: =SUM(J3:J9) -> 0 | L10: =SUM(L3:L9) -> 0 | O10: =SUM(N7:N9) -> 0
B11: Miscellaneous
B12: Hauling | C12: Assume 25% of total labor hrs | F12: 1 lot | I12: =I10*0.25 -> 0.625 | J12: =I12*Summary!$H$4 -> 0 | N12: =M12+J12 -> 0
I13: =I12 -> 0.625 | J13: =J12 -> 0 | K13: =SUM(K12:K12) -> 0 | L13: =SUM(L12:L12) -> 0 | O13: =N12 -> 0
O14: =O10+O13 -> 0

Sheet Notes, Assumptions
B2: Project Name | C2: ='HVAC COST'!C3 -> University Park Village
B3: Address | C3: ='HVAC COST'!C4 -> 1620 S University DR, Fort Worth, TX 76107
B4: Plan Date | C4: ='HVAC COST'!C5 -> 45962
B6: General Assumptions
B7: Consider Duct wastage at 10%
B8: Duct and fittings material unit price includes hangers and other miscellaneous hardwares
B9: Unit Labor costs are based on 2024 NPH book
B12: ASSUMPTIONS/TAKE OFF CONSIDERATION | C12: ILLUSTRATION | D12: SHEET NO.
B13: Assume Galvanized Sheet # 26 | D13: M001
B14: Dampers | D14: M001
B15: Duct Insulation; 1" thickness liner, R-6 Duct wrap | D15: M001

Sheet COMPUTATION
C1: QTY | D1: RND DUCT SIZE | E1: RND DUCT SIZE | F1: RND DUCT SIZE | G1: REC DUCT (W) | H1: REC DUCT (W) | I1: REC DUCT (W) | J1: REC DUCT (W) | K1: Labot HOUR | L1: Material cost | M1: R Value | N1: Square Foot | O1: 10% wastage (Insulation) | P1: Insulation / roll | Q1: Total Insulation / roll | R1: MH hr/ft | S1: MH hr | T1: MH (assume 8 hrs a day) | U1: Assume 5 working days in a week | V1: EQUIPMENT TOTAL Labot Rate | W1: ASSUME 3 CREW / DAY & 8 HRS A DAY | X1: CREW HRS / DAY | Y1: TOTAL | Z1: Total Area required firestop sealant | AA1: Assume 1" thickness of sealant | AB1: # OF WALL TO PENETRATE | AC1: Total Volume (Cu. FT) | AD1: Per pail (10.36) | AE1: DUCT LOADS IB/FT
B2: DUCTWORKS | P2: 400 | AE2: 0.9
AE3: 1.5
AE4: 0.75
P5: =4*25 -> 100
B6: RECTANGULAR DUCT
B7: SUPPLY - LINER
A8: ='MAT - TAKEOFF'!H37 -> REC DUCT W/ LINE(SA); 34X20 | B8: =TRIM(RIGHT(A8, LEN(A8) - FIND(";", A8))) -> 34X20 | C8: ='MAT - TAKEOFF'!I37 -> 18.8 | G8: =LEFT(B8,FIND("X",B8)-1) -> 34 | H8: =MID(B8,FIND("X",B8)+1,LEN(B8)-FIND("X",B8)) -> 20 | K8: =VLOOKUP(B8,$K$256:$L$520, 2, FALSE) -> 0.497 | L8: =VLOOKUP(B8,$B$256:$C$520, 2, FALSE) -> 32.9 | N8: =(((((G8+2)+(H8+2))*2)*(C8*12))/144)+((((G8+5)*(H8+5))/144)*M8) -> 181.73333 | O8: =N8*1.1 -> 199.90667 | P8: =O8/$P$5 -> 1.9990667 | Q8: =SUM(P8:P12) -> 3.6650167 | R8: =K8 -> 0.497 | S8: =((R8)*C8) -> 9.3436 | AE8: =((2*(G8+H8)/12)*$AE$2)+((2*(G8+H8)/12))*(1/12)*$AE$3 -> 9.225
A9: ='MAT - TAKEOFF'!H39 -> REC DUCT W/ LINED(SA); 35X20 | B9: =TRIM(RIGHT(A9, LEN(A9) - FIND(";", A9))) -> 35X20 | C9: ='MAT - TAKEOFF'!I39 -> 8.5 | G9: =LEFT(B9,FIND("X",B9)-1) -> 35 | H9: =MID(B9,FIND("X",B9)+1,LEN(B9)-FIND("X",B9)) -> 20 | K9: =VLOOKUP(B9,$K$256:$L$520, 2, FALSE) -> 0.517 | L9: =VLOOKUP(B9,$B$256:$C$520, 2, FALSE) -> 33.81 | N9: =(((((G9+2)+(H9+2))*2)*(C9*12))/144)+((((G9+5)*(H9+5))/144)*M9) -> 83.583333 | O9: =N9*1.1 -> 91.941667 | P9: =O9/$P$5 -> 0.91941667 | R9: =K9 -> 0.517 | S9: =((R9)*C9) -> 4.3945 | AE9: =((2*(G9+H9)/12)*$AE$2)+((2*(G9+H9)/12))*(1/12)*$AE$3 -> 9.3958333
S10: =((R10)*C10) -> 0
B11: RETURN - LINER | S11: =((R11)*C11) -> 0
A12: ='MAT - TAKEOFF'!H38 -> REC DUCT W/ LINED(RA); 20X16 | B12: =TRIM(RIGHT(A12, LEN(A12) - FIND(";", A12))) -> 20X16 | C12: ='MAT - TAKEOFF'!I38 -> 10.18 | G12: =LEFT(B12,FIND("X",B12)-1) -> 20 | H12: =MID(B12,FIND("X",B12)+1,LEN(B12)-FIND("X",B12)) -> 16 | K12: =VLOOKUP(B12,$K$256:$L$520, 2, FALSE) -> 0.269 | L12: =VLOOKUP(B12,$B$256:$C$520, 2, FALSE) -> 16.1 | N12: =(((((G12+2)+(H12+2))*2)*(C12*12))/144)+((((G12+5)*(H12+5))/144)*M12) -> 67.866667 | O12: =N12*1.1 -> 74.653333 | P12: =O12/$P$5 -> 0.74653333 | R12: =K12 -> 0.269 | S12: =((R12)*C12) -> 2.73842 | AE12: =((2*(G12+H12)/12)*$AE$2)+((2*(G12+H12)/12))*(1/12)*$AE$3 -> 6.15
S13: =((R13)*C13) -> 0
B14: SUPPLY - DUCT WRAP | S14: =((R14)*C14) -> 0
A15: ='MAT - TAKEOFF'!H36 -> REC DUCT W/ DUCT WRAP(SA); 18X6 | B15: =TRIM(RIGHT(A15, LEN(A15) - FIND(";", A15))) -> 18X6 | C15: ='MAT - TAKEOFF'!I36 -> 2.95 | G15: =LEFT(B15,FIND("X",B15)-1) -> 18 | H15: =MID(B15,FIND("X",B15)+1,LEN(B15)-FIND("X",B15)) -> 6 | K15: =VLOOKUP(B15,$K$256:$L$520, 2, FALSE) -> 0.184 | L15: =VLOOKUP(B15,$B$256:$C$520, 2, FALSE) -> 12.04 | N15: =(((((G15+2)+(H15+2))*2)*(C15*12))/144)+((((G15+5)*(H15+5))/144)*M15) -> 13.766667 | O15: =N15*1.1 -> 15.143333 | P15: =O15/$P$2 -> 0.037858333 | R15: =K15 -> 0.184 | S15: =((R15)*C15) -> 0.5428 | AE15: =((2*(G15+H15)/12)*$AE$2)+((2*(G15+H15)/12))*(1/12)*$AE$3 -> 4.1
S16: =((R16)*C16) -> 0
B17: ROUND DUCT | S17: =((R17)*C17) -> 0
B18: SUPPLY | S18: =((R18)*C18) -> 0 | AE18: =(3.1416*(B19/12))+((3.1416*(B19/12))*(1.5/12)*$AE$4) -> 2.8634375
A19: ='MAT - TAKEOFF'!H54 -> RND DUCT W/ DCUT WRAP(SA); 10" DIA | B19: =--TRIM(MID(A19,FIND(";",A19)+1,FIND("""",A19)-FIND(";",A19)-1)) -> 10 | C19: ='MAT - TAKEOFF'!I54 -> 95.95 | K19: =VLOOKUP(B19,$Q$259:$R$280,2,FALSE) -> 0.103 | L19: =VLOOKUP(B19,$O$256:$P$282,2,FALSE) -> 6.881 | N19: =PI()*(B19/144)*C19 -> 20.933043 | O19: =N19*1.1 -> 23.026347 | P19: =O19/$P$2 -> 0.057565867 | Q19: =SUM(P19:P26) -> 0.20824025 | R19: =K19 -> 0.103 | S19: =((R19)*C19) -> 9.88285 | AE19: =(3.1416*(B20/12))+((3.1416*(B20/12))*(1.5/12)*$AE$4) -> 3.436125
A20: ='MAT - TAKEOFF'!H55 -> RND DUCT W/ DCUT WRAP(SA); 12" DIA | B20: =--TRIM(MID(A20,FIND(";",A20)+1,FIND("""",A20)-FIND(";",A20)-1)) -> 12 | C20: ='MAT - TAKEOFF'!I55 -> 9.44 | K20: =VLOOKUP(B20,$Q$259:$R$280,2,FALSE) -> 0.123 | L20: =VLOOKUP(B20,$O$256:$P$282,2,FALSE) -> 8.19 | N20: =PI()*(B20/144)*C20 -> 2.4713862 | O20: =N20*1.1 -> 2.7185248 | P20: =O20/$P$2 -> 0.0067963121 | R20: =K20 -> 0.123 | S20: =((R20)*C20) -> 1.16112 | AE20: =(3.1416*(B21/12))+((3.1416*(B21/12))*(1.5/12)*$AE$4) -> 4.5815
A21: ='MAT - TAKEOFF'!H56 -> RND DUCT W/ DCUT WRAP(SA); 16" DIA | B21: =--TRIM(MID(A21,FIND(";",A21)+1,FIND("""",A21)-FIND(";",A21)-1)) -> 16 | C21: ='MAT - TAKEOFF'!I56 -> 48.29 | K21: =VLOOKUP(B21,$Q$259:$R$280,2,FALSE) -> 0.174 | L21: =VLOOKUP(B21,$O$256:$P$282,2,FALSE) -> 10.29 | N21: =PI()*(B21/144)*C21 -> 16.85639 | O21: =N21*1.1 -> 18.542029 | P21: =O21/$P$2 -> 0.046355072 | R21: =K21 -> 0.174 | S21: =((R21)*C21) -> 8.40246 | AE21: =(3.1416*(B22/12))+((3.1416*(B22/12))*(1.5/12)*$AE$4) -> 5.726875
A22: ='MAT - TAKEOFF'!H57 -> RND DUCT W/ DCUT WRAP(SA); 20" DIA | B22: =--TRIM(MID(A22,FIND(";",A22)+1,FIND("""",A22)-FIND(";",A22)-1)) -> 20 | C22: ='MAT - TAKEOFF'!I57 -> 50.11 | K22: =VLOOKUP(B22,$Q$259:$R$280,2,FALSE) -> 0.195 | L22: =VLOOKUP(B22,$O$256:$P$282,2,FALSE) -> 13.09 | N22: =PI()*(B22/144)*C22 -> 21.864612 | O22: =N22*1.1 -> 24.051073 | P22: =O22/$P$2 -> 0.060127684 | R22: =K22 -> 0.195 | S22: =((R22)*C22) -> 9.77145 | AE22: =(3.1416*(B23/12))+((3.1416*(B23/12))*(1.5/12)*$AE$4) -> 3.436125
A23: ='MAT - TAKEOFF'!H58 -> RND DUCT W/ DUCT WRAP(SA); 12" DIA | B23: =--TRIM(MID(A23,FIND(";",A23)+1,FIND("""",A23)-FIND(";",A23)-1)) -> 12 | C23: ='MAT - TAKEOFF'!I58 -> 15.24 | K23: =VLOOKUP(B23,$Q$259:$R$280,2,FALSE) -> 0.123 | L23: =VLOOKUP(B23,$O$256:$P$282,2,FALSE) -> 8.19 | N23: =PI()*(B23/144)*C23 -> 3.9898227 | O23: =N23*1.1 -> 4.3888049 | P23: =O23/$P$2 -> 0.010972012 | R23: =K23 -> 0.123 | S23: =((R23)*C23) -> 1.87452 | AE23: =(3.1416*(B24/12))+((3.1416*(B24/12))*(1.5/12)*$AE$4) -> 4.0088125
A24: ='MAT - TAKEOFF'!H59 -> RND DUCT W/ DUCT WRAP(SA); 14" DIA | B24: =--TRIM(MID(A24,FIND(";",A24)+1,FIND("""",A24)-FIND(";",A24)-1)) -> 14 | C24: ='MAT - TAKEOFF'!I59 -> 9.25 | K24: =VLOOKUP(B24,$Q$259:$R$280,2,FALSE) -> 0.174 | L24: =VLOOKUP(B24,$O$256:$P$282,2,FALSE) -> 10.29 | N24: =PI()*(B24/144)*C24 -> 2.8252517 | O24: =N24*1.1 -> 3.1077769 | P24: =O24/$P$2 -> 0.0077694422 | R24: =K24 -> 0.174 | S24: =((R24)*C24) -> 1.6095 | AE24: =(3.1416*(B25/12))+((3.1416*(B25/12))*(1.5/12)*$AE$4) -> 5.1541875
A25: ='MAT - TAKEOFF'!H60 -> RND DUCT W/ DUCT WRAP(SA); 18" DIA | B25: =--TRIM(MID(A25,FIND(";",A25)+1,FIND("""",A25)-FIND(";",A25)-1)) -> 18 | C25: ='MAT - TAKEOFF'!I60 -> 14.29 | K25: =VLOOKUP(B25,$Q$259:$R$280,2,FALSE) -> 0.195 | L25: =VLOOKUP(B25,$O$256:$P$282,2,FALSE) -> 13.09 | N25: =PI()*(B25/144)*C25 -> 5.6116699 | O25: =N25*1.1 -> 6.1728369 | P25: =O25/$P$2 -> 0.015432092 | R25: =K25 -> 0.195 | S25: =((R25)*C25) -> 2.78655 | AE25: =(3.1416*(B26/12))+((3.1416*(B26/12))*(1.5/12)*$AE$4) -> 1.7180625
A26: ='MAT - TAKEOFF'!H61 -> RND DUCT W/ DUCT WRAP(SA); 6" DIA | B26: =--TRIM(MID(A26,FIND(";",A26)+1,FIND("""",A26)-FIND(";",A26)-1)) -> 6 | C26: ='MAT - TAKEOFF'!I61 -> 8.95 | K26: =VLOOKUP(B26,$Q$259:$R$280,2,FALSE) -> 0.061 | L26: =VLOOKUP(B26,$O$256:$P$282,2,FALSE) -> 4.13 | N26: =PI()*(B26/144)*C26 -> 1.1715523 | O26: =N26*1.1 -> 1.2887075 | P26: =O26/$P$2 -> 0.0032217687 | R26: =K26 -> 0.061 | S26: =((R26)*C26) -> 0.54595
B28: FLEXIBLE DUCT
A29: ='MAT - TAKEOFF'!H21 -> FLEX DUCT(SA); 10" DIA | B29: =--TRIM(MID(A29,FIND(";",A29)+1,FIND("""",A29)-FIND(";",A29)-1)) -> 10 | C29: ='MAT - TAKEOFF'!I21 -> 30.76 | K29: =VLOOKUP(B29,$B$222:$C$237,2,FALSE) -> 0.09 | L29: =VLOOKUP(B29,$F$221:$G$237,2,FALSE) -> 3.0252
A30: ='MAT - TAKEOFF'!H22 -> FLEX DUCT(SA); 12" DIA | B30: =--TRIM(MID(A30,FIND(";",A30)+1,FIND("""",A30)-FIND(";",A30)-1)) -> 12 | C30: ='MAT - TAKEOFF'!I22 -> 15.17 | K30: =VLOOKUP(B30,$B$222:$C$237,2,FALSE) -> 0.1 | L30: =VLOOKUP(B30,$F$221:$G$237,2,FALSE) -> 3.2032
A31: ='MAT - TAKEOFF'!H23 -> FLEX DUCT(SA); 6" DIA | B31: =--TRIM(MID(A31,FIND(";",A31)+1,FIND("""",A31)-FIND(";",A31)-1)) -> 6 | C31: ='MAT - TAKEOFF'!I23 -> 9.06 | K31: =VLOOKUP(B31,$B$222:$C$237,2,FALSE) -> 0.07 | L31: =VLOOKUP(B31,$F$221:$G$237,2,FALSE) -> 1.8508
B33: FITTINGS
B34: SUPPLY - DUCTBOOTS 90DEG
A35: ='MAT - TAKEOFF'!H13 -> DUCTBOOTS 90DEG(SA); 10" DIA TO 24X24 | B35: =TRIM(MID(A35, FIND(";", A35)+2, LEN(A35))) -> 10" DIA TO 24X24 | C35: ='MAT - TAKEOFF'!I13 -> 10
A36: ='MAT - TAKEOFF'!H14 -> DUCTBOOTS 90DEG(SA); 12" DIA to 24X24 | B36: =TRIM(MID(A36, FIND(";", A36)+2, LEN(A36))) -> 12" DIA to 24X24 | C36: ='MAT - TAKEOFF'!I14 -> 5
A37: ='MAT - TAKEOFF'!H15 -> DUCTBOOTS 90DEG(SA); 6" DIA TO 12X12 | B37: =TRIM(MID(A37, FIND(";", A37)+2, LEN(A37))) -> 6" DIA TO 12X12 | C37: ='MAT - TAKEOFF'!I15 -> 3
B39: PLENUM DUCTBOOTS
A40: ='MAT - TAKEOFF'!H29 -> PLENUM DUCTBOOTS(EA); 8X8 TO 12X12 | B40: =TRIM(MID(A40, FIND(";", A40)+2, LEN(A40))) -> 8X8 TO 12X12 | C40: ='MAT - TAKEOFF'!I29 -> 3
A41: ='MAT - TAKEOFF'!H30 -> PLENUM DUCTBOOTS(RA); 20X16 TO 24X24 | B41: =TRIM(MID(A41, FIND(";", A41)+2, LEN(A41))) -> 20X16 TO 24X24 | C41: ='MAT - TAKEOFF'!I30 -> 1
B43: RECTANGULAR DUCT 90DEG ELBOW
A44: ='MAT - TAKEOFF'!H32 -> REC DUCT 90EL(SA); 20X16 | B44: =TRIM(RIGHT(A44, LEN(A44) - FIND(";", A44))) -> 20X16 | C44: ='MAT - TAKEOFF'!I32 -> 1
...

Sheet MAT - TAKEOFF
A1: Page | B1: Digitizer Item | C1: Total | D1: Units | H1: COMBINED
A2: M101_MECHANICAL PLAN - EXHAUST | B2: REC DUCT(EA); 8X8 | C2: 59.53 | D2: FT | H2: {=_xlfn.GROUPBY(B1:B70,C1:C70,_xleta.SUM)} -> AIR CURTAIN; X0702_ MARS STD242 | I2: 1
A3: M101_MECHANICAL PLAN - EXHAUST | B3: GRILLES(EA); X1001_TITUS 350_12X12 | C3: 3 | D3: EA | H3: BAROMETRIC RELIEF | I3: 3
A4: M101_MECHANICAL PLAN - EXHAUST | B4: PLENUM DUCTBOOTS(EA); 8X8 TO 12X12 | C4: 3 | D4: EA | H4: CARBON MONOXIDE DETECTOR | I4: 1
A5: M101_MECHANICAL PLAN - EXHAUST | B5: REC DUCT 90EL(EA); 8X8 | C5: 2 | D5: EA | H5: CO2 SENSOR | I5: 2
A6: M101_MECHANICAL PLAN | B6: FLEX DUCT(SA); 10" DIA | C6: 30.76 | D6: FT | H6: DAMPER_MANUAL VOLUME(SA); 10" DIA | I6: 10
A7: M101_MECHANICAL PLAN | B7: FLEX DUCT(SA); 6" DIA | C7: 9.06 | D7: FT | H7: DAMPER_MANUAL VOLUME(SA); 12" DIA | I7: 5
A8: M101_MECHANICAL PLAN | B8: FLEX DUCT(SA); 12" DIA | C8: 15.17 | D8: FT | H8: DAMPER_MANUAL VOLUME(SA); 6" DIA | I8: 3
A9: M101_MECHANICAL PLAN | B9: RND DUCT W/ DCUT WRAP(SA); 20" DIA | C9: 50.11 | D9: FT | H9: DEFLECTION GRILLES(SA); X2010_TITUS 300RS_18X6 | I9: 5
A10: M101_MECHANICAL PLAN | B10: RND DUCT W/ DCUT WRAP(SA); 10" DIA | C10: 95.95 | D10: FT | H10: DIFFUSER(SA); X2020_ TITUS TDC_24X24 | I10: 4
A11: M101_MECHANICAL PLAN | B11: DAMPER_MANUAL VOLUME(SA); 10" DIA | C11: 10 | D11: EA | H11: DIFFUSER(SA); X2030_TITUS OMN_24X24 | I11: 11
A12: M101_MECHANICAL PLAN | B12: RND DUCT 45DEG EL(SA); 10" DIA | C12: 2 | D12: EA | H12: DIFFUSER(SA); X2070_ TITUS OMNI_12X12 | I12: 3
A13: M101_MECHANICAL PLAN | B13: RND DUCT COLLAR(SA); 10" DIA | C13: 18 | D13: EA | H13: DUCTBOOTS 90DEG(SA); 10" DIA TO 24X24 | I13: 10
A14: M101_MECHANICAL PLAN | B14: DIFFUSER(SA); X2030_TITUS OMN_24X24 | C14: 11 | D14: EA | H14: DUCTBOOTS 90DEG(SA); 12" DIA to 24X24 | I14: 5
... A70: 01734-094_University Park Village_IFP SET | B70: GRAVITY BACKDRAFT DAMPER; 8X8 | C70: 2 | D70: EA | H70: Total | I70: 567.47
